Workbook

Sheet Auto -  Printable
C1: Rounds [Min Points] | D1: 1 | F1: 2 | H1: 3 | J1: 4 | L1: 5 | N1: 6 | P1: 7 | R1: 8 | T1: 9 | V1: 10 | X1: 11 | Z1: 12 | AB1: 13 | AD1: 14 | AF1: 15 | AH1: 16 | AJ1: 17 | AL1: 18
B2: WEEK | D2: Apr 29th | F2: May 6th | H2: May 13th | J2: May 20th | L2: May 27th | N2: June 3rd | P2: June 17th | R2: June 24th | T2: July 1st | V2: July 8th | X2: July 15th | Z2: July 22nd | AB2: July 29th | AD2: Aug 5th | AF2: Aug 12th | AH2: Aug 19th | AJ2: Aug 26th | AL2: Sept 2nd | AN2: TOTAL | AO2: AVG
B3: Side Game | D3: Closest to Pin | F3: Most Net Pars | H3: Most Under Par | J3: Skins | L3: Closest to Pin | N3: Most Net Pars | P3: Most Under Par | R3: Skins | T3: Closest to Pin | V3: Most Net Pars | X3: Most Under Par | Z3: Skins | AB3: Closest to Pin | AD3: Most Net Pars | AF3: Most Under Par | AH3: Skins | AJ3: Closest to Pin | AL3: Most Net Pars
B4: Winner | D4: RA,MB,JP,HBH | H4: HBH, MW, Bags | J4: JBx3, CPx2, MBx2, KC, MWx2 | L4: CP | N4: HBH, NC, MJ, KC | P4: JS, MW, MB, SP | R4: KCx2, CK, JS, ABx2, CM, SP | T4: Bagger | V4: BMx2, CM, JB
B5: TEES | D5: Blue | F5: Rain Out | H5: Black | J5: White | L5: Blue | N5: Black | P5: White | R5: Blue | T5: Black | V5: White | X5: Blue | Z5: Black | AB5: White | AD5: Blue | AF5: Black | AH5: White | AJ5: Blue | AL5: Black
A6: 1 | B6: Jeff Madden | C6: 8 | D6: 77 | E6: 36 | H6: 83 | I6: 26.5 | L6: 85 | M6: 31 | N6: 85 | O6: 23 | P6: 80 | Q6: 26.5 | R6: 79 | S6: 25.5 | T6: 80 | U6: 28.5 | V6: 75 | W6: 29.5 | AN6: 226.5 | AO6: 28.3125
A7: 1.13 | B7: Harvey Points | D7: 40 | E7: 18 | H7: 37 | I7: 14 | L7: 33 | M7: 14 | N7: 35 | O7: 13.5 | P7: 34 | Q7: 10.5 | R7: 37 | S7: 17 | T7: 38 | U7: 15 | V7: 37 | W7: 15.5 | AN7: 36.375 | AO7: 14.6875
A8: 1.023 | B8: cash +/- | C8: 23 | D8: 35 | E8: 18 | H8: 4 | I8: 12.5 | L8: 38 | M8: 17 | N8: -0.001 | O8: 9.5 | P8: 16 | Q8: 16 | R8: -2 | S8: 8.5 | T8: 5 | U8: 13.5 | V8: 16 | W8: 14 | AN8: 111.999 | AO8: 13.625
A9: 2 | B9: Ben McGinnis | C9: 8 | D9: 80 | E9: 23 | J9: 81 | K9: 21.5 | L9: 83 | M9: 29 | N9: 84 | O9: 17.5 | P9: 79 | Q9: 21.5 | R9: 79 | S9: 29.5 | T9: 76 | U9: 35 | V9: 81 | W9: 18 | AN9: 195 | AO9: 24.375
A10: 2.15 | B10: Harvey Points | D10: 34 | E10: 16 | J10: 32 | K10: 12.5 | L10: 33 | M10: 14 | N10: 34 | O10: 11.5 | P10: 36 | Q10: 13.5 | R10: 36 | S10: 15.5 | T10: 41 | U10: 18 | V10: 33 | W10: 9.5 | AN10: 34.875 | AO10: 13.8125
A11: 2.025 | B11: cash +/- | C11: 17.5 | D11: -10 | E11: 7 | J11: -15 | K11: 9 | L11: 20 | M11: 15 | N11: -16 | O11: 6 | P11: -4 | Q11: 8 | R11: 12 | S11: 14 | T11: 25 | U11: 17 | V11: -8 | W11: 8.5 | AN11: 4 | AO11: 10.5625
A12: 3 | B12: Matt White | C12: 8 | D12: 84 | E12: 20.5 | H12: 79 | I12: 31 | J12: 82 | K12: 26.5 | L12: 86 | M12: 26.5 | N12: 84 | O12: 23.5 | P12: 80 | Q12: 25.5 | R12: 83 | S12: 25.5 | T12: 96 | U12: 14 | AN12: 193 | AO12: 24.125
A13: 3.11 | B13: Harvey Points | D13: 32 | E13: 12.5 | H13: 39 | I13: 15 | J13: 32 | K13: 12.5 | L13: 30 | M13: 8.5 | N13: 34 | O13: 11.5 | P13: 34 | Q13: 10.5 | R13: 33 | S13: 11.5 | T13: 23 | U13: 3 | AN13: 32.125 | AO13: 10.625
A14: 3.021 | B14: cash +/- | C14: 14 | D14: -9 | E14: 8 | H14: 30 | I14: 16 | J14: 43 | K14: 14 | L14: 40 | M14: 18 | N14: 1 | O14: 12 | P14: 8 | Q14: 15 | R14: 12 | S14: 14 | T14: 3 | U14: 11 | AN14: 128 | AO14: 13.5
A15: 4 | B15: Chris Preston | C15: 9 | D15: 82 | E15: 22 | H15: 81 | I15: 23.5 | J15: 76 | K15: 26 | L15: 80 | M15: 22 | N15: 85 | O15: 11.5 | P15: 76 | Q15: 23.5 | R15: 74 | S15: 28.5 | T15: 80 | U15: 16.5 | V15: 74 | W15: 18.5 | AN15: 192 | AO15: 21.333333
A16: 4.12 | B16: Harvey Points | D16: 29 | E16: 6 | H16: 32 | I16: 11 | J16: 33 | K16: 14 | L16: 33 | M16: 14 | N16: 29 | O16: 7.5 | P16: 34 | Q16: 10.5 | R16: 38 | S16: 18 | T16: 33 | U16: 8.5 | V16: 34 | W16: 11.5 | AN16: 32.777778 | AO16: 11.222222
A17: 4.022 | B17: cash +/- | C17: 11.5 | D17: 12 | E17: 16 | H17: 4 | I17: 12.5 | J17: 13 | K17: 12 | L17: -6 | M17: 8 | N17: -28 | O17: 4 | P17: 4 | Q17: 13 | R17: -0.0001 | S17: 10.5 | T17: -9 | U17: 8 | V17: -18 | W17: 7 | AN17: -28.0001 | AO17: 10.111111
A18: 5 | B18: Nathan Copley | C18: 7 | D18: 85 | E18: 22 | L18: 80 | M18: 34 | N18: 80 | O18: 32.5 | P18: 74 | Q18: 22 | R18: 81 | S18: 21.5 | T18: 83 | U18: 23.5 | V18: 77 | W18: 18 | AN18: 173.5 | AO18: 24.785714
A19: 5.111 | B19: Harvey Points | D19: 32 | E19: 12.5 | L19: 37 | M19: 18 | N19: 37 | O19: 16.5 | P19: 39 | Q19: 15.5 | R19: 34 | S19: 13 | T19: 33 | U19: 8.5 | V19: 33 | W19: 9.5 | AN19: 35 | AO19: 13.357143
A20: 5.0211 | B20: cash +/- | C20: 18 | D20: -8 | E20: 9.5 | L20: 28 | M20: 16 | N20: 17 | O20: 16 | P20: -8 | Q20: 6.5 | R20: -2 | S20: 8.5 | T20: 13 | U20: 15 | V20: -8 | W20: 8.5 | AN20: 32 | AO20: 11.428571
A21: 6 | B21: Kyle Cox | C21: 7 | D21: 83 | E21: 26.5 | J21: 84 | K21: 24 | L21: 87 | M21: 23 | N21: 83 | O21: 29 | R21: 88 | S21: 10.5 | T21: 81 | U21: 33 | V21: 84 | W21: 22 | AN21: 168 | AO21: 24
A22: 6.14 | B22: Harvey Points | D22: 33 | E22: 14.5 | J22: 30 | K22: 11 | L22: 31 | M22: 11 | N22: 36 | O22: 15 | R22: 29 | S22: 6.5 | T22: 38 | U22: 15 | V22: 30 | W22: 8 | AN22: 32.428571 | AO22: 11.571429
A23: 6.024 | B23: cash +/- | C23: 10.5 | D23: 5 | E23: 12 | J23: 41 | K23: 13 | L23: 8 | M23: 12 | N23: 12 | O23: 14 | R23: -32 | S23: 4 | T23: 29 | U23: 18 | V23: 16 | W23: 14 | AN23: 79 | AO23: 12.428571
A24: 7 | B24: Scotty Pierson | C24: 7 | D24: 96 | E24: 27 | H24: 89 | I24: 31 | L24: 100 | M24: 12 | N24: 92 | O24: 34.5 | P24: 89 | Q24: 21.5 | R24: 93 | S24: 22 | V24: 86 | W24: 19.5 | AN24: 167.5 | AO24: 23.928571
A25: 7.16 | B25: Harvey Points | D25: 31 | E25: 10 | H25: 40 | I25: 16 | L25: 27 | M25: 7 | N25: 37 | O25: 16.5 | P25: 34 | Q25: 10.5 | R25: 32 | S25: 10 | V25: 36 | W25: 13.5 | AN25: 33.857143 | AO25: 11.928571
A26: 7.026 | B26: cash +/- | C26: 12 | D26: 27 | E26: 17 | H26: 21 | I26: 15 | L26: -20 | M26: 5 | N26: 28 | O26: 18 | P26: 2 | Q26: 11 | R26: 8 | S26: 12 | V26: -20 | W26: 6 | AN26: 46 | AO26: 12
A27: 8 | B27: Ronnie A. | C27: 7 | D27: 77 | E27: 31.5 | H27: 87 | I27: 15 | L27: 81 | M27: 23.5 | N27: 84 | O27: 23 | P27: 82 | Q27: 16 | T27: 87 | U27: 10 | V27: 76 | W27: 29.5 | AN27: 148.5 | AO27: 21.214286
A28: 8.17 | B28: Harvey Points | D28: 39 | E28: 17 | H28: 31 | I28: 10 | L28: 34 | M28: 16.5 | N28: 33 | O28: 10 | P28: 30 | Q28: 5 | T28: 30 | U28: 7 | V28: 36 | W28: 13.5 | AN28: 33.285714 | AO28: 11.285714
A29: 8.027 | B29: cash +/- | C29: 10 | D29: 10 | E29: 14.5 | H29: -32 | I29: 5 | L29: -8 | M29: 7 | N29: 10 | O29: 13 | P29: 2 | Q29: 11 | T29: -33 | U29: 3 | V29: 28 | W29: 16 | AN29: -23 | AO29: 9.9285714
A30: 9 | B30: Chris McNeely | C30: 7 | D30: 96 | E30: 24.5 | H30: 95 | I30: 27 | L30: 102 | M30: 9 | N30: 98 | O30: 18.5 | R30: 99 | S30: 9.5 | T30: 87 | U30: 30.5 | V30: 89 | W30: 23.5 | AN30: 142.5 | AO30: 20.357143
A31: 9.19 | B31: Harvey Points | D31: 31 | E31: 10 | H31: 35 | I31: 13 | L31: 23 | M31: 6 | N31: 30 | O31: 9 | R31: 25 | S31: 3 | T31: 40 | U31: 17 | V31: 34 | W31: 11.5 | AN31: 31.142857 | AO31: 9.9285714
A32: 9.029 | B32: cash +/- | C32: 9 | D32: 10 | E32: 14.5 | H32: 17 | I32: 14 | L32: -74 | M32: 3 | N32: -0.001 | O32: 9.5 | R32: -10 | S32: 6.5 | T32: 5 | U32: 13.5 | V32: 12 | W32: 12 | AN32: -40.001 | AO32: 10.428571
A33: 10 | B33: Josh Stoll | C33: 8 | D33: 93 | E33: 10.5 | H33: 101 | I33: 14.5 | L33: 92 | M33: 25 | N33: 96 | O33: 24.5 | P33: 87 | Q33: 15.5 | R33: 90 | S33: 18.5 | T33: 89 | U33: 17 | V33: 92 | W33: 10 | AN33: 135.5 | AO33: 16.9375
A34: 10.113 | B34: Harvey Points | D34: 30 | E34: 7.5 | H34: 24 | I34: 6 | L34: 31 | M34: 11 | N34: 29 | O34: 7.5 | P34: 31 | Q34: 6.5 | R34: 30 | S34: 8 | T34: 34 | U34: 11 | V34: 25 | W34: 5 | AN34: 29.25 | AO34: 7.8125
A35: 10.0213 | B35: cash +/- | C35: 10 | D35: -27 | E35: 3 | H35: -9 | I35: 8.5 | L35: 18 | M35: 14 | N35: 21 | O35: 17 | P35: -2 | Q35: 9 | R35: -0.0001 | S35: 10.5 | T35: -13 | U35: 6 | V35: -50 | W35: 5 | AN35: -62.0001 | AO35: 9.125
A36: 11 | B36: Mike Bonner | C36: 6 | D36: 89 | E36: 18.5 | H36: 91 | I36: 19 | J36: 93 | K36: 17 | P36: 80 | Q36: 22 | T36: 89 | U36: 15 | V36: 81 | W36: 29.5 | AN36: 121 | AO36: 20.166667
A37: 11.112 | B37: Harvey Points | D37: 33 | E37: 14.5 | H37: 33 | I37: 12 | J37: 26 | K37: 7 | P37: 39 | Q37: 15.5 | T37: 34 | U37: 11 | V37: 37 | W37: 15.5 | AN37: 33.666667 | AO37: 12.583333
A38: 11.0212 | B38: cash +/- | C38: 15 | D38: -15 | E38: 4 | H38: -12 | I38: 7 | J38: -13 | K38: 10 | P38: -8 | Q38: 6.5 | T38: -21 | U38: 4 | V38: 16 | W38: 14 | AN38: -53 | AO38: 7.5833333
A39: 12 | B39: Jay Patterson | C39: 7 | D39: 87 | E39: 9.5 | J39: 84 | K39: 16.5 | L39: 85 | M39: 17.5 | N39: 91 | O39: 12 | P39: 77 | Q39: 24.5 | R39: 85 | S39: 15.5 | T39: 84 | U39: 20 | AN39: 115.5 | AO39: 16.5
A40: 12.115 | B40: Harvey Points | D40: 28 | E40: 4.5 | J40: 28 | K40: 8.5 | L40: 30 | M40: 8.5 | N40: 26 | O40: 5 | P40: 36 | Q40: 13.5 | R40: 31 | S40: 9 | T40: 34 | U40: 11 | AN40: 30.428571 | AO40: 8.5714286
...

Sheet Standings
F1: Rounds [Min Points] | CS1: 1 | CU1: =CS1+1 -> 2 | CW1: =CU1+1 -> 3 | CY1: =CW1+1 -> 4 | DA1: =CY1+1 -> 5 | DC1: =DA1+1 -> 6 | DE1: =DC1+1 -> 7 | DG1: =DE1+1 -> 8 | DI1: =DG1+1 -> 9 | DK1: =DI1+1 -> 10 | DM1: =DK1+1 -> 11 | DO1: =DM1+1 -> 12 | DQ1: =DO1+1 -> 13 | DS1: =DQ1+1 -> 14 | DU1: =DS1+1 -> 15 | DW1: =DU1+1 -> 16 | DY1: =DW1+1 -> 17 | EA1: =DY1+1 -> 18
E2: WEEK | CS2: Apr 29th | CU2: May 6th | CW2: May 13th | CY2: May 20th | DA2: May 27th | DC2: June 3rd | DE2: June 17th | DG2: June 24th | DI2: July 1st | DK2: July 8th | DM2: July 15th | DO2: July 22nd | DQ2: July 29th | DS2: Aug 5th | DU2: Aug 12th | DW2: Aug 19th | DY2: Aug 26th | EA2: Sept 2nd | EC2: TOTAL | ED2: AVG
E3: Side Game | CS3: Closest to Pin | CU3: Most Net Pars | CW3: Most Under Par | CY3: Skins | DA3: Most Net Pars | DC3: Closest to Pin | DE3: Most Under Par | DG3: Skins | DI3: Most Net Pars | DK3: Closest to Pin | DM3: Most Under Par | DO3: Skins | DQ3: Most Net Pars | DS3: Closest to Pin | DU3: Most Under Par | DW3: Skins | DY3: Most Net Pars | EA3: Closest to Pin
E4: Winner | G4: 44680 | L4: 44687 | Q4: 44694 | V4: 44701 | AA4: 44708 | AF4: 44715 | AK4: 44729 | AP4: 44736 | AU4: 44743 | AZ4: 44750 | BE4: 44757 | BJ4: 44764 | BO4: 44771 | BT4: 44778 | BY4: 44785 | CD4: 44792 | CI4: 44799 | CN4: 44806 | CS4: RA,MB,JP,HBH | CW4: HBH, MW, Bags | CY4: JBx3, CPx2, MBx2, KC, MWx2 | DA4: CP | DC4: HBH, NC, MJ, KC | DE4: JS, MW, MB, SP | DG4: KCx2, CK, JS, ABx2, CM, SP | DI4: Bagger | DK4: BMx2, CM, JB
E5: TEES | G5: Score | H5: Harvey | I5: Money | J5: H Rank | K5: M Rank | L5: Score | M5: Harvey | N5: Money | O5: H Rank | P5: M Rank | Q5: Score | R5: Harvey | S5: Money | T5: H Rank | U5: M Rank | V5: Score | W5: Harvey | X5: Money | Y5: H Rank | Z5: M Rank | AA5: Score | AB5: Harvey | AC5: Money | AD5: H Rank | AE5: M Rank | AF5: Score | AG5: Harvey | AH5: Money | AI5: H Rank | AJ5: M Rank | AK5: Score | AL5: Harvey | AM5: Money | AN5: H Rank | AO5: M Rank | AP5: Score | AQ5: Harvey | AR5: Money | AS5: H Rank | AT5: M Rank | AU5: Score | AV5: Harvey | AW5: Money | AX5: H Rank | AY5: M Rank | AZ5: Score | BA5: Harvey | BB5: Money | BC5: H Rank | BD5: M Rank | BE5: Score | BF5: Harvey | BG5: Money | BH5: H Rank | BI5: M Rank | BJ5: Score | BK5: Harvey | BL5: Money | BM5: H Rank | BN5: M Rank | BO5: Score | BP5: Harvey | BQ5: Money | BR5: H Rank | BS5: M Rank | BT5: Score | BU5: Harvey | BV5: Money | BW5: H Rank | BX5: M Rank | BY5: Score | BZ5: Harvey | CA5: Money | CB5: H Rank | CC5: M Rank | CD5: Score | CE5: Harvey | CF5: Money | CG5: H Rank | CH5: M Rank | CI5: Score | CJ5: Harvey | CK5: Money | CL5: H Rank | CM5: M Rank | CN5: Score | CO5: Harvey | CP5: Money | CQ5: H Rank | CR5: M Rank | CS5: Blue | CU5: Rain Out | CW5: Black | CY5: White | DA5: Blue | DC5: Black | DE5: White | DG5: Blue | DI5: Black | DK5: White | DM5: Blue | DO5: Black | DQ5: White | DS5: Blue | DU5: Black | DW5: White | DY5: Blue | EA5: Black
B6: =_xlfn.RANK.EQ(C6,$C$6:$C$63,) -> 1 | C6: =EC6 -> 226.5 | D6: JM | E6: Jeff Madden | F6: =COUNT(CT6,CV6,CX6,CZ6,DB6,DD6,DF6,DH6,DJ6,DL6,DN6,DP6,DR6,DT6,DV6,DX6,DZ6,EB6) -> 8 | G6: =IF(CT6=0,"",CT6) -> 36 | L6: =IF(CV6=0,"",CV6) | Q6: =IF(CX6=0,"",CX6) -> 26.5 | V6: =IF(CZ6=0,"",CZ6) | AA6: =IF(DB6=0,"",DB6) -> 31 | AF6: =IF(DD6=0,"",DD6) -> 23 | AK6: =IF(DF6=0,"",DF6) -> 26.5 | AP6: =IF(DH6=0,"",DH6) -> 25.5 | AU6: =IF(DJ6=0,"",DJ6) -> 28.5 | AZ6: =IF(DL6=0,"",DL6) -> 29.5 | BE6: =IF(DN6=0,"",DN6) | BJ6: =IF(DP6=0,"",DP6) | BO6: =IF(DR6=0,"",DR6) | BT6: =IF(DT6=0,"",DT6) | BY6: =IF(DV6=0,"",DV6) | CD6: =IF(DX6=0,"",DX6) | CI6: =IF(DZ6=0,"",DZ6) | CN6: =IF(EB6=0,"",EB6) | CS6: 77 | CT6: =IFERROR(CT7+CT8,"") -> 36 | CV6: =IFERROR(CV7+CV8,"") | CW6: 83 | CX6: =IFERROR(CX7+CX8,"") -> 26.5 | CZ6: =IFERROR(CZ7+CZ8,"") | DA6: 85 | DB6: =IFERROR(DB7+DB8,"") -> 31 | DC6: 85 | DD6: =IFERROR(DD7+DD8,"") -> 23 | DE6: 80 | DF6: =IFERROR(DF7+DF8,"") -> 26.5 | DG6: 79 | DH6: =IFERROR(DH7+DH8,"") -> 25.5 | DI6: 80 | DJ6: =IFERROR(DJ7+DJ8,"") -> 28.5 | DK6: 75 | DL6: =IFERROR(DL7+DL8,"") -> 29.5 | DN6: =IFERROR(DN7+DN8,"") | DP6: =IFERROR(DP7+DP8,"") | DR6: =IFERROR(DR7+DR8,"") | DT6: =IFERROR(DT7+DT8,"") | DV6: =IFERROR(DV7+DV8,"") | DX6: =IFERROR(DX7+DX8,"") | DZ6: =IFERROR(DZ7+DZ8,"") | EB6: =IFERROR(EB7+EB8,"") | EC6: =IFERROR(LARGE($G6:$CN6,1),0)+IFERROR(LARGE($G6:$CN6,2),0)+IFERROR(LARGE($G6:$CN6,3),0)+IFERROR(LARGE($G6:$CN6,4),0)+IFERROR(LARGE($G6:$CN6,5),0)+IFERROR(LARGE($G6:$CN6,6),0)+IFERROR(LARGE($G6:$CN6,7),0)+IFERROR(LARGE($G6:$CN6,8),0)+IFERROR(LARGE($G6:$CN6,9),0)+IFERROR(LARGE($G6:$CN6,10),0) -> 226.5 | ED6: =AVERAGE(CT6,CV6,CX6,CZ6,DB6,DD6,DF6,DH6,DJ6,DL6,DN6,DP6,DR6,DT6,DV6,DX6,DZ6,EB6) -> 28.3125
B7: =B6+0.13 -> 1.13 | D7: JM1 | E7: Harvey Points | H7: =IF(CS7=0,"",CS7) -> 40 | J7: =IFERROR(RANK(H7,H$6:H$116,0),"") -> 1 | M7: =IF(CU7=0,"",CU7) | O7: =IFERROR(RANK(M7,M$6:M$116,0),"") | R7: =IF(CW7=0,"",CW7) -> 37 | T7: =IFERROR(RANK(R7,R$6:R$116,0),"") -> 3 | W7: =IF(CY7=0,"",CY7) | Y7: =IFERROR(RANK(W7,W$6:W$116,0),"") | AB7: =IF(DA7=0,"",DA7) -> 33 | AD7: =IFERROR(RANK(AB7,AB$6:AB$116,0),"") -> 4 | AG7: =IF(DC7=0,"",DC7) -> 35 | AI7: =IFERROR(RANK(AG7,AG$6:AG$116,0),"") -> 5 | AL7: =IF(DE7=0,"",DE7) -> 34 | AN7: =IFERROR(RANK(AL7,AL$6:AL$116,0),"") -> 5 | AQ7: =IF(DG7=0,"",DG7) -> 37 | AS7: =IFERROR(RANK(AQ7,AQ$6:AQ$116,0),"") -> 2 | AV7: =IF(DI7=0,"",DI7) -> 38 | AX7: =IFERROR(RANK(AV7,AV$6:AV$116,0),"") -> 3 | BA7: =IF(DK7=0,"",DK7) -> 37 | BC7: =IFERROR(RANK(BA7,BA$6:BA$116,0),"") -> 1 | BF7: =IF(DM7=0,"",DM7) | BH7: =IFERROR(RANK(BF7,BF$6:BF$116,0),"") | BK7: =IF(DO7=0,"",DO7) | BM7: =IFERROR(RANK(BK7,BK$6:BK$116,0),"") | BP7: =IF(DQ7=0,"",DQ7) | BR7: =IFERROR(RANK(BP7,BP$6:BP$116,0),"") | BU7: =IF(DS7=0,"",DS7) | BW7: =IFERROR(RANK(BU7,BU$6:BU$116,0),"") | BZ7: =IF(DU7=0,"",DU7) | CB7: =IFERROR(RANK(BZ7,BZ$6:BZ$116,0),"") | CE7: =IF(DW7=0,"",DW7) | CG7: =IFERROR(RANK(CE7,CE$6:CE$116,0),"") | CJ7: =IF(DY7=0,"",DY7) | CL7: =IFERROR(RANK(CJ7,CJ$6:CJ$116,0),"") | CO7: =IF(EA7=0,"",EA7) | CQ7: =IFERROR(RANK(CO7,CO$6:CO$116,0),"") | CS7: 40 | CT7: =IFERROR(AVERAGE(OFFSET('Data - For Rank'!B$2,J7,0,COUNTIF($J$7:J$116,J7)))+IFERROR(VLOOKUP((COUNT($H$6:$H$116)/4),$ER$9:$ES$13,2,FALSE()),0),"") -> 18 | CV7: =IFERROR(AVERAGE(OFFSET('Data - For Rank'!$C$2,O7,0,COUNTIF(O$7:O$116,O7)))+IFERROR(VLOOKUP((COUNT(M$6:M$116)/4),$ER$9:$ES$13,2,FALSE()),0),"") | CW7: 37 | CX7: =IFERROR(AVERAGE(OFFSET('Data - For Rank'!D$2,T7,0,COUNTIF(T$7:T$116,T7)))+IFERROR(VLOOKUP((COUNT(R$6:R$116)/4),$ER$9:$ES$13,2,FALSE()),0),"") -> 14 | CZ7: =IFERROR(AVERAGE(OFFSET('Data - For Rank'!E$2,Y7,0,COUNTIF(Y$7:Y$116,Y7)))+IFERROR(VLOOKUP((COUNT(W$6:W$116)/4),$ER$9:$ES$13,2,FALSE()),0),"") | DA7: 33 | DB7: =IFERROR(AVERAGE(OFFSET('Data - For Rank'!F$2,AD7,0,COUNTIF(AD$7:AD$116,AD7)))+IFERROR(VLOOKUP((COUNT(AB$6:AB$116)/4),$ER$9:$ES$13,2,FALSE()),0),"") -> 14 | DC7: 35 | DD7: =IFERROR(AVERAGE(OFFSET('Data - For Rank'!G$2,AI7,0,COUNTIF(AI$7:AI$116,AI7)))+IFERROR(VLOOKUP((COUNT(AG$6:AG$116)/4),$ER$9:$ES$13,2,FALSE()),0),"") -> 13.5 | DE7: 34 | DF7: =IFERROR(AVERAGE(OFFSET('Data - For Rank'!$H$2,AN7,0,COUNTIF(AN$7:AN$116,AN7)))+IFERROR(VLOOKUP((COUNT(AL$6:AL$116)/4),$ER$9:$ES$13,2,FALSE()),0),"") -> 10.5 | DG7: 37 | DH7: =IFERROR(AVERAGE(OFFSET('Data - For Rank'!$I$2,AS7,0,COUNTIF(AS$7:AS$116,AS7)))+IFERROR(VLOOKUP((COUNT(AQ$6:AQ$116)/4),$ER$9:$ES$13,2,FALSE()),0),"") -> 17 | DI7: 38 | DJ7: =IFERROR(AVERAGE(OFFSET('Data - For Rank'!$J$2,AX7,0,COUNTIF(AX$7:AX$116,AX7)))+IFERROR(VLOOKUP((COUNT(AV$6:AV$116)/4),$ER$9:$ES$13,2,FALSE()),0),"") -> 15 | DK7: 37 | DL7: =IFERROR(AVERAGE(OFFSET('Data - For Rank'!$K$2,BC7,0,COUNTIF(BC$7:BC$116,BC7)))+IFERROR(VLOOKUP((COUNT(BA$6:BA$116)/4),$ER$9:$ES$13,2,FALSE()),0),"") -> 15.5 | DN7: =IFERROR(AVERAGE(OFFSET('Data - For Rank'!$L$2,BH7,0,COUNTIF(BH$7:BH$116,BH7)))+IFERROR(VLOOKUP((COUNT(BF$6:BF$116)/4),$ER$9:$ES$13,2,FALSE()),0),"") | DP7: =IFERROR(AVERAGE(OFFSET('Data - For Rank'!$M$2,BM7,0,COUNTIF(BM$7:BM$116,BM7)))+IFERROR(VLOOKUP((COUNT(BK$6:BK$116)/4),$ER$9:$ES$13,2,FALSE()),0),"") | DR7: =IFERROR(AVERAGE(OFFSET('Data - For Rank'!$N$2,BR7,0,COUNTIF(BR$7:BR$116,BR7)))+IFERROR(VLOOKUP((COUNT(BP$6:BP$116)/4),$ER$9:$ES$13,2,FALSE()),0),"") | DT7: =IFERROR(AVERAGE(OFFSET('Data - For Rank'!$O$2,BW7,0,COUNTIF(BW$7:BW$116,BW7)))+IFERROR(VLOOKUP((COUNT(BU$6:BU$116)/4),$ER$9:$ES$13,2,FALSE()),0),"") | DV7: =IFERROR(AVERAGE(OFFSET('Data - For Rank'!$P$2,CB7,0,COUNTIF(CB$7:CB$116,CB7)))+IFERROR(VLOOKUP((COUNT(BZ$6:BZ$116)/4),$ER$9:$ES$13,2,FALSE()),0),"") | DX7: =IFERROR(AVERAGE(OFFSET('Data - For Rank'!$Q$2,CG7,0,COUNTIF(CG$7:CG$116,CG7)))+IFERROR(VLOOKUP((COUNT(CE$6:CE$116)/4),$ER$9:$ES$13,2,FALSE()),0),"") | DZ7: =IFERROR(AVERAGE(OFFSET('Data - For Rank'!$R$2,CL7,0,COUNTIF(CL$7:CL$116,CL7)))+IFERROR(VLOOKUP((COUNT(CJ$6:CJ$116)/4),$ER$9:$ES$13,2,FALSE()),0),"") | EB7: =IFERROR(AVERAGE(OFFSET('Data - For Rank'!$S$2,CQ7,0,COUNTIF(CQ$7:CQ$116,CQ7)))+IFERROR(VLOOKUP((COUNT(CO$6:CO$116)/4),$ER$9:$ES$13,2,FALSE()),0),"") | EC7: =AVERAGE(CS7,CU7,CW7,CY7,DA7,DC7,DE7,DG7,DI7,DK7,DM7,DO7,DQ7,DS7,DU7,DW7,DY7,EA7) -> 36.375 | ED7: =AVERAGE(CX7,CT7,CV7,CZ7,DB7,DD7,DF7,DH7,DJ7,DL7,DN7,DP7,DR7,DT7,DV7,DX7,DZ7,EB7) -> 14.6875
B8: =B6+0.023 -> 1.023 | D8: JM2 | E8: cash +/- | F8: =IF(COUNT(G6:CN6)>10,SMALL(G6:CN6,COUNT(G6:CN6)-10),MIN(G6:CN6)) -> 23 | I8: =IF(CS8=0,"",CS8) -> 35 | K8: =IFERROR(_xlfn.RANK.EQ(I8,I$6:I$116,0),"") -> 1 | N8: =IF(CU8=0,"",CU8) | P8: =IFERROR(_xlfn.RANK.EQ(N8,N$6:N$116,0),"") | S8: =IF(CW8=0,"",CW8) -> 4 | U8: =IFERROR(_xlfn.RANK.EQ(S8,S$6:S$116,0),"") -> 4 | X8: =IF(CY8=0,"",CY8) | Z8: =IFERROR(_xlfn.RANK.EQ(X8,X$6:X$116,0),"") | AC8: =IF(DA8=0,"",DA8) -> 38 | AE8: =IFERROR(_xlfn.RANK.EQ(AC8,AC$6:AC$116,0),"") -> 2 | AH8: =IF(DC8=0,"",DC8) -> -0.001 | AJ8: =IFERROR(_xlfn.RANK.EQ(AH8,AH$6:AH$116,0),"") -> 8 | AM8: =IF(DE8=0,"",DE8) -> 16 | AO8: =IFERROR(_xlfn.RANK.EQ(AM8,AM$6:AM$116,0),"") -> 1 | AR8: =IF(DG8=0,"",DG8) -> -2 | AT8: =IFERROR(_xlfn.RANK.EQ(AR8,AR$6:AR$116,0),"") -> 10 | AW8: =IF(DI8=0,"",DI8) -> 5 | AY8: =IFERROR(_xlfn.RANK.EQ(AW8,AW$6:AW$116,0),"") -> 5 | BB8: =IF(DK8=0,"",DK8) -> 16 | BD8: =IFERROR(_xlfn.RANK.EQ(BB8,BB$6:BB$116,0),"") -> 2 | BG8: =IF(DM8=0,"",DM8) | BI8: =IFERROR(_xlfn.RANK.EQ(BG8,BG$6:BG$116,0),"") | BL8: =IF(DO8=0,"",DO8) | BN8: =IFERROR(_xlfn.RANK.EQ(BL8,BL$6:BL$116,0),"") | BQ8: =IF(DQ8=0,"",DQ8) | BS8: =IFERROR(_xlfn.RANK.EQ(BQ8,BQ$6:BQ$116,0),"") | BV8: =IF(DS8=0,"",DS8) | BX8: =IFERROR(_xlfn.RANK.EQ(BV8,BV$6:BV$116,0),"") | CA8: =IF(DU8=0,"",DU8) | CC8: =IFERROR(_xlfn.RANK.EQ(CA8,CA$6:CA$116,0),"") | CF8: =IF(DW8=0,"",DW8) | CH8: =IFERROR(_xlfn.RANK.EQ(CF8,CF$6:CF$116,0),"") | CK8: =IF(DY8=0,"",DY8) | CM8: =IFERROR(_xlfn.RANK.EQ(CK8,CK$6:CK$116,0),"") | CP8: =IF(EA8=0,"",EA8) | CR8: =IFERROR(_xlfn.RANK.EQ(CP8,CP$6:CP$116,0),"") | CS8: 35 | CT8: =IFERROR(AVERAGE(OFFSET('Data - For Rank'!B$2,K8,0,COUNTIF(K$6:K$116,K8)))+IFERROR(VLOOKUP((COUNT($I$6:$I$116)/4),$ER$9:$ES$13,2,FALSE()),0),"") -> 18 | CV8: =IFERROR(AVERAGE(OFFSET('Data - For Rank'!$C$2,P8,0,COUNTIF(P$6:P$116,P8)))+IFERROR(VLOOKUP((COUNT(N$6:N$116)/4),$ER$9:$ES$13,2,FALSE()),0),"") | CW8: 4 | CX8: =IFERROR(AVERAGE(OFFSET('Data - For Rank'!D$2,U8,0,COUNTIF(U$6:$U116,U8)))+IFERROR(VLOOKUP((COUNT(S$6:S$116)/4),$ER$9:$ES$13,2,FALSE()),0),"") -> 12.5 | CZ8: =IFERROR(AVERAGE(OFFSET('Data - For Rank'!E$2,Z8,0,COUNTIF(Z$6:Z$116,Z8)))+IFERROR(VLOOKUP((COUNT(W$6:W$116)/4),$ER$9:$ES$13,2,FALSE()),0),"") | DA8: 38 | DB8: =IFERROR(AVERAGE(OFFSET('Data - For Rank'!F$2,AE8,0,COUNTIF(AE$6:AE$116,AE8)))+IFERROR(VLOOKUP((COUNT(AC$6:AC$116)/4),$ER$9:$ES$13,2,FALSE()),0),"") -> 17 | DC8: -0.001 | DD8: =IFERROR(AVERAGE(OFFSET('Data - For Rank'!G$2,AJ8,0,COUNTIF(AJ$6:AJ$116,AJ8)))+IFERROR(VLOOKUP((COUNT(AH$6:AH$116)/4),$ER$9:$ES$13,2,FALSE()),0),"") -> 9.5 | DE8: 16 | DF8: =IFERROR(AVERAGE(OFFSET('Data - For Rank'!$H$2,AO8,0,COUNTIF(AO$6:AO$116,AO8)))+IFERROR(VLOOKUP((COUNT(AM$6:AM$116)/4),$ER$9:$ES$13,2,FALSE()),0),"") -> 16 | DG8: -2 | DH8: =IFERROR(AVERAGE(OFFSET('Data - For Rank'!$I$2,AT8,0,COUNTIF(AT$6:AT$116,AT8)))+IFERROR(VLOOKUP((COUNT(AR$6:AR$116)/4),$ER$9:$ES$13,2,FALSE()),0),"") -> 8.5 | DI8: 5 | DJ8: =IFERROR(AVERAGE(OFFSET('Data - For Rank'!$J$2,AY8,0,COUNTIF(AY$6:AY$116,AY8)))+IFERROR(VLOOKUP((COUNT(AW$6:AW$116)/4),$ER$9:$ES$13,2,FALSE()),0),"") -> 13.5 | DK8: 16 | DL8: =IFERROR(AVERAGE(OFFSET('Data - For Rank'!$K$2,BD8,0,COUNTIF(BD$6:BD$116,BD8)))+IFERROR(VLOOKUP((COUNT(BB$6:BB$116)/4),$ER$9:$ES$13,2,FALSE()),0),"") -> 14 | DN8: =IFERROR(AVERAGE(OFFSET('Data - For Rank'!$L$2,BI8,0,COUNTIF(BI$6:BI$116,BI8)))+IFERROR(VLOOKUP((COUNT(BG$6:BG$116)/4),$ER$9:$ES$13,2,FALSE()),0),"") | DP8: =IFERROR(AVERAGE(OFFSET('Data - For Rank'!$M$2,BN8,0,COUNTIF(BN$6:BN$116,BN8)))+IFERROR(VLOOKUP((COUNT(BL$6:BL$116)/4),$ER$9:$ES$13,2,FALSE()),0),"") | DR8: =IFERROR(AVERAGE(OFFSET('Data - For Rank'!$N$2,BS8,0,COUNTIF(BS$6:BS$116,BS8)))+IFERROR(VLOOKUP((COUNT(BQ$6:BQ$116)/4),$ER$9:$ES$13,2,FALSE()),0),"") | DT8: =IFERROR(AVERAGE(OFFSET('Data - For Rank'!$O$2,BX8,0,COUNTIF(BX$6:BX$116,BX8)))+IFERROR(VLOOKUP((COUNT(BV$6:BV$116)/4),$ER$9:$ES$13,2,FALSE()),0),"") | DV8: =IFERROR(AVERAGE(OFFSET('Data - For Rank'!$P$2,CC8,0,COUNTIF(CC$6:CC$116,CC8)))+IFERROR(VLOOKUP((COUNT(CA$6:CA$116)/4),$ER$9:$ES$13,2,FALSE()),0),"") | DX8: =IFERROR(AVERAGE(OFFSET('Data - For Rank'!$Q$2,CH8,0,COUNTIF(CH$6:CH$116,CH8)))+IFERROR(VLOOKUP((COUNT(CF$6:CF$116)/4),$ER$9:$ES$13,2,FALSE()),0),"") | DZ8: =IFERROR(AVERAGE(OFFSET('Data - For Rank'!$R$2,CM8,0,COUNTIF(CM$6:CM$116,CM8)))+IFERROR(VLOOKUP((COUNT(CK$6:CK$116)/4),$ER$9:$ES$13,2,FALSE()),0),"") | EB8: =IFERROR(AVERAGE(OFFSET('Data - For Rank'!$S$2,CR8,0,COUNTIF(CR$6:CR$116,CR8)))+IFERROR(VLOOKUP((COUNT(CP$6:CP$116)/4),$ER$9:$ES$13,2,FALSE()),0),"") | EC8: =CS8+CU8+CW8+CY8+DA8+DC8+DE8+DG8+DI8+DK8+DM8+DO8+DQ8+DS8+DU8+DW8+DY8+EA8 -> 111.999 | ED8: =AVERAGE(CT8,CV8,CX8,CZ8,DB8,DD8,DF8,DH8,DJ8,DL8,DN8,DP8,DR8,DT8,DV8,DX8,DZ8,EB8) -> 13.625 | EM8: Points | EQ8: Players | ER8: Groups | ES8: Extra Points | EU8: Total Points Out
B9: =_xlfn.RANK.EQ(C9,$C$6:$C$63,) -> 2 | C9: =EC9 -> 195 | D9: BM | E9: Ben McGinnis | F9: =COUNT(CT9,CV9,CX9,CZ9,DB9,DD9,DF9,DH9,DJ9,DL9,DN9,DP9,DR9,DT9,DV9,DX9,DZ9,EB9) -> 8 | G9: =IF(CT9=0,"",CT9) -> 23 | L9: =IF(CV9=0,"",CV9) | Q9: =IF(CX9=0,"",CX9) | V9: =IF(CZ9=0,"",CZ9) -> 21.5 | AA9: =IF(DB9=0,"",DB9) -> 29 | AF9: =IF(DD9=0,"",DD9) -> 17.5 | AK9: =IF(DF9=0,"",DF9) -> 21.5 | AP9: =IF(DH9=0,"",DH9) -> 29.5 | AU9: =IF(DJ9=0,"",DJ9) -> 35 | AZ9: =IF(DL9=0,"",DL9) -> 18 | BE9: =IF(DN9=0,"",DN9) | BJ9: =IF(DP9=0,"",DP9) | BO9: =IF(DR9=0,"",DR9) | BT9: =IF(DT9=0,"",DT9) | BY9: =IF(DV9=0,"",DV9) | CD9: =IF(DX9=0,"",DX9) | CI9: =IF(DZ9=0,"",DZ9) | CN9: =IF(EB9=0,"",EB9) | CS9: 80 | CT9: =IFERROR(CT10+CT11,"") -> 23 | CV9: =IFERROR(CV10+CV11,"") | CX9: =IFERROR(CX10+CX11,"") | CY9: 81 | CZ9: =IFERROR(CZ10+CZ11,"") -> 21.5 | DA9: 83 | DB9: =IFERROR(DB10+DB11,"") -> 29 | DC9: 84 | DD9: =IFERROR(DD10+DD11,"") -> 17.5 | DE9: 79 | DF9: =IFERROR(DF10+DF11,"") -> 21.5 | DG9: 79 | DH9: =IFERROR(DH10+DH11,"") -> 29.5 | DI9: 76 | DJ9: =IFERROR(DJ10+DJ11,"") -> 35 | DK9: 81 | DL9: =IFERROR(DL10+DL11,"") -> 18 | DN9: =IFERROR(DN10+DN11,"") | DP9: =IFERROR(DP10+DP11,"") | DR9: =IFERROR(DR10+DR11,"") | DT9: =IFERROR(DT10+DT11,"") | DV9: =IFERROR(DV10+DV11,"") | DX9: =IFERROR(DX10+DX11,"") | DZ9: =IFERROR(DZ10+DZ11,"") | EB9: =IFERROR(EB10+EB11,"") | EC9: =IFERROR(LARGE($G9:$CN9,1),0)+IFERROR(LARGE($G9:$CN9,2),0)+IFERROR(LARGE($G9:$CN9,3),0)+IFERROR(LARGE($G9:$CN9,4),0)+IFERROR(LARGE($G9:$CN9,5),0)+IFERROR(LARGE($G9:$CN9,6),0)+IFERROR(LARGE($G9:$CN9,7),0)+IFERROR(LARGE($G9:$CN9,8),0)+IFERROR(LARGE($G9:$CN9,9),0)+IFERROR(LARGE($G9:$CN9,10),0) -> 195 | ED9: =AVERAGE(CT9,CV9,CX9,CZ9,DB9,DD9,DF9,DH9,DJ9,DL9,DN9,DP9,DR9,DT9,DV9,DX9,DZ9,EB9) -> 24.375 | EM9: 5 foursomes – first gets 20, last gets 1 | EQ9: 20 | ER9: 5 | ES9: 0 | EU9: =40+38+36+34+32+30+28+26+24+22+20+18+16+14+12+10+8+6+4+2 -> 420
B10: =B9+0.15 -> 2.15 | D10: BM1 | E10: Harvey Points | H10: =IF(CS10=0,"",CS10) -> 34 | J10: =IFERROR(RANK(H10,H$6:H$116,0),"") -> 3 | M10: =IF(CU10=0,"",CU10) | O10: =IFERROR(RANK(M10,M$6:M$116,0),"") | R10: =IF(CW10=0,"",CW10) | T10: =IFERROR(RANK(R10,R$6:R$116,0),"") | W10: =IF(CY10=0,"",CY10) -> 32 | Y10: =IFERROR(RANK(W10,W$6:W$116,0),"") -> 2 | AB10: =IF(DA10=0,"",DA10) -> 33 | AD10: =IFERROR(RANK(AB10,AB$6:AB$116,0),"") -> 4 | AG10: =IF(DC10=0,"",DC10) -> 34 | AI10: =IFERROR(RANK(AG10,AG$6:AG$116,0),"") -> 7 | AL10: =IF(DE10=0,"",DE10) -> 36 | AN10: =IFERROR(RANK(AL10,AL$6:AL$116,0),"") -> 3 | AQ10: =IF(DG10=0,"",DG10) -> 36 | AS10: =IFERROR(RANK(AQ10,AQ$6:AQ$116,0),"") -> 3 | AV10: =IF(DI10=0,"",DI10) -> 41 | AX10: =IFERROR(RANK(AV10,AV$6:AV$116,0),"") -> 1 | BA10: =IF(DK10=0,"",DK10) -> 33 | BC10: =IFERROR(RANK(BA10,BA$6:BA$116,0),"") -> 7 | BF10: =IF(DM10=0,"",DM10) | BH10: =IFERROR(RANK(BF10,BF$6:BF$116,0),"") | BK10: =IF(DO10=0,"",DO10) | BM10: =IFERROR(RANK(BK10,BK$6:BK$116,0),"") | BP10: =IF(DQ10=0,"",DQ10) | BR10: =IFERROR(RANK(BP10,BP$6:BP$116,0),"") | BU10: =IF(DS10=0,"",DS10) | BW10: =IFERROR(RANK(BU10,BU$6:BU$116,0),"") | BZ10: =IF(DU10=0,"",DU10) | CB10: =IFERROR(RANK(BZ10,BZ$6:BZ$116,0),"") | CE10: =IF(DW10=0,"",DW10) | CG10: =IFERROR(RANK(CE10,CE$6:CE$116,0),"") | CJ10: =IF(DY10=0,"",DY10) | CL10: =IFERROR(RANK(CJ10,CJ$6:CJ$116,0),"") | CO10: =IF(EA10=0,"",EA10) | CQ10: =IFERROR(RANK(CO10,CO$6:CO$116,0),"") | CS10: 34 | CT10: =IFERROR(AVERAGE(OFFSET('Data - For Rank'!B$2,J10,0,COUNTIF($J$7:J$116,J10)))+IFERROR(VLOOKUP((COUNT($H$6:$H$116)/4),$ER$9:$ES$13,2,FALSE()),0),"") -> 16 | CV10: =IFERROR(AVERAGE(OFFSET('Data - For Rank'!$C$2,O10,0,COUNTIF(O$7:O$116,O10)))+IFERROR(VLOOKUP((COUNT(M$6:M$116)/4),$ER$9:$ES$13,2,FALSE()),0),"") | CX10: =IFERROR(AVERAGE(OFFSET('Data - For Rank'!D$2,T10,0,COUNTIF(T$7:T$116,T10)))+IFERROR(VLOOKUP((COUNT(R$6:R$116)/4),$ER$9:$ES$13,2,FALSE()),0),"") | CY10: 32 | CZ10: =IFERROR(AVERAGE(OFFSET('Data - For Rank'!E$2,Y10,0,COUNTIF(Y$7:Y$116,Y10)))+IFERROR(VLOOKUP((COUNT(W$6:W$116)/4),$ER$9:$ES$13,2,FALSE()),0),"") -> 12.5 | DA10: 33 | DB10: =IFERROR(AVERAGE(OFFSET('Data - For Rank'!F$2,AD10,0,COUNTIF(AD$7:AD$116,AD10)))+IFERROR(VLOOKUP((COUNT(AB$6:AB$116)/4),$ER$9:$ES$13,2,FALSE()),0),"") -> 14 | DC10: 34 | DD10: =IFERROR(AVERAGE(OFFSET('Data - For Rank'!G$2,AI10,0,COUNTIF(AI$7:AI$116,AI10)))+IFERROR(VLOOKUP((COUNT(AG$6:AG$116)/4),$ER$9:$ES$13,2,FALSE()),0),"") -> 11.5 | DE10: 36 | DF10: =IFERROR(AVERAGE(OFFSET('Data - For Rank'!$H$2,AN10,0,COUNTIF(AN$7:AN$116,AN10)))+IFERROR(VLOOKUP((COUNT(AL$6:AL$116)/4),$ER$9:$ES$13,2,FALSE()),0),"") -> 13.5 | DG10: 36 | DH10: =IFERROR(AVERAGE(OFFSET('Data - For Rank'!$I$2,AS10,0,COUNTIF(AS$7:AS$116,AS10)))+IFERROR(VLOOKUP((COUNT(AQ$6:AQ$116)/4),$ER$9:$ES$13,2,FALSE()),0),"") -> 15.5 | DI10: 41 | DJ10: =IFERROR(AVERAGE(OFFSET('Data - For Rank'!$J$2,AX10,0,COUNTIF(AX$7:AX$116,AX10)))+IFERROR(VLOOKUP((COUNT(AV$6:AV$116)/4),$ER$9:$ES$13,2,FALSE()),0),"") -> 18 | DK10: 33 | DL10: =IFERROR(AVERAGE(OFFSET('Data - For Rank'!$K$2,BC10,0,COUNTIF(BC$7:BC$116,BC10)))+IFERROR(VLOOKUP((COUNT(BA$6:BA$116)/4),$ER$9:$ES$13,2,FALSE()),0),"") -> 9.5 | DN10: =IFERROR(AVERAGE(OFFSET('Data - For Rank'!$L$2,BH10,0,COUNTIF(BH$7:BH$116,BH10)))+IFERROR(VLOOKUP((COUNT(BF$6:BF$116)/4),$ER$9:$ES$13,2,FALSE()),0),"") | DP10: =IFERROR(AVERAGE(OFFSET('Data - For Rank'!$M$2,BM10,0,COUNTIF(BM$7:BM$116,BM10)))+IFERROR(VLOOKUP((COUNT(BK$6:BK$116)/4),$ER$9:$ES$13,2,FALSE()),0),"") | DR10: =IFERROR(AVERAGE(OFFSET('Data - For Rank'!$N$2,BR10,0,COUNTIF(BR$7:BR$116,BR10)))+IFERROR(VLOOKUP((COUNT(BP$6:BP$116)/4),$ER$9:$ES$13,2,FALSE()),0),"") | DT10: =IFERROR(AVERAGE(OFFSET('Data - For Rank'!$O$2,BW10,0,COUNTIF(BW$7:BW$116,BW10)))+IFERROR(VLOOKUP((COUNT(BU$6:BU$116)/4),$ER$9:$ES$13,2,FALSE()),0),"") | DV10: =IFERROR(AVERAGE(OFFSET('Data - For Rank'!$P$2,CB10,0,COUNTIF(CB$7:CB$116,CB10)))+IFERROR(VLOOKUP((COUNT(BZ$6:BZ$116)/4),$ER$9:$ES$13,2,FALSE()),0),"") | DX10: =IFERROR(AVERAGE(OFFSET('Data - For Rank'!$Q$2,CG10,0,COUNTIF(CG$7:CG$116,CG10)))+IFERROR(VLOOKUP((COUNT(CE$6:CE$116)/4),$ER$9:$ES$13,2,FALSE()),0),"") | DZ10: =IFERROR(AVERAGE(OFFSET('Data - For Rank'!$R$2,CL10,0,COUNTIF(CL$7:CL$116,CL10)))+IFERROR(VLOOKUP((COUNT(CJ$6:CJ$116)/4),$ER$9:$ES$13,2,FALSE()),0),"") | EB10: =IFERROR(AVERAGE(OFFSET('Data - For Rank'!$S$2,CQ10,0,COUNTIF(CQ$7:CQ$116,CQ10)))+IFERROR(VLOOKUP((COUNT(CO$6:CO$116)/4),$ER$9:$ES$13,2,FALSE()),0),"") | EC10: =AVERAGE(CS10,CU10,CW10,CY10,DA10,DC10,DE10,DG10,DI10,DK10,DM10,DO10,DQ10,DS10,DU10,DW10,DY10,EA10) -> 34.875 | ED10: =AVERAGE(CT10,CV10,CX10,CZ10,DB10,DD10,DF10,DH10,DJ10,DL10,DN10,DP10,DR10,DT10,DV10,DX10,DZ10,EB10) -> 13.8125 | EM10: 4 foursomes – first gets 18, last gets 3 | EQ10: 16 | ER10: 4 | ES10: 2 | EU10: =36+34+32+30+28+26+24+22+20+18+16+14+12+10+8+6 -> 336
B11: =B9+0.025 -> 2.025 | D11: BM2 | E11: cash +/- | F11: =IF(COUNT(G9:CN9)>10,SMALL(G9:CN9,COUNT(G9:CN9)-10),MIN(G9:CN9)) -> 17.5 | I11: =IF(CS11=0,"",CS11) -> -10 | K11: =IFERROR(_xlfn.RANK.EQ(I11,I$6:I$116,0),"") -> 12 | N11: =IF(CU11=0,"",CU11) | P11: =IFERROR(_xlfn.RANK.EQ(N11,N$6:N$116,0),"") | S11: =IF(CW11=0,"",CW11) | U11: =IFERROR(_xlfn.RANK.EQ(S11,S$6:S$116,0),"") | X11: =IF(CY11=0,"",CY11) -> -15 | Z11: =IFERROR(_xlfn.RANK.EQ(X11,X$6:X$116,0),"") -> 6 | AC11: =IF(DA11=0,"",DA11) -> 20 | AE11: =IFERROR(_xlfn.RANK.EQ(AC11,AC$6:AC$116,0),"") -> 4 | AH11: =IF(DC11=0,"",DC11) -> -16 | AJ11: =IFERROR(_xlfn.RANK.EQ(AH11,AH$6:AH$116,0),"") -> 13 | AM11: =IF(DE11=0,"",DE11) -> -4 | AO11: =IFERROR(_xlfn.RANK.EQ(AM11,AM$6:AM$116,0),"") -> 9 | AR11: =IF(DG11=0,"",DG11) -> 12 | AT11: =IFERROR(_xlfn.RANK.EQ(AR11,AR$6:AR$116,0),"") -> 4 | AW11: =IF(DI11=0,"",DI11) -> 25 | AY11: =IFERROR(_xlfn.RANK.EQ(AW11,AW$6:AW$116,0),"") -> 2 | BB11: =IF(DK11=0,"",DK11) -> -8 | BD11: =IFERROR(_xlfn.RANK.EQ(BB11,BB$6:BB$116,0),"") -> 8 | BG11: =IF(DM11=0,"",DM11) | BI11: =IFERROR(_xlfn.RANK.EQ(BG11,BG$6:BG$116,0),"") | BL11: =IF(DO11=0,"",DO11) | BN11: =IFERROR(_xlfn.RANK.EQ(BL11,BL$6:BL$116,0),"") | BQ11: =IF(DQ11=0,"",DQ11) | BS11: =IFERROR(_xlfn.RANK.EQ(BQ11,BQ$6:BQ$116,0),"") | BV11: =IF(DS11=0,"",DS11) | BX11: =IFERROR(_xlfn.RANK.EQ(BV11,BV$6:BV$116,0),"") | CA11: =IF(DU11=0,"",DU11) | CC11: =IFERROR(_xlfn.RANK.EQ(CA11,CA$6:CA$116,0),"") | CF11: =IF(DW11=0,"",DW11) | CH11: =IFERROR(_xlfn.RANK.EQ(CF11,CF$6:CF$116,0),"") | CK11: =IF(DY11=0,"",DY11) | CM11: =IFERROR(_xlfn.RANK.EQ(CK11,CK$6:CK$116,0),"") | CP11: =IF(EA11=0,"",EA11) | CR11: =IFERROR(_xlfn.RANK.EQ(CP11,CP$6:CP$116,0),"") | CS11: -10 | CT11: =IFERROR(AVERAGE(OFFSET('Data - For Rank'!B$2,K11,0,COUNTIF(K$6:K$116,K11)))+IFERROR(VLOOKUP((COUNT($I$6:$I$116)/4),$ER$9:$ES$13,2,FALSE()),0),"") -> 7 | CV11: =IFERROR(AVERAGE(OFFSET('Data - For Rank'!$C$2,P11,0,COUNTIF(P$6:P$116,P11)))+IFERROR(VLOOKUP((COUNT(N$6:N$116)/4),$ER$9:$ES$13,2,FALSE()),0),"") | CX11: =IFERROR(AVERAGE(OFFSET('Data - For Rank'!D$2,U11,0,COUNTIF(U$6:$U119,U11)))+IFERROR(VLOOKUP((COUNT(S$6:S$116)/4),$ER$9:$ES$13,2,FALSE()),0),"") | CY11: -15 | CZ11: =IFERROR(AVERAGE(OFFSET('Data - For Rank'!E$2,Z11,0,COUNTIF(Z$6:Z$116,Z11)))+IFERROR(VLOOKUP((COUNT(W$6:W$116)/4),$ER$9:$ES$13,2,FALSE()),0),"") -> 9 | DA11: 20 | DB11: =IFERROR(AVERAGE(OFFSET('Data - For Rank'!F$2,AE11,0,COUNTIF(AE$6:AE$116,AE11)))+IFERROR(VLOOKUP((COUNT(AC$6:AC$116)/4),$ER$9:$ES$13,2,FALSE()),0),"") -> 15 | DC11: -16 | DD11: =IFERROR(AVERAGE(OFFSET('Data - For Rank'!G$2,AJ11,0,COUNTIF(AJ$6:AJ$116,AJ11)))+IFERROR(VLOOKUP((COUNT(AH$6:AH$116)/4),$ER$9:$ES$13,2,FALSE()),0),"") -> 6 | DE11: -4 | DF11: =IFERROR(AVERAGE(OFFSET('Data - For Rank'!$H$2,AO11,0,COUNTIF(AO$6:AO$116,AO11)))+IFERROR(VLOOKUP((COUNT(AM$6:AM$116)/4),$ER$9:$ES$13,2,FALSE()),0),"") -> 8 | DG11: 12 | DH11: =IFERROR(AVERAGE(OFFSET('Data - For Rank'!$I$2,AT11,0,COUNTIF(AT$6:AT$116,AT11)))+IFERROR(VLOOKUP((COUNT(AR$6:AR$116)/4),$ER$9:$ES$13,2,FALSE()),0),"") -> 14 | DI11: 25 | DJ11: =IFERROR(AVERAGE(OFFSET('Data - For Rank'!$J$2,AY11,0,COUNTIF(AY$6:AY$116,AY11)))+IFERROR(VLOOKUP((COUNT(AW$6:AW$116)/4),$ER$9:$ES$13,2,FALSE()),0),"") -> 17 | DK11: -8 | DL11: =IFERROR(AVERAGE(OFFSET('Data - For Rank'!$K$2,BD11,0,COUNTIF(BD$6:BD$116,BD11)))+IFERROR(VLOOKUP((COUNT(BB$6:BB$116)/4),$ER$9:$ES$13,2,FALSE()),0),"") -> 8.5 | DN11: =IFERROR(AVERAGE(OFFSET('Data - For Rank'!$L$2,BI11,0,COUNTIF(BI$6:BI$116,BI11)))+IFERROR(VLOOKUP((COUNT(BG$6:BG$116)/4),$ER$9:$ES$13,2,FALSE()),0),"") | DP11: =IFERROR(AVERAGE(OFFSET('Data - For Rank'!$M$2,BN11,0,COUNTIF(BN$6:BN$116,BN11)))+IFERROR(VLOOKUP((COUNT(BL$6:BL$116)/4),$ER$9:$ES$13,2,FALSE()),0),"") | DR11: =IFERROR(AVERAGE(OFFSET('Data - For Rank'!$N$2,BS11,0,COUNTIF(BS$6:BS$116,BS11)))+IFERROR(VLOOKUP((COUNT(BQ$6:BQ$116)/4),$ER$9:$ES$13,2,FALSE()),0),"") | DT11: =IFERROR(AVERAGE(OFFSET('Data - For Rank'!$O$2,BX11,0,COUNTIF(BX$6:BX$116,BX11)))+IFERROR(VLOOKUP((COUNT(BV$6:BV$116)/4),$ER$9:$ES$13,2,FALSE()),0),"") | DV11: =IFERROR(AVERAGE(OFFSET('Data - For Rank'!$P$2,CC11,0,COUNTIF(CC$6:CC$116,CC11)))+IFERROR(VLOOKUP((COUNT(CA$6:CA$116)/4),$ER$9:$ES$13,2,FALSE()),0),"") | DX11: =IFERROR(AVERAGE(OFFSET('Data - For Rank'!$Q$2,CH11,0,COUNTIF(CH$6:CH$116,CH11)))+IFERROR(VLOOKUP((COUNT(CF$6:CF$116)/4),$ER$9:$ES$13,2,FALSE()),0),"") | DZ11: =IFERROR(AVERAGE(OFFSET('Data - For Rank'!$R$2,CM11,0,COUNTIF(CM$6:CM$116,CM11)))+IFERROR(VLOOKUP((COUNT(CK$6:CK$116)/4),$ER$9:$ES$13,2,FALSE()),0),"") | EB11: =IFERROR(AVERAGE(OFFSET('Data - For Rank'!$S$2,CR11,0,COUNTIF(CR$6:CR$116,CR11)))+IFERROR(VLOOKUP((COUNT(CP$6:CP$116)/4),$ER$9:$ES$13,2,FALSE()),0),"") | EC11: =CS11+CU11+CW11+CY11+DA11+DC11+DE11+DG11+DI11+DK11+DM11+DO11+DQ11+DS11+DU11+DW11+DY11+EA11 -> 4 | ED11: =AVERAGE(CT11,CV11,CX11,CZ11,DB11,DD11,DF11,DH11,DJ11,DL11,DN11,DP11,DR11,DT11,DV11,DX11,DZ11,EB11) -> 10.5625 | EM11: 3 foursomes – first gets 16, last gets 5 | EQ11: 12 | ER11: 3 | ES11: 4 | EU11: =32+30+28+26+24+22+20+18+16+14+12+10 -> 252
B12: =_xlfn.RANK.EQ(C12,$C$6:$C$63,) -> 3 | C12: =EC12 -> 193 | D12: MW | E12: Matt White | F12: =COUNT(CT12,CV12,CX12,CZ12,DB12,DD12,DF12,DH12,DJ12,DL12,DN12,DP12,DR12,DT12,DV12,DX12,DZ12,EB12) -> 8 | G12: =IF(CT12=0,"",CT12) -> 20.5 | L12: =IF(CV12=0,"",CV12) | Q12: =IF(CX12=0,"",CX12) -> 31 | V12: =IF(CZ12=0,"",CZ12) -> 26.5 | AA12: =IF(DB12=0,"",DB12) -> 26.5 | AF12: =IF(DD12=0,"",DD12) -> 23.5 | AK12: =IF(DF12=0,"",DF12) -> 25.5 | AP12: =IF(DH12=0,"",DH12) -> 25.5 | AU12: =IF(DJ12=0,"",DJ12) -> 14 | AZ12: =IF(DL12=0,"",DL12) | BE12: =IF(DN12=0,"",DN12) | BJ12: =IF(DP12=0,"",DP12) | BO12: =IF(DR12=0,"",DR12) | BT12: =IF(DT12=0,"",DT12) | BY12: =IF(DV12=0,"",DV12) | CD12: =IF(DX12=0,"",DX12) | CI12: =IF(DZ12=0,"",DZ12) | CN12: =IF(EB12=0,"",EB12) | CS12: 84 | CT12: =IFERROR(CT13+CT14,"") -> 20.5 | CV12: =IFERROR(CV13+CV14,"") | CW12: 79 | CX12: =IFERROR(CX13+CX14,"") -> 31 | CY12: 82 | CZ12: =IFERROR(CZ13+CZ14,"") -> 26.5 | DA12: 86 | DB12: =IFERROR(DB13+DB14,"") -> 26.5 | DC12: 84 | DD12: =IFERROR(DD13+DD14,"") -> 23.5 | DE12: 80 | DF12: =IFERROR(DF13+DF14,"") -> 25.5 | DG12: 83 | DH12: =IFERROR(DH13+DH14,"") -> 25.5 | DI12: 96 | DJ12: =IFERROR(DJ13+DJ14,"") -> 14 | DL12: =IFERROR(DL13+DL14,"") | DN12: =IFERROR(DN13+DN14,"") | DP12: =IFERROR(DP13+DP14,"") | DR12: =IFERROR(DR13+DR14,"") | DT12: =IFERROR(DT13+DT14,"") | DV12: =IFERROR(DV13+DV14,"") | DX12: =IFERROR(DX13+DX14,"") | DZ12: =IFERROR(DZ13+DZ14,"") | EB12: =IFERROR(EB13+EB14,"") | EC12: =IFERROR(LARGE($G12:$CN12,1),0)+IFERROR(LARGE($G12:$CN12,2),0)+IFERROR(LARGE($G12:$CN12,3),0)+IFERROR(LARGE($G12:$CN12,4),0)+IFERROR(LARGE($G12:$CN12,5),0)+IFERROR(LARGE($G12:$CN12,6),0)+IFERROR(LARGE($G12:$CN12,7),0)+IFERROR(LARGE($G12:$CN12,8),0)+IFERROR(LARGE($G12:$CN12,9),0)+IFERROR(LARGE($G12:$CN12,10),0) -> 193 | ED12: =AVERAGE(CT12,CV12,CX12,CZ12,DB12,DD12,DF12,DH12,DJ12,DL12,DN12,DP12,DR12,DT12,DV12,DX12,DZ12,EB12) -> 24.125 | EM12: 2 foursomes – first gets 14, last gets 7 | EQ12: 8 | ER12: 2 | ES12: 6 | EU12: =28+26+24+22+20+18+16+14 -> 168
B13: =B12+0.11 -> 3.11 | D13: MW1 | E13: Harvey Points | H13: =IF(CS13=0,"",CS13) -> 32 | J13: =IFERROR(RANK(H13,H$6:H$116,0),"") -> 6 | M13: =IF(CU13=0,"",CU13) | O13: =IFERROR(RANK(M13,M$6:M$116,0),"") | R13: =IF(CW13=0,"",CW13) -> 39 | T13: =IFERROR(RANK(R13,R$6:R$116,0),"") -> 2 | W13: =IF(CY13=0,"",CY13) -> 32 | Y13: =IFERROR(RANK(W13,W$6:W$116,0),"") -> 2 | AB13: =IF(DA13=0,"",DA13) -> 30 | AD13: =IFERROR(RANK(AB13,AB$6:AB$116,0),"") -> 10 | AG13: =IF(DC13=0,"",DC13) -> 34 | AI13: =IFERROR(RANK(AG13,AG$6:AG$116,0),"") -> 7 | AL13: =IF(DE13=0,"",DE13) -> 34 | AN13: =IFERROR(RANK(AL13,AL$6:AL$116,0),"") -> 5 | AQ13: =IF(DG13=0,"",DG13) -> 33 | AS13: =IFERROR(RANK(AQ13,AQ$6:AQ$116,0),"") -> 7 | AV13: =IF(DI13=0,"",DI13) -> 23 | AX13: =IFERROR(RANK(AV13,AV$6:AV$116,0),"") -> 16 | BA13: =IF(DK13=0,"",DK13) | BC13: =IFERROR(RANK(BA13,BA$6:BA$116,0),"") | BF13: =IF(DM13=0,"",DM13) | BH13: =IFERROR(RANK(BF13,BF$6:BF$116,0),"") | BK13: =IF(DO13=0,"",DO13) | BM13: =IFERROR(RANK(BK13,BK$6:BK$116,0),"") | BP13: =IF(DQ13=0,"",DQ13) | BR13: =IFERROR(RANK(BP13,BP$6:BP$116,0),"") | BU13: =IF(DS13=0,"",DS13) | BW13: =IFERROR(RANK(BU13,BU$6:BU$116,0),"") | BZ13: =IF(DU13=0,"",DU13) | CB13: =IFERROR(RANK(BZ13,BZ$6:BZ$116,0),"") | CE13: =IF(DW13=0,"",DW13) | CG13: =IFERROR(RANK(CE13,CE$6:CE$116,0),"") | CJ13: =IF(DY13=0,"",DY13) | CL13: =IFERROR(RANK(CJ13,CJ$6:CJ$116,0),"") | CO13: =IF(EA13=0,"",EA13) | CQ13: =IFERROR(RANK(CO13,CO$6:CO$116,0),"") | CS13: 32 | CT13: =IFERROR(AVERAGE(OFFSET('Data - For Rank'!B$2,J13,0,COUNTIF($J$7:J$116,J13)))+IFERROR(VLOOKUP((COUNT($H$6:$H$116)/4),$ER$9:$ES$13,2,FALSE()),0),"") -> 12.5 | CV13: =IFERROR(AVERAGE(OFFSET('Data - For Rank'!$C$2,O13,0,COUNTIF(O$7:O$116,O13)))+IFERROR(VLOOKUP((COUNT(M$6:M$116)/4),$ER$9:$ES$13,2,FALSE()),0),"") | CW13: 39 | CX13: =IFERROR(AVERAGE(OFFSET('Data - For Rank'!D$2,T13,0,COUNTIF(T$7:T$116,T13)))+IFERROR(VLOOKUP((COUNT(R$6:R$116)/4),$ER$9:$ES$13,2,FALSE()),0),"") -> 15 | CY13: 32 | CZ13: =IFERROR(AVERAGE(OFFSET('Data - For Rank'!E$2,Y13,0,COUNTIF(Y$7:Y$116,Y13)))+IFERROR(VLOOKUP((COUNT(W$6:W$116)/4),$ER$9:$ES$13,2,FALSE()),0),"") -> 12.5 | DA13: 30 | DB13: =IFERROR(AVERAGE(OFFSET('Data - For Rank'!F$2,AD13,0,COUNTIF(AD$7:AD$116,AD13)))+IFERROR(VLOOKUP((COUNT(AB$6:AB$116)/4),$ER$9:$ES$13,2,FALSE()),0),"") -> 8.5 | DC13: 34 | DD13: =IFERROR(AVERAGE(OFFSET('Data - For Rank'!G$2,AI13,0,COUNTIF(AI$7:AI$116,AI13)))+IFERROR(VLOOKUP((COUNT(AG$6:AG$116)/4),$ER$9:$ES$13,2,FALSE()),0),"") -> 11.5 | DE13: 34 | DF13: =IFERROR(AVERAGE(OFFSET('Data - For Rank'!$H$2,AN13,0,COUNTIF(AN$7:AN$116,AN13)))+IFERROR(VLOOKUP((COUNT(AL$6:AL$116)/4),$ER$9:$ES$13,2,FALSE()),0),"") -> 10.5 | DG13: 33 | DH13: =IFERROR(AVERAGE(OFFSET('Data - For Rank'!$I$2,AS13,0,COUNTIF(AS$7:AS$116,AS13)))+IFERROR(VLOOKUP((COUNT(AQ$6:AQ$116)/4),$ER$9:$ES$13,2,FALSE()),0),"") -> 11.5 | DI13: 23 | DJ13: =IFERROR(AVERAGE(OFFSET('Data - For Rank'!$J$2,AX13,0,COUNTIF(AX$7:AX$116,AX13)))+IFERROR(VLOOKUP((COUNT(AV$6:AV$116)/4),$ER$9:$ES$13,2,FALSE()),0),"") -> 3 | DL13: =IFERROR(AVERAGE(OFFSET('Data - For Rank'!$K$2,BC13,0,COUNTIF(BC$7:BC$116,BC13)))+IFERROR(VLOOKUP((COUNT(BA$6:BA$116)/4),$ER$9:$ES$13,2,FALSE()),0),"") | DN13: =IFERROR(AVERAGE(OFFSET('Data - For Rank'!$L$2,BH13,0,COUNTIF(BH$7:BH$116,BH13)))+IFERROR(VLOOKUP((COUNT(BF$6:BF$116)/4),$ER$9:$ES$13,2,FALSE()),0),"") | DP13: =IFERROR(AVERAGE(OFFSET('Data - For Rank'!$M$2,BM13,0,COUNTIF(BM$7:BM$116,BM13)))+IFERROR(VLOOKUP((COUNT(BK$6:BK$116)/4),$ER$9:$ES$13,2,FALSE()),0),"") | DR13: =IFERROR(AVERAGE(OFFSET('Data - For Rank'!$N$2,BR13,0,COUNTIF(BR$7:BR$116,BR13)))+IFERROR(VLOOKUP((COUNT(BP$6:BP$116)/4),$ER$9:$ES$13,2,FALSE()),0),"") | DT13: =IFERROR(AVERAGE(OFFSET('Data - For Rank'!$O$2,BW13,0,COUNTIF(BW$7:BW$116,BW13)))+IFERROR(VLOOKUP((COUNT(BU$6:BU$116)/4),$ER$9:$ES$13,2,FALSE()),0),"") | DV13: =IFERROR(AVERAGE(OFFSET('Data - For Rank'!$P$2,CB13,0,COUNTIF(CB$7:CB$116,CB13)))+IFERROR(VLOOKUP((COUNT(BZ$6:BZ$116)/4),$ER$9:$ES$13,2,FALSE()),0),"") | DX13: =IFERROR(AVERAGE(OFFSET('Data - For Rank'!$Q$2,CG13,0,COUNTIF(CG$7:CG$116,CG13)))+IFERROR(VLOOKUP((COUNT(CE$6:CE$116)/4),$ER$9:$ES$13,2,FALSE()),0),"") | DZ13: =IFERROR(AVERAGE(OFFSET('Data - For Rank'!$R$2,CL13,0,COUNTIF(CL$7:CL$116,CL13)))+IFERROR(VLOOKUP((COUNT(CJ$6:CJ$116)/4),$ER$9:$ES$13,2,FALSE()),0),"") | EB13: =IFERROR(AVERAGE(OFFSET('Data - For Rank'!$S$2,CQ13,0,COUNTIF(CQ$7:CQ$116,CQ13)))+IFERROR(VLOOKUP((COUNT(CO$6:CO$116)/4),$ER$9:$ES$13,2,FALSE()),0),"") | EC13: =AVERAGE(CS13,CU13,CW13,CY13,DA13,DC13,DE13,DG13,DI13,DK13,DM13,DO13,DQ13,DS13,DU13,DW13,DY13,EA13) -> 32.125 | ED13: =AVERAGE(CT13,CV13,CX13,CZ13,DB13,DD13,DF13,DH13,DJ13,DL13,DN13,DP13,DR13,DT13,DV13,DX13,DZ13,EB13) -> 10.625 | EM13: 1 foursome – first gets 12, last gets 9 | EQ13: 4 | ER13: 1 | ES13: 8 | EU13: =24+22+20+18 -> 84
B14: =B12+0.021 -> 3.021 | D14: MW2 | E14: cash +/- | F14: =IF(COUNT(G12:CN12)>10,SMALL(G12:CN12,COUNT(G12:CN12)-10),MIN(G12:CN12)) -> 14 | I14: =IF(CS14=0,"",CS14) -> -9 | K14: =IFERROR(_xlfn.RANK.EQ(I14,I$6:I$116,0),"") -> 11 | N14: =IF(CU14=0,"",CU14) | P14: =IFERROR(_xlfn.RANK.EQ(N14,N$6:N$116,0),"") | S14: =IF(CW14=0,"",CW14) -> 30 | U14: =IFERROR(_xlfn.RANK.EQ(S14,S$6:S$116,0),"") -> 1 | X14: =IF(CY14=0,"",CY14) -> 43 | Z14: =IFERROR(_xlfn.RANK.EQ(X14,X$6:X$116,0),"") -> 1 | AC14: =IF(DA14=0,"",DA14) -> 40 | AE14: =IFERROR(_xlfn.RANK.EQ(AC14,AC$6:AC$116,0),"") -> 1 | AH14: =IF(DC14=0,"",DC14) -> 1 | AJ14: =IFERROR(_xlfn.RANK.EQ(AH14,AH$6:AH$116,0),"") -> 7 | AM14: =IF(DE14=0,"",DE14) -> 8 | AO14: =IFERROR(_xlfn.RANK.EQ(AM14,AM$6:AM$116,0),"") -> 2 | AR14: =IF(DG14=0,"",DG14) -> 12 | AT14: =IFERROR(_xlfn.RANK.EQ(AR14,AR$6:AR$116,0),"") -> 4 | AW14: =IF(DI14=0,"",DI14) -> 3 | AY14: =IFERROR(_xlfn.RANK.EQ(AW14,AW$6:AW$116,0),"") -> 7 | BB14: =IF(DK14=0,"",DK14) | BD14: =IFERROR(_xlfn.RANK.EQ(BB14,BB$6:BB$116,0),"") | BG14: =IF(DM14=0,"",DM14) | BI14: =IFERROR(_xlfn.RANK.EQ(BG14,BG$6:BG$116,0),"") | BL14: =IF(DO14=0,"",DO14) | BN14: =IFERROR(_xlfn.RANK.EQ(BL14,BL$6:BL$116,0),"") | BQ14: =IF(DQ14=0,"",DQ14) | BS14: =IFERROR(_xlfn.RANK.EQ(BQ14,BQ$6:BQ$116,0),"") | BV14: =IF(DS14=0,"",DS14) | BX14: =IFERROR(_xlfn.RANK.EQ(BV14,BV$6:BV$116,0),"") | CA14: =IF(DU14=0,"",DU14) | CC14: =IFERROR(_xlfn.RANK.EQ(CA14,CA$6:CA$116,0),"") | CF14: =IF(DW14=0,"",DW14) | CH14: =IFERROR(_xlfn.RANK.EQ(CF14,CF$6:CF$116,0),"") | CK14: =IF(DY14=0,"",DY14) | CM14: =IFERROR(_xlfn.RANK.EQ(CK14,CK$6:CK$116,0),"") | CP14: =IF(EA14=0,"",EA14) | CR14: =IFERROR(_xlfn.RANK.EQ(CP14,CP$6:CP$116,0),"") | CS14: -9 | CT14: =IFERROR(AVERAGE(OFFSET('Data - For Rank'!B$2,K14,0,COUNTIF(K$6:K$116,K14)))+IFERROR(VLOOKUP((COUNT($I$6:$I$116)/4),$ER$9:$ES$13,2,FALSE()),0),"") -> 8 | CV14: =IFERROR(AVERAGE(OFFSET('Data - For Rank'!$C$2,P14,0,COUNTIF(P$6:P$116,P14)))+IFERROR(VLOOKUP((COUNT(N$6:N$116)/4),$ER$9:$ES$13,2,FALSE()),0),"") | CW14: 30 | CX14: =IFERROR(AVERAGE(OFFSET('Data - For Rank'!D$2,U14,0,COUNTIF(U$6:$U122,U14)))+IFERROR(VLOOKUP((COUNT(S$6:S$116)/4),$ER$9:$ES$13,2,FALSE()),0),"") -> 16 | CY14: 43 | CZ14: =IFERROR(AVERAGE(OFFSET('Data - For Rank'!E$2,Z14,0,COUNTIF(Z$6:Z$116,Z14)))+IFERROR(VLOOKUP((COUNT(W$6:W$116)/4),$ER$9:$ES$13,2,FALSE()),0),"") -> 14 | DA14: 40 | DB14: =IFERROR(AVERAGE(OFFSET('Data - For Rank'!F$2,AE14,0,COUNTIF(AE$6:AE$116,AE14)))+IFERROR(VLOOKUP((COUNT(AC$6:AC$116)/4),$ER$9:$ES$13,2,FALSE()),0),"") -> 18 | DC14: 1 | DD14: =IFERROR(AVERAGE(OFFSET('Data - For Rank'!G$2,AJ14,0,COUNTIF(AJ$6:AJ$116,AJ14)))+IFERROR(VLOOKUP((COUNT(AH$6:AH$116)/4),$ER$9:$ES$13,2,FALSE()),0),"") -> 12 | DE14: 8 | DF14: =IFERROR(AVERAGE(OFFSET('Data - For Rank'!$H$2,AO14,0,COUNTIF(AO$6:AO$116,AO14)))+IFERROR(VLOOKUP((COUNT(AM$6:AM$116)/4),$ER$9:$ES$13,2,FALSE()),0),"") -> 15 | DG14: 12 | DH14: =IFERROR(AVERAGE(OFFSET('Data - For Rank'!$I$2,AT14,0,COUNTIF(AT$6:AT$116,AT14)))+IFERROR(VLOOKUP((COUNT(AR$6:AR$116)/4),$ER$9:$ES$13,2,FALSE()),0),"") -> 14 | DI14: 3 | DJ14: =IFERROR(AVERAGE(OFFSET('Data - For Rank'!$J$2,AY14,0,COUNTIF(AY$6:AY$116,AY14)))+IFERROR(VLOOKUP((COUNT(AW$6:AW$116)/4),$ER$9:$ES$13,2,FALSE()),0),"") -> 11 | DL14: =IFERROR(AVERAGE(OFFSET('Data - For Rank'!$K$2,BD14,0,COUNTIF(BD$6:BD$116,BD14)))+IFERROR(VLOOKUP((COUNT(BB$6:BB$116)/4),$ER$9:$ES$13,2,FALSE()),0),"") | DN14: =IFERROR(AVERAGE(OFFSET('Data - For Rank'!$L$2,BI14,0,COUNTIF(BI$6:BI$116,BI14)))+IFERROR(VLOOKUP((COUNT(BG$6:BG$116)/4),$ER$9:$ES$13,2,FALSE()),0),"") | DP14: =IFERROR(AVERAGE(OFFSET('Data - For Rank'!$M$2,BN14,0,COUNTIF(BN$6:BN$116,BN14)))+IFERROR(VLOOKUP((COUNT(BL$6:BL$116)/4),$ER$9:$ES$13,2,FALSE()),0),"") | DR14: =IFERROR(AVERAGE(OFFSET('Data - For Rank'!$N$2,BS14,0,COUNTIF(BS$6:BS$116,BS14)))+IFERROR(VLOOKUP((COUNT(BQ$6:BQ$116)/4),$ER$9:$ES$13,2,FALSE()),0),"") | DT14: =IFERROR(AVERAGE(OFFSET('Data - For Rank'!$O$2,BX14,0,COUNTIF(BX$6:BX$116,BX14)))+IFERROR(VLOOKUP((COUNT(BV$6:BV$116)/4),$ER$9:$ES$13,2,FALSE()),0),"") | DV14: =IFERROR(AVERAGE(OFFSET('Data - For Rank'!$P$2,CC14,0,COUNTIF(CC$6:CC$116,CC14)))+IFERROR(VLOOKUP((COUNT(CA$6:CA$116)/4),$ER$9:$ES$13,2,FALSE()),0),"") | DX14: =IFERROR(AVERAGE(OFFSET('Data - For Rank'!$Q$2,CH14,0,COUNTIF(CH$6:CH$116,CH14)))+IFERROR(VLOOKUP((COUNT(CF$6:CF$116)/4),$ER$9:$ES$13,2,FALSE()),0),"") | DZ14: =IFERROR(AVERAGE(OFFSET('Data - For Rank'!$R$2,CM14,0,COUNTIF(CM$6:CM$116,CM14)))+IFERROR(VLOOKUP((COUNT(CK$6:CK$116)/4),$ER$9:$ES$13,2,FALSE()),0),"") | EB14: =IFERROR(AVERAGE(OFFSET('Data - For Rank'!$S$2,CR14,0,COUNTIF(CR$6:CR$116,CR14)))+IFERROR(VLOOKUP((COUNT(CP$6:CP$116)/4),$ER$9:$ES$13,2,FALSE()),0),"") | EC14: =CS14+CU14+CW14+CY14+DA14+DC14+DE14+DG14+DI14+DK14+DM14+DO14+DQ14+DS14+DU14+DW14+DY14+EA14 -> 128 | ED14: =AVERAGE(CT14,CV14,CX14,CZ14,DB14,DD14,DF14,DH14,DJ14,DL14,DN14,DP14,DR14,DT14,DV14,DX14,DZ14,EB14) -> 13.5
B15: =_xlfn.RANK.EQ(C15,$C$6:$C$63,) -> 4 | C15: =EC15 -> 192 | D15: CP | E15: Chris Preston | F15: =COUNT(CT15,CV15,CX15,CZ15,DB15,DD15,DF15,DH15,DJ15,DL15,DN15,DP15,DR15,DT15,DV15,DX15,DZ15,EB15) -> 9 | G15: =IF(CT15=0,"",CT15) -> 22 | L15: =IF(CV15=0,"",CV15) | Q15: =IF(CX15=0,"",CX15) -> 23.5 | V15: =IF(CZ15=0,"",CZ15) -> 26 | AA15: =IF(DB15=0,"",DB15) -> 22 | AF15: =IF(DD15=0,"",DD15) -> 11.5 | AK15: =IF(DF15=0,"",DF15) -> 23.5 | AP15: =IF(DH15=0,"",DH15) -> 28.5 | AU15: =IF(DJ15=0,"",DJ15) -> 16.5 | AZ15: =IF(DL15=0,"",DL15) -> 18.5 | BE15: =IF(DN15=0,"",DN15) | BJ15: =IF(DP15=0,"",DP15) | BO15: =IF(DR15=0,"",DR15) | BT15: =IF(DT15=0,"",DT15) | BY15: =IF(DV15=0,"",DV15) | CD15: =IF(DX15=0,"",DX15) | CI15: =IF(DZ15=0,"",DZ15) | CN15: =IF(EB15=0,"",EB15) | CS15: 82 | CT15: =IFERROR(CT16+CT17,"") -> 22 | CV15: =IFERROR(CV16+CV17,"") | CW15: 81 | CX15: =IFERROR(CX16+CX17,"") -> 23.5 | CY15: 76 | CZ15: =IFERROR(CZ16+CZ17,"") -> 26 | DA15: 80 | DB15: =IFERROR(DB16+DB17,"") -> 22 | DC15: 85 | DD15: =IFERROR(DD16+DD17,"") -> 11.5 | DE15: 76 | DF15: =IFERROR(DF16+DF17,"") -> 23.5 | DG15: 74 | DH15: =IFERROR(DH16+DH17,"") -> 28.5 | DI15: 80 | DJ15: =IFERROR(DJ16+DJ17,"") -> 16.5 | DK15: 74 | DL15: =IFERROR(DL16+DL17,"") -> 18.5 | DN15: =IFERROR(DN16+DN17,"") | DP15: =IFERROR(DP16+DP17,"") | DR15: =IFERROR(DR16+DR17,"") | DT15: =IFERROR(DT16+DT17,"") | DV15: =IFERROR(DV16+DV17,"") | DX15: =IFERROR(DX16+DX17,"") | DZ15: =IFERROR(DZ16+DZ17,"") | EB15: =IFERROR(EB16+EB17,"") | EC15: =IFERROR(LARGE($G15:$CN15,1),0)+IFERROR(LARGE($G15:$CN15,2),0)+IFERROR(LARGE($G15:$CN15,3),0)+IFERROR(LARGE($G15:$CN15,4),0)+IFERROR(LARGE($G15:$CN15,5),0)+IFERROR(LARGE($G15:$CN15,6),0)+IFERROR(LARGE($G15:$CN15,7),0)+IFERROR(LARGE($G15:$CN15,8),0)+IFERROR(LARGE($G15:$CN15,9),0)+IFERROR(LARGE($G15:$CN15,10),0) -> 192 | ED15: =AVERAGE(CT15,CV15,CX15,CZ15,DB15,DD15,DF15,DH15,DJ15,DL15,DN15,DP15,DR15,DT15,DV15,DX15,DZ15,EB15) -> 21.333333
B16: =B15+0.12 -> 4.12 | D16: CP1 | E16: Harvey Points | H16: =IF(CS16=0,"",CS16) -> 29 | J16: =IFERROR(RANK(H16,H$6:H$116,0),"") -> 13 | M16: =IF(CU16=0,"",CU16) | O16: =IFERROR(RANK(M16,M$6:M$116,0),"") | R16: =IF(CW16=0,"",CW16) -> 32 | T16: =IFERROR(RANK(R16,R$6:R$116,0),"") -> 6 | W16: =IF(CY16=0,"",CY16) -> 33 | Y16: =IFERROR(RANK(W16,W$6:W$116,0),"") -> 1 | AB16: =IF(DA16=0,"",DA16) -> 33 | AD16: =IFERROR(RANK(AB16,AB$6:AB$116,0),"") -> 4 | AG16: =IF(DC16=0,"",DC16) -> 29 | AI16: =IFERROR(RANK(AG16,AG$6:AG$116,0),"") -> 11 | AL16: =IF(DE16=0,"",DE16) -> 34 | AN16: =IFERROR(RANK(AL16,AL$6:AL$116,0),"") -> 5 | AQ16: =IF(DG16=0,"",DG16) -> 38 | AS16: =IFERROR(RANK(AQ16,AQ$6:AQ$116,0),"") -> 1 | AV16: =IF(DI16=0,"",DI16) -> 33 | AX16: =IFERROR(RANK(AV16,AV$6:AV$116,0),"") -> 10 | BA16: =IF(DK16=0,"",DK16) -> 34 | BC16: =IFERROR(RANK(BA16,BA$6:BA$116,0),"") -> 5 | BF16: =IF(DM16=0,"",DM16) | BH16: =IFERROR(RANK(BF16,BF$6:BF$116,0),"") | BK16: =IF(DO16=0,"",DO16) | BM16: =IFERROR(RANK(BK16,BK$6:BK$116,0),"") | BP16: =IF(DQ16=0,"",DQ16) | BR16: =IFERROR(RANK(BP16,BP$6:BP$116,0),"") | BU16: =IF(DS16=0,"",DS16) | BW16: =IFERROR(RANK(BU16,BU$6:BU$116,0),"") | BZ16: =IF(DU16=0,"",DU16) | CB16: =IFERROR(RANK(BZ16,BZ$6:BZ$116,0),"") | CE16: =IF(DW16=0,"",DW16) | CG16: =IFERROR(RANK(CE16,CE$6:CE$116,0),"") | CJ16: =IF(DY16=0,"",DY16) | CL16: =IFERROR(RANK(CJ16,CJ$6:CJ$116,0),"") | CO16: =IF(EA16=0,"",EA16) | CQ16: =IFERROR(RANK(CO16,CO$6:CO$116,0),"") | CS16: 29 | CT16: =IFERROR(AVERAGE(OFFSET('Data - For Rank'!B$2,J16,0,COUNTIF($J$7:J$116,J16)))+IFERROR(VLOOKUP((COUNT($H$6:$H$116)/4),$ER$9:$ES$13,2,FALSE()),0),"") -> 6 | CV16: =IFERROR(AVERAGE(OFFSET('Data - For Rank'!$C$2,O16,0,COUNTIF(O$7:O$116,O16)))+IFERROR(VLOOKUP((COUNT(M$6:M$116)/4),$ER$9:$ES$13,2,FALSE()),0),"") | CW16: 32 | CX16: =IFERROR(AVERAGE(OFFSET('Data - For Rank'!D$2,T16,0,COUNTIF(T$7:T$116,T16)))+IFERROR(VLOOKUP((COUNT(R$6:R$116)/4),$ER$9:$ES$13,2,FALSE()),0),"") -> 11 | CY16: 33 | CZ16: =IFERROR(AVERAGE(OFFSET('Data - For Rank'!E$2,Y16,0,COUNTIF(Y$7:Y$116,Y16)))+IFERROR(VLOOKUP((COUNT(W$6:W$116)/4),$ER$9:$ES$13,2,FALSE()),0),"") -> 14 | DA16: 33 | DB16: =IFERROR(AVERAGE(OFFSET('Data - For Rank'!F$2,AD16,0,COUNTIF(AD$7:AD$116,AD16)))+IFERROR(VLOOKUP((COUNT(AB$6:AB$116)/4),$ER$9:$ES$13,2,FALSE()),0),"") -> 14 | DC16: 29 | DD16: =IFERROR(AVERAGE(OFFSET('Data - For Rank'!G$2,AI16,0,COUNTIF(AI$7:AI$116,AI16)))+IFERROR(VLOOKUP((COUNT(AG$6:AG$116)/4),$ER$9:$ES$13,2,FALSE()),0),"") -> 7.5 | DE16: 34 | DF16: =IFERROR(AVERAGE(OFFSET('Data - For Rank'!$H$2,AN16,0,COUNTIF(AN$7:AN$116,AN16)))+IFERROR(VLOOKUP((COUNT(AL$6:AL$116)/4),$ER$9:$ES$13,2,FALSE()),0),"") -> 10.5 | DG16: 38 | DH16: =IFERROR(AVERAGE(OFFSET('Data - For Rank'!$I$2,AS16,0,COUNTIF(AS$7:AS$116,AS16)))+IFERROR(VLOOKUP((COUNT(AQ$6:AQ$116)/4),$ER$9:$ES$13,2,FALSE()),0),"") -> 18 | DI16: 33 | DJ16: =IFERROR(AVERAGE(OFFSET('Data - For Rank'!$J$2,AX16,0,COUNTIF(AX$7:AX$116,AX16)))+IFERROR(VLOOKUP((COUNT(AV$6:AV$116)/4),$ER$9:$ES$13,2,FALSE()),0),"") -> 8.5 | DK16: 34 | DL16: =IFERROR(AVERAGE(OFFSET('Data - For Rank'!$K$2,BC16,0,COUNTIF(BC$7:BC$116,BC16)))+IFERROR(VLOOKUP((COUNT(BA$6:BA$116)/4),$ER$9:$ES$13,2,FALSE()),0),"") -> 11.5 | DN16: =IFERROR(AVERAGE(OFFSET('Data - For Rank'!$L$2,BH16,0,COUNTIF(BH$7:BH$116,BH16)))+IFERROR(VLOOKUP((COUNT(BF$6:BF$116)/4),$ER$9:$ES$13,2,FALSE()),0),"") | DP16: =IFERROR(AVERAGE(OFFSET('Data - For Rank'!$M$2,BM16,0,COUNTIF(BM$7:BM$116,BM16)))+IFERROR(VLOOKUP((COUNT(BK$6:BK$116)/4),$ER$9:$ES$13,2,FALSE()),0),"") | DR16: =IFERROR(AVERAGE(OFFSET('Data - For Rank'!$N$2,BR16,0,COUNTIF(BR$7:BR$116,BR16)))+IFERROR(VLOOKUP((COUNT(BP$6:BP$116)/4),$ER$9:$ES$13,2,FALSE()),0),"") | DT16: =IFERROR(AVERAGE(OFFSET('Data - For Rank'!$O$2,BW16,0,COUNTIF(BW$7:BW$116,BW16)))+IFERROR(VLOOKUP((COUNT(BU$6:BU$116)/4),$ER$9:$ES$13,2,FALSE()),0),"") | DV16: =IFERROR(AVERAGE(OFFSET('Data - For Rank'!$P$2,CB16,0,COUNTIF(CB$7:CB$116,CB16)))+IFERROR(VLOOKUP((COUNT(BZ$6:BZ$116)/4),$ER$9:$ES$13,2,FALSE()),0),"") | DX16: =IFERROR(AVERAGE(OFFSET('Data - For Rank'!$Q$2,CG16,0,COUNTIF(CG$7:CG$116,CG16)))+IFERROR(VLOOKUP((COUNT(CE$6:CE$116)/4),$ER$9:$ES$13,2,FALSE()),0),"") | DZ16: =IFERROR(AVERAGE(OFFSET('Data - For Rank'!$R$2,CL16,0,COUNTIF(CL$7:CL$116,CL16)))+IFERROR(VLOOKUP((COUNT(CJ$6:CJ$116)/4),$ER$9:$ES$13,2,FALSE()),0),"") | EB16: =IFERROR(AVERAGE(OFFSET('Data - For Rank'!$S$2,CQ16,0,COUNTIF(CQ$7:CQ$116,CQ16)))+IFERROR(VLOOKUP((COUNT(CO$6:CO$116)/4),$ER$9:$ES$13,2,FALSE()),0),"") | EC16: =AVERAGE(CS16,CU16,CW16,CY16,DA16,DC16,DE16,DG16,DI16,DK16,DM16,DO16,DQ16,DS16,DU16,DW16,DY16,EA16) -> 32.777778 | ED16: =AVERAGE(CT16,CV16,CX16,CZ16,DB16,DD16,DF16,DH16,DJ16,DL16,DN16,DP16,DR16,DT16,DV16,DX16,DZ16,EB16) -> 11.222222 | EM16: Basically, one point for every player and you take two from the top and the bottom
B17: =B15+0.022 -> 4.022 | D17: CP2 | E17: cash +/- | F17: =IF(COUNT(G15:CN15)>10,SMALL(G15:CN15,COUNT(G15:CN15)-10),MIN(G15:CN15)) -> 11.5 | I17: =IF(CS17=0,"",CS17) -> 12 | K17: =IFERROR(_xlfn.RANK.EQ(I17,I$6:I$116,0),"") -> 3 | N17: =IF(CU17=0,"",CU17) | P17: =IFERROR(_xlfn.RANK.EQ(N17,N$6:N$116,0),"") | S17: =IF(CW17=0,"",CW17) -> 4 | U17: =IFERROR(_xlfn.RANK.EQ(S17,S$6:S$116,0),"") -> 4 | X17: =IF(CY17=0,"",CY17) -> 13 | Z17: =IFERROR(_xlfn.RANK.EQ(X17,X$6:X$116,0),"") -> 3 | AC17: =IF(DA17=0,"",DA17) -> -6 | AE17: =IFERROR(_xlfn.RANK.EQ(AC17,AC$6:AC$116,0),"") -> 11 | AH17: =IF(DC17=0,"",DC17) -> -28 | AJ17: =IFERROR(_xlfn.RANK.EQ(AH17,AH$6:AH$116,0),"") -> 15 | AM17: =IF(DE17=0,"",DE17) -> 4 | AO17: =IFERROR(_xlfn.RANK.EQ(AM17,AM$6:AM$116,0),"") -> 4 | AR17: =IF(DG17=0,"",DG17) -> -0.0001 | AT17: =IFERROR(_xlfn.RANK.EQ(AR17,AR$6:AR$116,0),"") -> 8 | AW17: =IF(DI17=0,"",DI17) -> -9 | AY17: =IFERROR(_xlfn.RANK.EQ(AW17,AW$6:AW$116,0),"") -> 11 | BB17: =IF(DK17=0,"",DK17) -> -18 | BD17: =IFERROR(_xlfn.RANK.EQ(BB17,BB$6:BB$116,0),"") -> 10 | BG17: =IF(DM17=0,"",DM17) | BI17: =IFERROR(_xlfn.RANK.EQ(BG17,BG$6:BG$116,0),"") | BL17: =IF(DO17=0,"",DO17) | BN17: =IFERROR(_xlfn.RANK.EQ(BL17,BL$6:BL$116,0),"") | BQ17: =IF(DQ17=0,"",DQ17) | BS17: =IFERROR(_xlfn.RANK.EQ(BQ17,BQ$6:BQ$116,0),"") | BV17: =IF(DS17=0,"",DS17) | BX17: =IFERROR(_xlfn.RANK.EQ(BV17,BV$6:BV$116,0),"") | CA17: =IF(DU17=0,"",DU17) | CC17: =IFERROR(_xlfn.RANK.EQ(CA17,CA$6:CA$116,0),"") | CF17: =IF(DW17=0,"",DW17) | CH17: =IFERROR(_xlfn.RANK.EQ(CF17,CF$6:CF$116,0),"") | CK17: =IF(DY17=0,"",DY17) | CM17: =IFERROR(_xlfn.RANK.EQ(CK17,CK$6:CK$116,0),"") | CP17: =IF(EA17=0,"",EA17) | CR17: =IFERROR(_xlfn.RANK.EQ(CP17,CP$6:CP$116,0),"") | CS17: 12 | CT17: =IFERROR(AVERAGE(OFFSET('Data - For Rank'!B$2,K17,0,COUNTIF(K$6:K$116,K17)))+IFERROR(VLOOKUP((COUNT($I$6:$I$116)/4),$ER$9:$ES$13,2,FALSE()),0),"") -> 16 | CV17: =IFERROR(AVERAGE(OFFSET('Data - For Rank'!$C$2,P17,0,COUNTIF(P$6:P$116,P17)))+IFERROR(VLOOKUP((COUNT(N$6:N$116)/4),$ER$9:$ES$13,2,FALSE()),0),"") | CW17: 4 | CX17: =IFERROR(AVERAGE(OFFSET('Data - For Rank'!D$2,U17,0,COUNTIF(U$6:$U125,U17)))+IFERROR(VLOOKUP((COUNT(S$6:S$116)/4),$ER$9:$ES$13,2,FALSE()),0),"") -> 12.5 | CY17: 13 | CZ17: =IFERROR(AVERAGE(OFFSET('Data - For Rank'!E$2,Z17,0,COUNTIF(Z$6:Z$116,Z17)))+IFERROR(VLOOKUP((COUNT(W$6:W$116)/4),$ER$9:$ES$13,2,FALSE()),0),"") -> 12 | DA17: -6 | DB17: =IFERROR(AVERAGE(OFFSET('Data - For Rank'!F$2,AE17,0,COUNTIF(AE$6:AE$116,AE17)))+IFERROR(VLOOKUP((COUNT(AC$6:AC$116)/4),$ER$9:$ES$13,2,FALSE()),0),"") -> 8 | DC17: -28 | DD17: =IFERROR(AVERAGE(OFFSET('Data - For Rank'!G$2,AJ17,0,COUNTIF(AJ$6:AJ$116,AJ17)))+IFERROR(VLOOKUP((COUNT(AH$6:AH$116)/4),$ER$9:$ES$13,2,FALSE()),0),"") -> 4 | DE17: 4 | DF17: =IFERROR(AVERAGE(OFFSET('Data - For Rank'!$H$2,AO17,0,COUNTIF(AO$6:AO$116,AO17)))+IFERROR(VLOOKUP((COUNT(AM$6:AM$116)/4),$ER$9:$ES$13,2,FALSE()),0),"") -> 13 | DG17: -0.0001 | DH17: =IFERROR(AVERAGE(OFFSET('Data - For Rank'!$I$2,AT17,0,COUNTIF(AT$6:AT$116,AT17)))+IFERROR(VLOOKUP((COUNT(AR$6:AR$116)/4),$ER$9:$ES$13,2,FALSE()),0),"") -> 10.5 | DI17: -9 | DJ17: =IFERROR(AVERAGE(OFFSET('Data - For Rank'!$J$2,AY17,0,COUNTIF(AY$6:AY$116,AY17)))+IFERROR(VLOOKUP((COUNT(AW$6:AW$116)/4),$ER$9:$ES$13,2,FALSE()),0),"") -> 8 | DK17: -18 | DL17: =IFERROR(AVERAGE(OFFSET('Data - For Rank'!$K$2,BD17,0,COUNTIF(BD$6:BD$116,BD17)))+IFERROR(VLOOKUP((COUNT(BB$6:BB$116)/4),$ER$9:$ES$13,2,FALSE()),0),"") -> 7 | DN17: =IFERROR(AVERAGE(OFFSET('Data - For Rank'!$L$2,BI17,0,COUNTIF(BI$6:BI$116,BI17)))+IFERROR(VLOOKUP((COUNT(BG$6:BG$116)/4),$ER$9:$ES$13,2,FALSE()),0),"") | DP17: =IFERROR(AVERAGE(OFFSET('Data - For Rank'!$M$2,BN17,0,COUNTIF(BN$6:BN$116,BN17)))+IFERROR(VLOOKUP((COUNT(BL$6:BL$116)/4),$ER$9:$ES$13,2,FALSE()),0),"") | DR17: =IFERROR(AVERAGE(OFFSET('Data - For Rank'!$N$2,BS17,0,COUNTIF(BS$6:BS$116,BS17)))+IFERROR(VLOOKUP((COUNT(BQ$6:BQ$116)/4),$ER$9:$ES$13,2,FALSE()),0),"") | DT17: =IFERROR(AVERAGE(OFFSET('Data - For Rank'!$O$2,BX17,0,COUNTIF(BX$6:BX$116,BX17)))+IFERROR(VLOOKUP((COUNT(BV$6:BV$116)/4),$ER$9:$ES$13,2,FALSE()),0),"") | DV17: =IFERROR(AVERAGE(OFFSET('Data - For Rank'!$P$2,CC17,0,COUNTIF(CC$6:CC$116,CC17)))+IFERROR(VLOOKUP((COUNT(CA$6:CA$116)/4),$ER$9:$ES$13,2,FALSE()),0),"") | DX17: =IFERROR(AVERAGE(OFFSET('Data - For Rank'!$Q$2,CH17,0,COUNTIF(CH$6:CH$116,CH17)))+IFERROR(VLOOKUP((COUNT(CF$6:CF$116)/4),$ER$9:$ES$13,2,FALSE()),0),"") | DZ17: =IFERROR(AVERAGE(OFFSET('Data - For Rank'!$R$2,CM17,0,COUNTIF(CM$6:CM$116,CM17)))+IFERROR(VLOOKUP((COUNT(CK$6:CK$116)/4),$ER$9:$ES$13,2,FALSE()),0),"") | EB17: =IFERROR(AVERAGE(OFFSET('Data - For Rank'!$S$2,CR17,0,COUNTIF(CR$6:CR$116,CR17)))+IFERROR(VLOOKUP((COUNT(CP$6:CP$116)/4),$ER$9:$ES$13,2,FALSE()),0),"") | EC17: =CS17+CU17+CW17+CY17+DA17+DC17+DE17+DG17+DI17+DK17+DM17+DO17+DQ17+DS17+DU17+DW17+DY17+EA17 -> -28.0001 | ED17: =AVERAGE(CT17,CV17,CX17,CZ17,DB17,DD17,DF17,DH17,DJ17,DL17,DN17,DP17,DR17,DT17,DV17,DX17,DZ17,EB17) -> 10.111111
