Workbook
Name Ranking: Standings!$B$6

Sheet Auto -  Printable
C1: Rounds [Min Points] | D1: 1 | F1: 2 | H1: 3 | J1: 4 | L1: 5 | N1: 6 | P1: 7 | R1: 8 | T1: 9 | V1: 10 | X1: 11 | Z1: 12 | AB1: 13 | AD1: 14 | AF1: 15 | AH1: 16 | AJ1: 17 | AL1: 18
B2: WEEK | D2: Apr 29th | F2: May 6th | H2: May 13th | J2: May 20th | L2: May 27th | N2: June 3rd | P2: June 17th | R2: June 24th | T2: July 1st | V2: July 8th | X2: July 15th | Z2: July 22nd | AB2: July 29th | AD2: Aug 5th | AF2: Aug 12th | AH2: Aug 19th | AJ2: Aug 26th | AL2: Sept 2nd | AN2: TOTAL | AO2: AVG
B3: Side Game | D3: Closest to Pin | F3: Most Net Pars | H3: Most Under Par | J3: Skins | L3: Closest to Pin | N3: Most Net Pars | P3: Most Under Par | R3: Skins | T3: Closest to Pin | V3: Most Net Pars | X3: Most Under Par | Z3: Skins | AB3: Closest to Pin | AD3: Most Net Pars | AF3: Most Under Par | AH3: Skins | AJ3: Closest to Pin | AL3: Most Net Pars
B4: Winner | D4: RA,MB,JP,HBH | H4: HBH, MW, Bags | J4: JBx3, CPx2, MBx2, KC, MWx2 | L4: CP
B5: TEES | D5: Blue | F5: Rain Out | H5: Black | J5: White | L5: Blue | N5: Black | P5: White | R5: Blue | T5: Black | V5: White | X5: Blue | Z5: Black | AB5: White | AD5: Blue | AF5: Black | AH5: White | AJ5: Blue | AL5: Black
A6: 1 | B6: Matt White | C6: 4 | D6: 84 | E6: 20.5 | H6: 79 | I6: 31 | J6: 82 | K6: 26.5 | L6: 86 | M6: 26.5 | AN6: 104.5 | AO6: 26.125
A7: 1.11 | B7: Harvey Points | D7: 32 | E7: 12.5 | H7: 39 | I7: 15 | J7: 32 | K7: 12.5 | L7: 30 | M7: 8.5 | AN7: 33.25 | AO7: 12.125
A8: 1.021 | B8: cash +/- | C8: 20.5 | D8: -9 | E8: 8 | H8: 30 | I8: 16 | J8: 43 | K8: 14 | L8: 40 | M8: 18 | AN8: 104 | AO8: 14
A9: 2 | B9: Chris Preston | C9: 4 | D9: 82 | E9: 22 | H9: 81 | I9: 23.5 | J9: 76 | K9: 26 | L9: 80 | M9: 22.5 | AN9: 94 | AO9: 23.5
A10: 2.12 | B10: Harvey Points | D10: 29 | E10: 6 | H10: 32 | I10: 11 | J10: 33 | K10: 14 | L10: 33 | M10: 14 | AN10: 31.75 | AO10: 11.25
A11: 2.022 | B11: cash +/- | C11: 22 | D11: 12 | E11: 16 | H11: 4 | I11: 12.5 | J11: 13 | K11: 12 | L11: -6 | M11: 8.5 | AN11: 23 | AO11: 12.25
A12: 3 | B12: Jeff Madden | C12: 3 | D12: 77 | E12: 36 | H12: 83 | I12: 26.5 | L12: 85 | M12: 31 | AN12: 93.5 | AO12: 31.166667
A13: 3.13 | B13: Harvey Points | D13: 40 | E13: 18 | H13: 37 | I13: 14 | L13: 33 | M13: 14 | AN13: 36.666667 | AO13: 15.333333
A14: 3.023 | B14: cash +/- | C14: 26.5 | D14: 35 | E14: 18 | H14: 4 | I14: 12.5 | L14: 38 | M14: 17 | AN14: 77 | AO14: 15.833333
A15: 4 | B15: Kyle Cox | C15: 3 | D15: 83 | E15: 26.5 | J15: 84 | K15: 24 | L15: 87 | M15: 23 | AN15: 73.5 | AO15: 24.5
A16: 4.14 | B16: Harvey Points | D16: 33 | E16: 14.5 | J16: 30 | K16: 11 | L16: 31 | M16: 11 | AN16: 31.333333 | AO16: 12.166667
A17: 4.024 | B17: cash +/- | C17: 23 | D17: 5 | E17: 12 | J17: 41 | K17: 13 | L17: 8 | M17: 12 | AN17: 54 | AO17: 12.333333
A18: 4 | B18: Ben McGinnis | C18: 3 | D18: 80 | E18: 23 | J18: 81 | K18: 21.5 | L18: 83 | M18: 29 | AN18: 73.5 | AO18: 24.5
A19: 4.15 | B19: Harvey Points | D19: 34 | E19: 16 | J19: 32 | K19: 12.5 | L19: 33 | M19: 14 | AN19: 33 | AO19: 14.166667
A20: 4.025 | B20: cash +/- | C20: 21.5 | D20: -10 | E20: 7 | J20: -15 | K20: 9 | L20: 20 | M20: 15 | AN20: -5 | AO20: 10.333333
A21: 6 | B21: Scotty Pierson | C21: 3 | D21: 96 | E21: 27 | H21: 89 | I21: 31 | L21: 100 | M21: 12 | AN21: 70 | AO21: 23.333333
A22: 6.16 | B22: Harvey Points | D22: 31 | E22: 10 | H22: 40 | I22: 16 | L22: 27 | M22: 7 | AN22: 32.666667 | AO22: 11
A23: 6.026 | B23: cash +/- | C23: 12 | D23: 27 | E23: 17 | H23: 21 | I23: 15 | L23: -20 | M23: 5 | AN23: 28 | AO23: 12.333333
A24: 6 | B24: Ronnie A. | C24: 3 | D24: 77 | E24: 31.5 | H24: 87 | I24: 15 | L24: 81 | M24: 23.5 | AN24: 70 | AO24: 23.333333
A25: 6.17 | B25: Harvey Points | D25: 39 | E25: 17 | H25: 31 | I25: 10 | L25: 34 | M25: 16.5 | AN25: 34.666667 | AO25: 14.5
A26: 6.027 | B26: cash +/- | C26: 15 | D26: 10 | E26: 14.5 | H26: -32 | I26: 5 | L26: -8 | M26: 7 | AN26: -30 | AO26: 8.8333333
A27: 8 | B27: Jeff Biederman | C27: 3 | D27: 90 | E27: 23 | J27: 91 | K27: 19.5 | L27: 94 | M27: 23 | AN27: 65.5 | AO27: 21.833333
A28: 8.18 | B28: Harvey Points | D28: 31 | E28: 10 | J28: 28 | K28: 8.5 | L28: 31 | M28: 11 | AN28: 30 | AO28: 9.8333333
A29: 8.028 | B29: cash +/- | C29: 19.5 | D29: 6 | E29: 13 | J29: -11 | K29: 11 | L29: 8 | M29: 12 | AN29: 3 | AO29: 12
A30: 9 | B30: Chris McNeely | C30: 3 | D30: 96 | E30: 24.5 | H30: 95 | I30: 27 | L30: 102 | M30: 9 | AN30: 60.5 | AO30: 20.166667
A31: 9.19 | B31: Harvey Points | D31: 31 | E31: 10 | H31: 35 | I31: 13 | L31: 23 | M31: 6 | AN31: 29.666667 | AO31: 9.6666667
A32: 9.029 | B32: cash +/- | C32: 9 | D32: 10 | E32: 14.5 | H32: 17 | I32: 14 | L32: -74 | M32: 3 | AN32: -47 | AO32: 10.5
A33: 10 | B33: Nathan Copley | C33: 2 | D33: 85 | E33: 22 | L33: 80 | M33: 34 | AN33: 56 | AO33: 28
A34: 10.111 | B34: Harvey Points | D34: 32 | E34: 12.5 | L34: 37 | M34: 18 | AN34: 34.5 | AO34: 15.25
A35: 10.0211 | B35: cash +/- | C35: 22 | D35: -8 | E35: 9.5 | L35: 28 | M35: 16 | AN35: 20 | AO35: 12.75
A36: 11 | B36: Mike Bonner | C36: 3 | D36: 89 | E36: 18.5 | H36: 91 | I36: 19 | J36: 93 | K36: 17 | AN36: 54.5 | AO36: 18.166667
A37: 11.112 | B37: Harvey Points | D37: 33 | E37: 14.5 | H37: 33 | I37: 12 | J37: 26 | K37: 7 | AN37: 30.666667 | AO37: 11.166667
A38: 11.0212 | B38: cash +/- | C38: 17 | D38: -15 | E38: 4 | H38: -12 | I38: 7 | J38: -13 | K38: 10 | AN38: -40 | AO38: 7
A39: 12 | B39: Josh Stoll | C39: 3 | D39: 93 | E39: 10.5 | H39: 101 | I39: 14.5 | L39: 92 | M39: 25 | AN39: 50 | AO39: 16.666667
A40: 12.113 | B40: Harvey Points | D40: 30 | E40: 7.5 | H40: 24 | I40: 6 | L40: 31 | M40: 11 | AN40: 28.333333 | AO40: 8.1666667
...

Sheet Printable
C1: Rounds Min | D1: 15
B2: WEEK | D2: Aug 20th | J2: TOTAL | K2: AVG
B3: Side Game | D3: Holes < Par
B4: Winners | D4: Cox?
A5: 1 | B5: =VLOOKUP(A5,Standings!B:E,3,FALSE()) -> MW | C5: =VLOOKUP(B5,Standings!$E$6:$F$62,2,FALSE()) -> #N/A | J5: =VLOOKUP(B5,Standings!$E$5:$EC$62,57,FALSE()) -> #N/A | K5: =VLOOKUP(B5,Standings!$E$5:$ED$63,58,FALSE()) -> #N/A
A6: =A5+0.1 -> 1.1 | B6: Harvey Points | J6: =VLOOKUP(A6,Standings!$B$6:$EC$62,59,FALSE()) -> #N/A | K6: =VLOOKUP(A6,Standings!$B$6:$ED$62,60,FALSE()) -> #N/A
A7: =A5+0.02 -> 1.02 | B7: cash +/- | C7: =VLOOKUP(A7,Standings!B:F,4,FALSE()) -> #N/A | J7: =VLOOKUP(A7,Standings!$B$6:$EC$62,59,FALSE()) -> #N/A | K7: =VLOOKUP(A7,Standings!$B$6:$ED$62,60,FALSE()) -> #N/A
A8: 2 | B8: =VLOOKUP(A8,Standings!B:E,3,FALSE()) -> CP | C8: =VLOOKUP(B8,Standings!$E$6:$F$62,2,FALSE()) -> #N/A | D8: 77 | E8: 17.5 | J8: =VLOOKUP(B8,Standings!$E$5:$EC$62,57,FALSE()) -> #N/A | K8: =VLOOKUP(B8,Standings!$E$5:$ED$63,58,FALSE()) -> #N/A
A9: =A8+0.1 -> 2.1 | B9: Harvey Points | D9: 36 | E9: 10.5 | J9: =VLOOKUP(A9,Standings!$B$6:$EC$62,59,FALSE()) -> #N/A | K9: =VLOOKUP(A9,Standings!$B$6:$ED$62,60,FALSE()) -> #N/A
A10: =A8+0.02 -> 2.02 | B10: cash +/- | C10: =VLOOKUP(A10,Standings!B:F,4,FALSE()) -> #N/A | D10: -11 | E10: 7 | J10: =VLOOKUP(A10,Standings!$B$6:$EC$62,59,FALSE()) -> #N/A | K10: =VLOOKUP(A10,Standings!$B$6:$ED$62,60,FALSE()) -> #N/A
A11: 3 | B11: =VLOOKUP(A11,Standings!B:E,3,FALSE()) -> #N/A | C11: =VLOOKUP(B11,Standings!$E$6:$F$62,2,FALSE()) -> #N/A | D11: 73 | E11: 17.5 | J11: =VLOOKUP(B11,Standings!$E$5:$EC$62,57,FALSE()) -> #N/A | K11: =VLOOKUP(B11,Standings!$E$5:$ED$63,58,FALSE()) -> #N/A
A12: =A11+0.1 -> 3.1 | B12: Harvey Points | D12: 34 | E12: 7 | J12: =VLOOKUP(A12,Standings!$B$6:$EC$62,59,FALSE()) -> #N/A | K12: =VLOOKUP(A12,Standings!$B$6:$ED$62,60,FALSE()) -> #N/A
A13: =A11+0.02 -> 3.02 | B13: cash +/- | C13: =VLOOKUP(A13,Standings!B:F,4,FALSE()) -> #N/A | D13: 16 | E13: 10.5 | J13: =VLOOKUP(A13,Standings!$B$6:$EC$62,59,FALSE()) -> #N/A | K13: =VLOOKUP(A13,Standings!$B$6:$ED$62,60,FALSE()) -> #N/A
A14: 4 | B14: =VLOOKUP(A14,Standings!B:E,3,FALSE()) -> KC | C14: =VLOOKUP(B14,Standings!$E$6:$F$62,2,FALSE()) -> #N/A | J14: =VLOOKUP(B14,Standings!$E$5:$EC$62,57,FALSE()) -> #N/A | K14: =VLOOKUP(B14,Standings!$E$5:$ED$63,58,FALSE()) -> #N/A
A15: =A14+0.1 -> 4.1 | B15: Harvey Points | J15: =VLOOKUP(A15,Standings!$B$6:$EC$62,59,FALSE()) -> #N/A | K15: =VLOOKUP(A15,Standings!$B$6:$ED$62,60,FALSE()) -> #N/A
A16: =A14+0.02 -> 4.02 | B16: cash +/- | C16: =VLOOKUP(A16,Standings!B:F,4,FALSE()) -> #N/A | J16: =VLOOKUP(A16,Standings!$B$6:$EC$62,59,FALSE()) -> #N/A | K16: =VLOOKUP(A16,Standings!$B$6:$ED$62,60,FALSE()) -> #N/A
A17: 5 | B17: =VLOOKUP(A17,Standings!B:E,3,FALSE()) -> #N/A | C17: =VLOOKUP(B17,Standings!$E$6:$F$62,2,FALSE()) -> #N/A | D17: 77 | E17: 16.5 | J17: =VLOOKUP(B17,Standings!$E$5:$EC$62,57,FALSE()) -> #N/A | K17: =VLOOKUP(B17,Standings!$E$5:$ED$63,58,FALSE()) -> #N/A
A18: =A17+0.1 -> 5.1 | B18: Harvey Points | D18: 36 | E18: 10.5 | J18: =VLOOKUP(A18,Standings!$B$6:$EC$62,59,FALSE()) -> #N/A | K18: =VLOOKUP(A18,Standings!$B$6:$ED$62,60,FALSE()) -> #N/A
A19: =A17+0.02 -> 5.02 | B19: cash +/- | C19: =VLOOKUP(A19,Standings!B:F,4,FALSE()) -> #N/A | D19: -23 | E19: 6 | J19: =VLOOKUP(A19,Standings!$B$6:$EC$62,59,FALSE()) -> #N/A | K19: =VLOOKUP(A19,Standings!$B$6:$ED$62,60,FALSE()) -> #N/A
A20: 6 | B20: =VLOOKUP(A20,Standings!B:E,3,FALSE()) -> SP | C20: =VLOOKUP(B20,Standings!$E$6:$F$62,2,FALSE()) -> #N/A | J20: =VLOOKUP(B20,Standings!$E$5:$EC$62,57,FALSE()) -> #N/A | K20: =VLOOKUP(B20,Standings!$E$5:$ED$63,58,FALSE()) -> #N/A
A21: =A20+0.1 -> 6.1 | B21: Harvey Points | J21: =VLOOKUP(A21,Standings!$B$6:$EC$62,59,FALSE()) -> #N/A | K21: =VLOOKUP(A21,Standings!$B$6:$ED$62,60,FALSE()) -> #N/A
A22: =A20+0.02 -> 6.02 | B22: cash +/- | C22: =VLOOKUP(A22,Standings!B:F,4,FALSE()) -> #N/A | J22: =VLOOKUP(A22,Standings!$B$6:$EC$62,59,FALSE()) -> #N/A | K22: =VLOOKUP(A22,Standings!$B$6:$ED$62,60,FALSE()) -> #N/A
A23: 7 | B23: =VLOOKUP(A23,Standings!B:E,3,FALSE()) -> #N/A | C23: =VLOOKUP(B23,Standings!$E$6:$F$62,2,FALSE()) -> #N/A | D23: 87 | E23: 13.5 | J23: =VLOOKUP(B23,Standings!$E$5:$EC$62,57,FALSE()) -> #N/A | K23: =VLOOKUP(B23,Standings!$E$5:$ED$63,58,FALSE()) -> #N/A
A24: =A23+0.1 -> 7.1 | B24: Harvey Points | D24: 35 | E24: 8.5 | J24: =VLOOKUP(A24,Standings!$B$6:$EC$62,59,FALSE()) -> #N/A | K24: =VLOOKUP(A24,Standings!$B$6:$ED$62,60,FALSE()) -> #N/A
A25: =A23+0.02 -> 7.02 | B25: cash +/- | C25: =VLOOKUP(A25,Standings!B:F,4,FALSE()) -> #N/A | D25: -34 | E25: 5 | J25: =VLOOKUP(A25,Standings!$B$6:$EC$62,59,FALSE()) -> #N/A | K25: =VLOOKUP(A25,Standings!$B$6:$ED$62,60,FALSE()) -> #N/A
A26: 8 | B26: =VLOOKUP(A26,Standings!B:E,3,FALSE()) -> JB | C26: =VLOOKUP(B26,Standings!$E$6:$F$62,2,FALSE()) -> #N/A | D26: 75 | E26: 24 | J26: =VLOOKUP(B26,Standings!$E$5:$EC$62,57,FALSE()) -> #N/A | K26: =VLOOKUP(B26,Standings!$E$5:$ED$63,58,FALSE()) -> #N/A
A27: =A26+0.1 -> 8.1 | B27: Harvey Points | D27: 37 | E27: 12 | J27: =VLOOKUP(A27,Standings!$B$6:$EC$62,59,FALSE()) -> #N/A | K27: =VLOOKUP(A27,Standings!$B$6:$ED$62,60,FALSE()) -> #N/A
A28: =A26+0.02 -> 8.02 | B28: cash +/- | C28: =VLOOKUP(A28,Standings!B:F,4,FALSE()) -> #N/A | D28: 25 | E28: 12 | J28: =VLOOKUP(A28,Standings!$B$6:$EC$62,59,FALSE()) -> #N/A | K28: =VLOOKUP(A28,Standings!$B$6:$ED$62,60,FALSE()) -> #N/A
A29: 9 | B29: =VLOOKUP(A29,Standings!B:E,3,FALSE()) -> CM | C29: =VLOOKUP(B29,Standings!$E$6:$F$62,2,FALSE()) -> #N/A | J29: =VLOOKUP(B29,Standings!$E$5:$EC$62,57,FALSE()) -> #N/A | K29: =VLOOKUP(B29,Standings!$E$5:$ED$63,58,FALSE()) -> #N/A
A30: =A29+0.1 -> 9.1 | B30: Harvey Points | J30: =VLOOKUP(A30,Standings!$B$6:$EC$62,59,FALSE()) -> #N/A | K30: =VLOOKUP(A30,Standings!$B$6:$ED$62,60,FALSE()) -> #N/A
A31: =A29+0.02 -> 9.02 | B31: cash +/- | C31: =VLOOKUP(A31,Standings!B:F,4,FALSE()) -> #N/A | J31: =VLOOKUP(A31,Standings!$B$6:$EC$62,59,FALSE()) -> #N/A | K31: =VLOOKUP(A31,Standings!$B$6:$ED$62,60,FALSE()) -> #N/A
A32: 10 | B32: =VLOOKUP(A32,Standings!B:E,3,FALSE()) -> NC | C32: =VLOOKUP(B32,Standings!$E$6:$F$62,2,FALSE()) -> #N/A | J32: =VLOOKUP(B32,Standings!$E$5:$EC$62,57,FALSE()) -> #N/A | K32: =VLOOKUP(B32,Standings!$E$5:$ED$63,58,FALSE()) -> #N/A
A33: =A32+0.1 -> 10.1 | B33: Harvey Points | J33: =VLOOKUP(A33,Standings!$B$6:$EC$62,59,FALSE()) -> #N/A | K33: =VLOOKUP(A33,Standings!$B$6:$ED$62,60,FALSE()) -> #N/A
A34: =A32+0.02 -> 10.02 | B34: cash +/- | C34: =VLOOKUP(A34,Standings!B:F,4,FALSE()) -> #N/A | J34: =VLOOKUP(A34,Standings!$B$6:$EC$62,59,FALSE()) -> #N/A | K34: =VLOOKUP(A34,Standings!$B$6:$ED$62,60,FALSE()) -> #N/A
A35: 11 | B35: =VLOOKUP(A35,Standings!B:E,3,FALSE()) -> MB | C35: =VLOOKUP(B35,Standings!$E$6:$F$62,2,FALSE()) -> #N/A | D35: 88 | E35: 19 | J35: =VLOOKUP(B35,Standings!$E$5:$EC$62,57,FALSE()) -> #N/A | K35: =VLOOKUP(B35,Standings!$E$5:$ED$63,58,FALSE()) -> #N/A
A36: =A35+0.1 -> 11.1 | B36: Harvey Points | D36: 35 | E36: 8.5 | J36: =VLOOKUP(A36,Standings!$B$6:$EC$62,59,FALSE()) -> #N/A | K36: =VLOOKUP(A36,Standings!$B$6:$ED$62,60,FALSE()) -> #N/A
A37: =A35+0.02 -> 11.02 | B37: cash +/- | C37: =VLOOKUP(A37,Standings!B:F,4,FALSE()) -> #N/A | D37: 16 | E37: 10.5 | J37: =VLOOKUP(A37,Standings!$B$6:$EC$62,59,FALSE()) -> #N/A | K37: =VLOOKUP(A37,Standings!$B$6:$ED$62,60,FALSE()) -> #N/A
A38: 12 | B38: =VLOOKUP(A38,Standings!B:E,3,FALSE()) -> JS | C38: =VLOOKUP(B38,Standings!$E$6:$F$62,2,FALSE()) -> #N/A | D38: 80 | E38: 15 | J38: =VLOOKUP(B38,Standings!$E$5:$EC$62,57,FALSE()) -> #N/A | K38: =VLOOKUP(B38,Standings!$E$5:$ED$63,58,FALSE()) -> #N/A
A39: =A38+0.1 -> 12.1 | B39: Harvey Points | D39: 33 | E39: 6 | J39: =VLOOKUP(A39,Standings!$B$6:$EC$62,59,FALSE()) -> #N/A | K39: =VLOOKUP(A39,Standings!$B$6:$ED$62,60,FALSE()) -> #N/A
A40: =A38+0.02 -> 12.02 | B40: cash +/- | C40: =VLOOKUP(A40,Standings!B:F,4,FALSE()) -> #N/A | D40: 9 | E40: 9 | J40: =VLOOKUP(A40,Standings!$B$6:$EC$62,59,FALSE()) -> #N/A | K40: =VLOOKUP(A40,Standings!$B$6:$ED$62,60,FALSE()) -> #N/A
...

Sheet Standings
F1: Rounds [Min Points] | CS1: 1 | CU1: =CS1+1 -> 2 | CW1: =CU1+1 -> 3 | CY1: =CW1+1 -> 4 | DA1: =CY1+1 -> 5 | DC1: =DA1+1 -> 6 | DE1: =DC1+1 -> 7 | DG1: =DE1+1 -> 8 | DI1: =DG1+1 -> 9 | DK1: =DI1+1 -> 10 | DM1: =DK1+1 -> 11 | DO1: =DM1+1 -> 12 | DQ1: =DO1+1 -> 13 | DS1: =DQ1+1 -> 14 | DU1: =DS1+1 -> 15 | DW1: =DU1+1 -> 16 | DY1: =DW1+1 -> 17 | EA1: =DY1+1 -> 18
E2: WEEK | CS2: Apr 29th | CU2: May 6th | CW2: May 13th | CY2: May 20th | DA2: May 27th | DC2: June 3rd | DE2: June 17th | DG2: June 24th | DI2: July 1st | DK2: July 8th | DM2: July 15th | DO2: July 22nd | DQ2: July 29th | DS2: Aug 5th | DU2: Aug 12th | DW2: Aug 19th | DY2: Aug 26th | EA2: Sept 2nd | EC2: TOTAL | ED2: AVG
E3: Side Game | CS3: Closest to Pin | CU3: Most Net Pars | CW3: Most Under Par | CY3: Skins | DA3: Most Net Pars | DC3: Closest to Pin | DE3: Most Under Par | DG3: Skins | DI3: Most Net Pars | DK3: Closest to Pin | DM3: Most Under Par | DO3: Skins | DQ3: Most Net Pars | DS3: Closest to Pin | DU3: Most Under Par | DW3: Skins | DY3: Most Net Pars | EA3: Closest to Pin
E4: Winner | G4: 44680 | L4: 44687 | Q4: 44694 | V4: 44701 | AA4: 44708 | AF4: 44715 | AK4: 44729 | AP4: 44736 | AU4: 44743 | AZ4: 44750 | BE4: 44757 | BJ4: 44764 | BO4: 44771 | BT4: 44778 | BY4: 44785 | CD4: 44792 | CI4: 44799 | CN4: 44806 | CS4: RA,MB,JP,HBH | CW4: HBH, MW, Bags | CY4: JBx3, CPx2, MBx2, KC, MWx2 | DA4: CP
E5: TEES | G5: Score | H5: Harvey | I5: Money | J5: H Rank | K5: M Rank | L5: Score | M5: Harvey | N5: Money | O5: H Rank | P5: M Rank | Q5: Score | R5: Harvey | S5: Money | T5: H Rank | U5: M Rank | V5: Score | W5: Harvey | X5: Money | Y5: H Rank | Z5: M Rank | AA5: Score | AB5: Harvey | AC5: Money | AD5: H Rank | AE5: M Rank | AF5: Score | AG5: Harvey | AH5: Money | AI5: H Rank | AJ5: M Rank | AK5: Score | AL5: Harvey | AM5: Money | AN5: H Rank | AO5: M Rank | AP5: Score | AQ5: Harvey | AR5: Money | AS5: H Rank | AT5: M Rank | AU5: Score | AV5: Harvey | AW5: Money | AX5: H Rank | AY5: M Rank | AZ5: Score | BA5: Harvey | BB5: Money | BC5: H Rank | BD5: M Rank | BE5: Score | BF5: Harvey | BG5: Money | BH5: H Rank | BI5: M Rank | BJ5: Score | BK5: Harvey | BL5: Money | BM5: H Rank | BN5: M Rank | BO5: Score | BP5: Harvey | BQ5: Money | BR5: H Rank | BS5: M Rank | BT5: Score | BU5: Harvey | BV5: Money | BW5: H Rank | BX5: M Rank | BY5: Score | BZ5: Harvey | CA5: Money | CB5: H Rank | CC5: M Rank | CD5: Score | CE5: Harvey | CF5: Money | CG5: H Rank | CH5: M Rank | CI5: Score | CJ5: Harvey | CK5: Money | CL5: H Rank | CM5: M Rank | CN5: Score | CO5: Harvey | CP5: Money | CQ5: H Rank | CR5: M Rank | CS5: Blue | CU5: Rain Out | CW5: Black | CY5: White | DA5: Blue | DC5: Black | DE5: White | DG5: Blue | DI5: Black | DK5: White | DM5: Blue | DO5: Black | DQ5: White | DS5: Blue | DU5: Black | DW5: White | DY5: Blue | EA5: Black
B6: =_xlfn.RANK.EQ(C6,$C$6:$C$63,) -> 1 | C6: =EC6 -> 104.5 | D6: MW | E6: Matt White | F6: =COUNT(CT6,CV6,CX6,CZ6,DB6,DD6,DF6,DH6,DJ6,DL6,DN6,DP6,DR6,DT6,DV6,DX6,DZ6,EB6) -> 4 | G6: =IF(CT6=0,"",CT6) -> 20.5 | L6: =IF(CV6=0,"",CV6) | Q6: =IF(CX6=0,"",CX6) -> 31 | V6: =IF(CZ6=0,"",CZ6) -> 26.5 | AA6: =IF(DB6=0,"",DB6) -> 26.5 | AF6: =IF(DD6=0,"",DD6) | AK6: =IF(DF6=0,"",DF6) | AP6: =IF(DH6=0,"",DH6) | AU6: =IF(DJ6=0,"",DJ6) | AZ6: =IF(DL6=0,"",DL6) | BE6: =IF(DN6=0,"",DN6) | BJ6: =IF(DP6=0,"",DP6) | BO6: =IF(DR6=0,"",DR6) | BT6: =IF(DT6=0,"",DT6) | BY6: =IF(DV6=0,"",DV6) | CD6: =IF(DX6=0,"",DX6) | CI6: =IF(DZ6=0,"",DZ6) | CN6: =IF(EB6=0,"",EB6) | CS6: 84 | CT6: =IFERROR(CT7+CT8,"") -> 20.5 | CV6: =IFERROR(CV7+CV8,"") | CW6: 79 | CX6: =IFERROR(CX7+CX8,"") -> 31 | CY6: 82 | CZ6: =IFERROR(CZ7+CZ8,"") -> 26.5 | DA6: 86 | DB6: =IFERROR(DB7+DB8,"") -> 26.5 | DD6: =IFERROR(DD7+DD8,"") | DF6: =IFERROR(DF7+DF8,"") | DH6: =IFERROR(DH7+DH8,"") | DJ6: =IFERROR(DJ7+DJ8,"") | DL6: =IFERROR(DL7+DL8,"") | DN6: =IFERROR(DN7+DN8,"") | DP6: =IFERROR(DP7+DP8,"") | DR6: =IFERROR(DR7+DR8,"") | DT6: =IFERROR(DT7+DT8,"") | DV6: =IFERROR(DV7+DV8,"") | DX6: =IFERROR(DX7+DX8,"") | DZ6: =IFERROR(DZ7+DZ8,"") | EB6: =IFERROR(EB7+EB8,"") | EC6: =IFERROR(LARGE($G6:$CN6,1),0)+IFERROR(LARGE($G6:$CN6,2),0)+IFERROR(LARGE($G6:$CN6,3),0)+IFERROR(LARGE($G6:$CN6,4),0)+IFERROR(LARGE($G6:$CN6,5),0)+IFERROR(LARGE($G6:$CN6,6),0)+IFERROR(LARGE($G6:$CN6,7),0)+IFERROR(LARGE($G6:$CN6,8),0)+IFERROR(LARGE($G6:$CN6,9),0)+IFERROR(LARGE($G6:$CN6,10),0) -> 104.5 | ED6: =AVERAGE(CT6,CV6,CX6,CZ6,DB6,DD6,DF6,DH6,DJ6,DL6,DN6,DP6,DR6,DT6,DV6,DX6,DZ6,EB6) -> 26.125
B7: =B6+0.11 -> 1.11 | D7: MW1 | E7: Harvey Points | H7: =IF(CS7=0,"",CS7) -> 32 | J7: =IFERROR(RANK(H7,H$6:H$115,0),"") -> 6 | M7: =IF(CU7=0,"",CU7) | O7: =IFERROR(RANK(M7,M$6:M$115,0),"") | R7: =IF(CW7=0,"",CW7) -> 39 | T7: =IFERROR(RANK(R7,R$6:R$115,0),"") -> 2 | W7: =IF(CY7=0,"",CY7) -> 32 | Y7: =IFERROR(RANK(W7,W$6:W$115,0),"") -> 2 | AB7: =IF(DA7=0,"",DA7) -> 30 | AD7: =IFERROR(RANK(AB7,AB$6:AB$115,0),"") -> 10 | AG7: =IF(DC7=0,"",DC7) | AI7: =IFERROR(RANK(AG7,AG$6:AG$115,0),"") | AL7: =IF(DE7=0,"",DE7) | AN7: =IFERROR(RANK(AL7,AL$6:AL$115,0),"") | AQ7: =IF(DG7=0,"",DG7) | AS7: =IFERROR(RANK(AQ7,AQ$6:AQ$115,0),"") | AV7: =IF(DI7=0,"",DI7) | AX7: =IFERROR(RANK(AV7,AV$6:AV$115,0),"") | BA7: =IF(DK7=0,"",DK7) | BC7: =IFERROR(RANK(BA7,BA$6:BA$115,0),"") | BF7: =IF(DM7=0,"",DM7) | BH7: =IFERROR(RANK(BF7,BF$6:BF$115,0),"") | BK7: =IF(DO7=0,"",DO7) | BM7: =IFERROR(RANK(BK7,BK$6:BK$115,0),"") | BP7: =IF(DQ7=0,"",DQ7) | BR7: =IFERROR(RANK(BP7,BP$6:BP$115,0),"") | BU7: =IF(DS7=0,"",DS7) | BW7: =IFERROR(RANK(BU7,BU$6:BU$115,0),"") | BZ7: =IF(DU7=0,"",DU7) | CB7: =IFERROR(RANK(BZ7,BZ$6:BZ$115,0),"") | CE7: =IF(DW7=0,"",DW7) | CG7: =IFERROR(RANK(CE7,CE$6:CE$115,0),"") | CJ7: =IF(DY7=0,"",DY7) | CL7: =IFERROR(RANK(CJ7,CJ$6:CJ$115,0),"") | CO7: =IF(EA7=0,"",EA7) | CQ7: =IFERROR(RANK(CO7,CO$6:CO$115,0),"") | CS7: 32 | CT7: =IFERROR(AVERAGE(OFFSET('Data - For Rank'!B$2,J7,0,COUNTIF($J$7:J$115,J7)))+IFERROR(VLOOKUP((COUNT($H$6:$H$115)/4),$ER$8:$ES$12,2,FALSE()),0),"") -> 12.5 | CV7: =IFERROR(AVERAGE(OFFSET('Data - For Rank'!$C$2,O7,0,COUNTIF(O$7:O$115,O7)))+IFERROR(VLOOKUP((COUNT(M$6:M$115)/4),$ER$8:$ES$12,2,FALSE()),0),"") | CW7: 39 | CX7: =IFERROR(AVERAGE(OFFSET('Data - For Rank'!D$2,T7,0,COUNTIF(T$7:T$115,T7)))+IFERROR(VLOOKUP((COUNT(R$6:R$115)/4),$ER$8:$ES$12,2,FALSE()),0),"") -> 15 | CY7: 32 | CZ7: =IFERROR(AVERAGE(OFFSET('Data - For Rank'!E$2,Y7,0,COUNTIF(Y$7:Y$115,Y7)))+IFERROR(VLOOKUP((COUNT(W$6:W$115)/4),$ER$8:$ES$12,2,FALSE()),0),"") -> 12.5 | DA7: 30 | DB7: =IFERROR(AVERAGE(OFFSET('Data - For Rank'!F$2,AD7,0,COUNTIF(AD$7:AD$115,AD7)))+IFERROR(VLOOKUP((COUNT(AB$6:AB$115)/4),$ER$8:$ES$12,2,FALSE()),0),"") -> 8.5 | DD7: =IFERROR(AVERAGE(OFFSET('Data - For Rank'!G$2,AI7,0,COUNTIF(AI$7:AI$115,AI7)))+IFERROR(VLOOKUP((COUNT(AG$6:AG$115)/4),$ER$8:$ES$12,2,FALSE()),0),"") | DF7: =IFERROR(AVERAGE(OFFSET('Data - For Rank'!$H$2,AN7,0,COUNTIF(AN$7:AN$115,AN7)))+IFERROR(VLOOKUP((COUNT(AL$6:AL$115)/4),$ER$8:$ES$12,2,FALSE()),0),"") | DH7: =IFERROR(AVERAGE(OFFSET('Data - For Rank'!$I$2,AS7,0,COUNTIF(AS$7:AS$115,AS7)))+IFERROR(VLOOKUP((COUNT(AQ$6:AQ$115)/4),$ER$8:$ES$12,2,FALSE()),0),"") | DJ7: =IFERROR(AVERAGE(OFFSET('Data - For Rank'!$J$2,AX7,0,COUNTIF(AX$7:AX$115,AX7)))+IFERROR(VLOOKUP((COUNT(AV$6:AV$115)/4),$ER$8:$ES$12,2,FALSE()),0),"") | DL7: =IFERROR(AVERAGE(OFFSET('Data - For Rank'!$K$2,BC7,0,COUNTIF(BC$7:BC$115,BC7)))+IFERROR(VLOOKUP((COUNT(BA$6:BA$115)/4),$ER$8:$ES$12,2,FALSE()),0),"") | DN7: =IFERROR(AVERAGE(OFFSET('Data - For Rank'!$L$2,BH7,0,COUNTIF(BH$7:BH$115,BH7)))+IFERROR(VLOOKUP((COUNT(BF$6:BF$115)/4),$ER$8:$ES$12,2,FALSE()),0),"") | DP7: =IFERROR(AVERAGE(OFFSET('Data - For Rank'!$M$2,BM7,0,COUNTIF(BM$7:BM$115,BM7)))+IFERROR(VLOOKUP((COUNT(BK$6:BK$115)/4),$ER$8:$ES$12,2,FALSE()),0),"") | DR7: =IFERROR(AVERAGE(OFFSET('Data - For Rank'!$N$2,BR7,0,COUNTIF(BR$7:BR$115,BR7)))+IFERROR(VLOOKUP((COUNT(BP$6:BP$115)/4),$ER$8:$ES$12,2,FALSE()),0),"") | DT7: =IFERROR(AVERAGE(OFFSET('Data - For Rank'!$O$2,BW7,0,COUNTIF(BW$7:BW$115,BW7)))+IFERROR(VLOOKUP((COUNT(BU$6:BU$115)/4),$ER$8:$ES$12,2,FALSE()),0),"") | DV7: =IFERROR(AVERAGE(OFFSET('Data - For Rank'!$P$2,CB7,0,COUNTIF(CB$7:CB$115,CB7)))+IFERROR(VLOOKUP((COUNT(BZ$6:BZ$115)/4),$ER$8:$ES$12,2,FALSE()),0),"") | DX7: =IFERROR(AVERAGE(OFFSET('Data - For Rank'!$Q$2,CG7,0,COUNTIF(CG$7:CG$115,CG7)))+IFERROR(VLOOKUP((COUNT(CE$6:CE$115)/4),$ER$8:$ES$12,2,FALSE()),0),"") | DZ7: =IFERROR(AVERAGE(OFFSET('Data - For Rank'!$R$2,CL7,0,COUNTIF(CL$7:CL$115,CL7)))+IFERROR(VLOOKUP((COUNT(CJ$6:CJ$115)/4),$ER$8:$ES$12,2,FALSE()),0),"") | EB7: =IFERROR(AVERAGE(OFFSET('Data - For Rank'!$S$2,CQ7,0,COUNTIF(CQ$7:CQ$115,CQ7)))+IFERROR(VLOOKUP((COUNT(CO$6:CO$115)/4),$ER$8:$ES$12,2,FALSE()),0),"") | EC7: =AVERAGE(CS7,CU7,CW7,CY7,DA7,DC7,DE7,DG7,DI7,DK7,DM7,DO7,DQ7,DS7,DU7,DW7,DY7,EA7) -> 33.25 | ED7: =AVERAGE(CT7,CV7,CX7,CZ7,DB7,DD7,DF7,DH7,DJ7,DL7,DN7,DP7,DR7,DT7,DV7,DX7,DZ7,EB7) -> 12.125 | ER7: Groups
B8: =B6+0.021 -> 1.021 | D8: MW2 | E8: cash +/- | F8: =IF(COUNT(CT6:EB6)>10,SMALL(G6:CN6,COUNT(G6:CN6)-10),MIN(CT6:EB6)) -> 20.5 | I8: =IF(CS8=0,"",CS8) -> -9 | K8: =IFERROR(_xlfn.RANK.EQ(I8,I$6:I$115,0),"") -> 11 | N8: =IF(CU8=0,"",CU8) | P8: =IFERROR(_xlfn.RANK.EQ(N8,N$6:N$115,0),"") | S8: =IF(CW8=0,"",CW8) -> 30 | U8: =IFERROR(_xlfn.RANK.EQ(S8,S$6:S$115,0),"") -> 1 | X8: =IF(CY8=0,"",CY8) -> 43 | Z8: =IFERROR(_xlfn.RANK.EQ(X8,X$6:X$115,0),"") -> 1 | AC8: =IF(DA8=0,"",DA8) -> 40 | AE8: =IFERROR(_xlfn.RANK.EQ(AC8,AC$6:AC$115,0),"") -> 1 | AH8: =IF(DC8=0,"",DC8) | AJ8: =IFERROR(_xlfn.RANK.EQ(AH8,AH$6:AH$115,0),"") | AM8: =IF(DE8=0,"",DE8) | AO8: =IFERROR(_xlfn.RANK.EQ(AM8,AM$6:AM$115,0),"") | AR8: =IF(DG8=0,"",DG8) | AT8: =IFERROR(_xlfn.RANK.EQ(AR8,AR$6:AR$115,0),"") | AW8: =IF(DI8=0,"",DI8) | AY8: =IFERROR(_xlfn.RANK.EQ(AW8,AW$6:AW$115,0),"") | BB8: =IF(DK8=0,"",DK8) | BD8: =IFERROR(_xlfn.RANK.EQ(BB8,BB$6:BB$115,0),"") | BG8: =IF(DM8=0,"",DM8) | BI8: =IFERROR(_xlfn.RANK.EQ(BG8,BG$6:BG$115,0),"") | BL8: =IF(DO8=0,"",DO8) | BN8: =IFERROR(_xlfn.RANK.EQ(BL8,BL$6:BL$115,0),"") | BQ8: =IF(DQ8=0,"",DQ8) | BS8: =IFERROR(_xlfn.RANK.EQ(BQ8,BQ$6:BQ$115,0),"") | BV8: =IF(DS8=0,"",DS8) | BX8: =IFERROR(_xlfn.RANK.EQ(BV8,BV$6:BV$115,0),"") | CA8: =IF(DU8=0,"",DU8) | CC8: =IFERROR(_xlfn.RANK.EQ(CA8,CA$6:CA$115,0),"") | CF8: =IF(DW8=0,"",DW8) | CH8: =IFERROR(_xlfn.RANK.EQ(CF8,CF$6:CF$115,0),"") | CK8: =IF(DY8=0,"",DY8) | CM8: =IFERROR(_xlfn.RANK.EQ(CK8,CK$6:CK$115,0),"") | CP8: =IF(EA8=0,"",EA8) | CR8: =IFERROR(_xlfn.RANK.EQ(CP8,CP$6:CP$115,0),"") | CS8: -9 | CT8: =IFERROR(AVERAGE(OFFSET('Data - For Rank'!B$2,K8,0,COUNTIF(K$6:K$115,K8)))+IFERROR(VLOOKUP((COUNT($I$6:$I$115)/4),$ER$8:$ES$12,2,FALSE()),0),"") -> 8 | CV8: =IFERROR(AVERAGE(OFFSET('Data - For Rank'!$C$2,P8,0,COUNTIF(P$6:P$115,P8)))+IFERROR(VLOOKUP((COUNT(N$6:N$115)/4),$ER$8:$ES$12,2,FALSE()),0),"") | CW8: 30 | CX8: =IFERROR(AVERAGE(OFFSET('Data - For Rank'!D$2,U8,0,COUNTIF(U$6:$U115,U8)))+IFERROR(VLOOKUP((COUNT(S$6:S$115)/4),$ER$8:$ES$12,2,FALSE()),0),"") -> 16 | CY8: 43 | CZ8: =IFERROR(AVERAGE(OFFSET('Data - For Rank'!E$2,Z8,0,COUNTIF(Z$6:Z$115,Z8)))+IFERROR(VLOOKUP((COUNT(W$6:W$115)/4),$ER$8:$ES$12,2,FALSE()),0),"") -> 14 | DA8: 40 | DB8: =IFERROR(AVERAGE(OFFSET('Data - For Rank'!F$2,AE8,0,COUNTIF(AE$6:AE$115,AE8)))+IFERROR(VLOOKUP((COUNT(AC$6:AC$115)/4),$ER$8:$ES$12,2,FALSE()),0),"") -> 18 | DD8: =IFERROR(AVERAGE(OFFSET('Data - For Rank'!G$2,AJ8,0,COUNTIF(AJ$6:AJ$115,AJ8)))+IFERROR(VLOOKUP((COUNT(AH$6:AH$115)/4),$ER$8:$ES$12,2,FALSE()),0),"") | DF8: =IFERROR(AVERAGE(OFFSET('Data - For Rank'!$H$2,AO8,0,COUNTIF(AO$6:AO$115,AO8)))+IFERROR(VLOOKUP((COUNT(AM$6:AM$115)/4),$ER$8:$ES$12,2,FALSE()),0),"") | DH8: =IFERROR(AVERAGE(OFFSET('Data - For Rank'!$I$2,AT8,0,COUNTIF(AT$6:AT$115,AT8)))+IFERROR(VLOOKUP((COUNT(AR$6:AR$115)/4),$ER$8:$ES$12,2,FALSE()),0),"") | DJ8: =IFERROR(AVERAGE(OFFSET('Data - For Rank'!$J$2,AY8,0,COUNTIF(AY$6:AY$115,AY8)))+IFERROR(VLOOKUP((COUNT(AW$6:AW$115)/4),$ER$8:$ES$12,2,FALSE()),0),"") | DL8: =IFERROR(AVERAGE(OFFSET('Data - For Rank'!$K$2,BD8,0,COUNTIF(BD$6:BD$115,BD8)))+IFERROR(VLOOKUP((COUNT(BB$6:BB$115)/4),$ER$8:$ES$12,2,FALSE()),0),"") | DN8: =IFERROR(AVERAGE(OFFSET('Data - For Rank'!$L$2,BI8,0,COUNTIF(BI$6:BI$115,BI8)))+IFERROR(VLOOKUP((COUNT(BG$6:BG$115)/4),$ER$8:$ES$12,2,FALSE()),0),"") | DP8: =IFERROR(AVERAGE(OFFSET('Data - For Rank'!$M$2,BN8,0,COUNTIF(BN$6:BN$115,BN8)))+IFERROR(VLOOKUP((COUNT(BL$6:BL$115)/4),$ER$8:$ES$12,2,FALSE()),0),"") | DR8: =IFERROR(AVERAGE(OFFSET('Data - For Rank'!$N$2,BS8,0,COUNTIF(BS$6:BS$115,BS8)))+IFERROR(VLOOKUP((COUNT(BQ$6:BQ$115)/4),$ER$8:$ES$12,2,FALSE()),0),"") | DT8: =IFERROR(AVERAGE(OFFSET('Data - For Rank'!$O$2,BX8,0,COUNTIF(BX$6:BX$115,BX8)))+IFERROR(VLOOKUP((COUNT(BV$6:BV$115)/4),$ER$8:$ES$12,2,FALSE()),0),"") | DV8: =IFERROR(AVERAGE(OFFSET('Data - For Rank'!$P$2,CC8,0,COUNTIF(CC$6:CC$115,CC8)))+IFERROR(VLOOKUP((COUNT(CA$6:CA$115)/4),$ER$8:$ES$12,2,FALSE()),0),"") | DX8: =IFERROR(AVERAGE(OFFSET('Data - For Rank'!$Q$2,CH8,0,COUNTIF(CH$6:CH$115,CH8)))+IFERROR(VLOOKUP((COUNT(CF$6:CF$115)/4),$ER$8:$ES$12,2,FALSE()),0),"") | DZ8: =IFERROR(AVERAGE(OFFSET('Data - For Rank'!$R$2,CM8,0,COUNTIF(CM$6:CM$115,CM8)))+IFERROR(VLOOKUP((COUNT(CK$6:CK$115)/4),$ER$8:$ES$12,2,FALSE()),0),"") | EB8: =IFERROR(AVERAGE(OFFSET('Data - For Rank'!$S$2,CR8,0,COUNTIF(CR$6:CR$115,CR8)))+IFERROR(VLOOKUP((COUNT(CP$6:CP$115)/4),$ER$8:$ES$12,2,FALSE()),0),"") | EC8: =CS8+CU8+CW8+CY8+DA8+DC8+DE8+DG8+DI8+DK8+DM8+DO8+DQ8+DS8+DU8+DW8+DY8+EA8 -> 104 | ED8: =AVERAGE(CT8,CV8,CX8,CZ8,DB8,DD8,DF8,DH8,DJ8,DL8,DN8,DP8,DR8,DT8,DV8,DX8,DZ8,EB8) -> 14 | EM8: Points | ER8: 5 | ES8: 0 | EU8: Total Points Out
B9: =_xlfn.RANK.EQ(C9,$C$6:$C$63,) -> 2 | C9: =EC9 -> 93.5 | D9: CP | E9: Chris Preston | F9: =COUNT(CT9,CV9,CX9,CZ9,DB9,DD9,DF9,DH9,DJ9,DL9,DN9,DP9,DR9,DT9,DV9,DX9,DZ9,EB9) -> 4 | G9: =IF(CT9=0,"",CT9) -> 22 | L9: =IF(CV9=0,"",CV9) | Q9: =IF(CX9=0,"",CX9) -> 23.5 | V9: =IF(CZ9=0,"",CZ9) -> 26 | AA9: =IF(DB9=0,"",DB9) -> 22 | AF9: =IF(DD9=0,"",DD9) | AK9: =IF(DF9=0,"",DF9) | AP9: =IF(DH9=0,"",DH9) | AU9: =IF(DJ9=0,"",DJ9) | AZ9: =IF(DL9=0,"",DL9) | BE9: =IF(DN9=0,"",DN9) | BJ9: =IF(DP9=0,"",DP9) | BO9: =IF(DR9=0,"",DR9) | BT9: =IF(DT9=0,"",DT9) | BY9: =IF(DV9=0,"",DV9) | CD9: =IF(DX9=0,"",DX9) | CI9: =IF(DZ9=0,"",DZ9) | CN9: =IF(EB9=0,"",EB9) | CS9: 82 | CT9: =IFERROR(CT10+CT11,"") -> 22 | CV9: =IFERROR(CV10+CV11,"") | CW9: 81 | CX9: =IFERROR(CX10+CX11,"") -> 23.5 | CY9: 76 | CZ9: =IFERROR(CZ10+CZ11,"") -> 26 | DA9: 80 | DB9: =IFERROR(DB10+DB11,"") -> 22 | DD9: =IFERROR(DD10+DD11,"") | DF9: =IFERROR(DF10+DF11,"") | DH9: =IFERROR(DH10+DH11,"") | DJ9: =IFERROR(DJ10+DJ11,"") | DL9: =IFERROR(DL10+DL11,"") | DN9: =IFERROR(DN10+DN11,"") | DP9: =IFERROR(DP10+DP11,"") | DR9: =IFERROR(DR10+DR11,"") | DT9: =IFERROR(DT10+DT11,"") | DV9: =IFERROR(DV10+DV11,"") | DX9: =IFERROR(DX10+DX11,"") | DZ9: =IFERROR(DZ10+DZ11,"") | EB9: =IFERROR(EB10+EB11,"") | EC9: =IFERROR(LARGE($G9:$CN9,1),0)+IFERROR(LARGE($G9:$CN9,2),0)+IFERROR(LARGE($G9:$CN9,3),0)+IFERROR(LARGE($G9:$CN9,4),0)+IFERROR(LARGE($G9:$CN9,5),0)+IFERROR(LARGE($G9:$CN9,6),0)+IFERROR(LARGE($G9:$CN9,7),0)+IFERROR(LARGE($G9:$CN9,8),0)+IFERROR(LARGE($G9:$CN9,9),0)+IFERROR(LARGE($G9:$CN9,10),0) -> 93.5 | ED9: =AVERAGE(CT9,CV9,CX9,CZ9,DB9,DD9,DF9,DH9,DJ9,DL9,DN9,DP9,DR9,DT9,DV9,DX9,DZ9,EB9) -> 23.375 | EM9: 5 foursomes – first gets 20, last gets 1 | ER9: 4 | ES9: 2 | EU9: =40+38+36+34+32+30+28+26+24+22+20+18+16+14+12+10+8+6+4+2 -> 420
B10: =B9+0.12 -> 2.12 | D10: CP1 | E10: Harvey Points | H10: =IF(CS10=0,"",CS10) -> 29 | J10: =IFERROR(RANK(H10,H$6:H$115,0),"") -> 13 | M10: =IF(CU10=0,"",CU10) | O10: =IFERROR(RANK(M10,M$6:M$115,0),"") | R10: =IF(CW10=0,"",CW10) -> 32 | T10: =IFERROR(RANK(R10,R$6:R$115,0),"") -> 6 | W10: =IF(CY10=0,"",CY10) -> 33 | Y10: =IFERROR(RANK(W10,W$6:W$115,0),"") -> 1 | AB10: =IF(DA10=0,"",DA10) -> 33 | AD10: =IFERROR(RANK(AB10,AB$6:AB$115,0),"") -> 4 | AG10: =IF(DC10=0,"",DC10) | AI10: =IFERROR(RANK(AG10,AG$6:AG$115,0),"") | AL10: =IF(DE10=0,"",DE10) | AN10: =IFERROR(RANK(AL10,AL$6:AL$115,0),"") | AQ10: =IF(DG10=0,"",DG10) | AS10: =IFERROR(RANK(AQ10,AQ$6:AQ$115,0),"") | AV10: =IF(DI10=0,"",DI10) | AX10: =IFERROR(RANK(AV10,AV$6:AV$115,0),"") | BA10: =IF(DK10=0,"",DK10) | BC10: =IFERROR(RANK(BA10,BA$6:BA$115,0),"") | BF10: =IF(DM10=0,"",DM10) | BH10: =IFERROR(RANK(BF10,BF$6:BF$115,0),"") | BK10: =IF(DO10=0,"",DO10) | BM10: =IFERROR(RANK(BK10,BK$6:BK$115,0),"") | BP10: =IF(DQ10=0,"",DQ10) | BR10: =IFERROR(RANK(BP10,BP$6:BP$115,0),"") | BU10: =IF(DS10=0,"",DS10) | BW10: =IFERROR(RANK(BU10,BU$6:BU$115,0),"") | BZ10: =IF(DU10=0,"",DU10) | CB10: =IFERROR(RANK(BZ10,BZ$6:BZ$115,0),"") | CE10: =IF(DW10=0,"",DW10) | CG10: =IFERROR(RANK(CE10,CE$6:CE$115,0),"") | CJ10: =IF(DY10=0,"",DY10) | CL10: =IFERROR(RANK(CJ10,CJ$6:CJ$115,0),"") | CO10: =IF(EA10=0,"",EA10) | CQ10: =IFERROR(RANK(CO10,CO$6:CO$115,0),"") | CS10: 29 | CT10: =IFERROR(AVERAGE(OFFSET('Data - For Rank'!B$2,J10,0,COUNTIF($J$7:J$115,J10)))+IFERROR(VLOOKUP((COUNT($H$6:$H$115)/4),$ER$8:$ES$12,2,FALSE()),0),"") -> 6 | CV10: =IFERROR(AVERAGE(OFFSET('Data - For Rank'!$C$2,O10,0,COUNTIF(O$7:O$115,O10)))+IFERROR(VLOOKUP((COUNT(M$6:M$115)/4),$ER$8:$ES$12,2,FALSE()),0),"") | CW10: 32 | CX10: =IFERROR(AVERAGE(OFFSET('Data - For Rank'!D$2,T10,0,COUNTIF(T$7:T$115,T10)))+IFERROR(VLOOKUP((COUNT(R$6:R$115)/4),$ER$8:$ES$12,2,FALSE()),0),"") -> 11 | CY10: 33 | CZ10: =IFERROR(AVERAGE(OFFSET('Data - For Rank'!E$2,Y10,0,COUNTIF(Y$7:Y$115,Y10)))+IFERROR(VLOOKUP((COUNT(W$6:W$115)/4),$ER$8:$ES$12,2,FALSE()),0),"") -> 14 | DA10: 33 | DB10: =IFERROR(AVERAGE(OFFSET('Data - For Rank'!F$2,AD10,0,COUNTIF(AD$7:AD$115,AD10)))+IFERROR(VLOOKUP((COUNT(AB$6:AB$115)/4),$ER$8:$ES$12,2,FALSE()),0),"") -> 14 | DD10: =IFERROR(AVERAGE(OFFSET('Data - For Rank'!G$2,AI10,0,COUNTIF(AI$7:AI$115,AI10)))+IFERROR(VLOOKUP((COUNT(AG$6:AG$115)/4),$ER$8:$ES$12,2,FALSE()),0),"") | DF10: =IFERROR(AVERAGE(OFFSET('Data - For Rank'!$H$2,AN10,0,COUNTIF(AN$7:AN$115,AN10)))+IFERROR(VLOOKUP((COUNT(AL$6:AL$115)/4),$ER$8:$ES$12,2,FALSE()),0),"") | DH10: =IFERROR(AVERAGE(OFFSET('Data - For Rank'!$I$2,AS10,0,COUNTIF(AS$7:AS$115,AS10)))+IFERROR(VLOOKUP((COUNT(AQ$6:AQ$115)/4),$ER$8:$ES$12,2,FALSE()),0),"") | DJ10: =IFERROR(AVERAGE(OFFSET('Data - For Rank'!$J$2,AX10,0,COUNTIF(AX$7:AX$115,AX10)))+IFERROR(VLOOKUP((COUNT(AV$6:AV$115)/4),$ER$8:$ES$12,2,FALSE()),0),"") | DL10: =IFERROR(AVERAGE(OFFSET('Data - For Rank'!$K$2,BC10,0,COUNTIF(BC$7:BC$115,BC10)))+IFERROR(VLOOKUP((COUNT(BA$6:BA$115)/4),$ER$8:$ES$12,2,FALSE()),0),"") | DN10: =IFERROR(AVERAGE(OFFSET('Data - For Rank'!$L$2,BH10,0,COUNTIF(BH$7:BH$115,BH10)))+IFERROR(VLOOKUP((COUNT(BF$6:BF$115)/4),$ER$8:$ES$12,2,FALSE()),0),"") | DP10: =IFERROR(AVERAGE(OFFSET('Data - For Rank'!$M$2,BM10,0,COUNTIF(BM$7:BM$115,BM10)))+IFERROR(VLOOKUP((COUNT(BK$6:BK$115)/4),$ER$8:$ES$12,2,FALSE()),0),"") | DR10: =IFERROR(AVERAGE(OFFSET('Data - For Rank'!$N$2,BR10,0,COUNTIF(BR$7:BR$115,BR10)))+IFERROR(VLOOKUP((COUNT(BP$6:BP$115)/4),$ER$8:$ES$12,2,FALSE()),0),"") | DT10: =IFERROR(AVERAGE(OFFSET('Data - For Rank'!$O$2,BW10,0,COUNTIF(BW$7:BW$115,BW10)))+IFERROR(VLOOKUP((COUNT(BU$6:BU$115)/4),$ER$8:$ES$12,2,FALSE()),0),"") | DV10: =IFERROR(AVERAGE(OFFSET('Data - For Rank'!$P$2,CB10,0,COUNTIF(CB$7:CB$115,CB10)))+IFERROR(VLOOKUP((COUNT(BZ$6:BZ$115)/4),$ER$8:$ES$12,2,FALSE()),0),"") | DX10: =IFERROR(AVERAGE(OFFSET('Data - For Rank'!$Q$2,CG10,0,COUNTIF(CG$7:CG$115,CG10)))+IFERROR(VLOOKUP((COUNT(CE$6:CE$115)/4),$ER$8:$ES$12,2,FALSE()),0),"") | DZ10: =IFERROR(AVERAGE(OFFSET('Data - For Rank'!$R$2,CL10,0,COUNTIF(CL$7:CL$115,CL10)))+IFERROR(VLOOKUP((COUNT(CJ$6:CJ$115)/4),$ER$8:$ES$12,2,FALSE()),0),"") | EB10: =IFERROR(AVERAGE(OFFSET('Data - For Rank'!$S$2,CQ10,0,COUNTIF(CQ$7:CQ$115,CQ10)))+IFERROR(VLOOKUP((COUNT(CO$6:CO$115)/4),$ER$8:$ES$12,2,FALSE()),0),"") | EC10: =AVERAGE(CS10,CU10,CW10,CY10,DA10,DC10,DE10,DG10,DI10,DK10,DM10,DO10,DQ10,DS10,DU10,DW10,DY10,EA10) -> 31.75 | ED10: =AVERAGE(CT10,CV10,CX10,CZ10,DB10,DD10,DF10,DH10,DJ10,DL10,DN10,DP10,DR10,DT10,DV10,DX10,DZ10,EB10) -> 11.25 | EM10: 4 foursomes – first gets 18, last gets 3 | ER10: 3 | ES10: 4 | EU10: =36+34+32+30+28+26+24+22+20+18+16+14+12+10+8+6 -> 336
B11: =B9+0.022 -> 2.022 | D11: CP2 | E11: cash +/- | F11: =IF(COUNT(CT9:EB9)>10,SMALL(G9:CN9,COUNT(G9:CN9)-10),MIN(CT9:EB9)) -> 22 | I11: =IF(CS11=0,"",CS11) -> 12 | K11: =IFERROR(_xlfn.RANK.EQ(I11,I$6:I$115,0),"") -> 3 | N11: =IF(CU11=0,"",CU11) | P11: =IFERROR(_xlfn.RANK.EQ(N11,N$6:N$115,0),"") | S11: =IF(CW11=0,"",CW11) -> 4 | U11: =IFERROR(_xlfn.RANK.EQ(S11,S$6:S$115,0),"") -> 4 | X11: =IF(CY11=0,"",CY11) -> 13 | Z11: =IFERROR(_xlfn.RANK.EQ(X11,X$6:X$115,0),"") -> 3 | AC11: =IF(DA11=0,"",DA11) -> -6 | AE11: =IFERROR(_xlfn.RANK.EQ(AC11,AC$6:AC$115,0),"") -> 11 | AH11: =IF(DC11=0,"",DC11) | AJ11: =IFERROR(_xlfn.RANK.EQ(AH11,AH$6:AH$115,0),"") | AM11: =IF(DE11=0,"",DE11) | AO11: =IFERROR(_xlfn.RANK.EQ(AM11,AM$6:AM$115,0),"") | AR11: =IF(DG11=0,"",DG11) | AT11: =IFERROR(_xlfn.RANK.EQ(AR11,AR$6:AR$115,0),"") | AW11: =IF(DI11=0,"",DI11) | AY11: =IFERROR(_xlfn.RANK.EQ(AW11,AW$6:AW$115,0),"") | BB11: =IF(DK11=0,"",DK11) | BD11: =IFERROR(_xlfn.RANK.EQ(BB11,BB$6:BB$115,0),"") | BG11: =IF(DM11=0,"",DM11) | BI11: =IFERROR(_xlfn.RANK.EQ(BG11,BG$6:BG$115,0),"") | BL11: =IF(DO11=0,"",DO11) | BN11: =IFERROR(_xlfn.RANK.EQ(BL11,BL$6:BL$115,0),"") | BQ11: =IF(DQ11=0,"",DQ11) | BS11: =IFERROR(_xlfn.RANK.EQ(BQ11,BQ$6:BQ$115,0),"") | BV11: =IF(DS11=0,"",DS11) | BX11: =IFERROR(_xlfn.RANK.EQ(BV11,BV$6:BV$115,0),"") | CA11: =IF(DU11=0,"",DU11) | CC11: =IFERROR(_xlfn.RANK.EQ(CA11,CA$6:CA$115,0),"") | CF11: =IF(DW11=0,"",DW11) | CH11: =IFERROR(_xlfn.RANK.EQ(CF11,CF$6:CF$115,0),"") | CK11: =IF(DY11=0,"",DY11) | CM11: =IFERROR(_xlfn.RANK.EQ(CK11,CK$6:CK$115,0),"") | CP11: =IF(EA11=0,"",EA11) | CR11: =IFERROR(_xlfn.RANK.EQ(CP11,CP$6:CP$115,0),"") | CS11: 12 | CT11: =IFERROR(AVERAGE(OFFSET('Data - For Rank'!B$2,K11,0,COUNTIF(K$6:K$115,K11)))+IFERROR(VLOOKUP((COUNT($I$6:$I$115)/4),$ER$8:$ES$12,2,FALSE()),0),"") -> 16 | CV11: =IFERROR(AVERAGE(OFFSET('Data - For Rank'!$C$2,P11,0,COUNTIF(P$6:P$115,P11)))+IFERROR(VLOOKUP((COUNT(N$6:N$115)/4),$ER$8:$ES$12,2,FALSE()),0),"") | CW11: 4 | CX11: =IFERROR(AVERAGE(OFFSET('Data - For Rank'!D$2,U11,0,COUNTIF(U$6:$U118,U11)))+IFERROR(VLOOKUP((COUNT(S$6:S$115)/4),$ER$8:$ES$12,2,FALSE()),0),"") -> 12.5 | CY11: 13 | CZ11: =IFERROR(AVERAGE(OFFSET('Data - For Rank'!E$2,Z11,0,COUNTIF(Z$6:Z$115,Z11)))+IFERROR(VLOOKUP((COUNT(W$6:W$115)/4),$ER$8:$ES$12,2,FALSE()),0),"") -> 12 | DA11: -6 | DB11: =IFERROR(AVERAGE(OFFSET('Data - For Rank'!F$2,AE11,0,COUNTIF(AE$6:AE$115,AE11)))+IFERROR(VLOOKUP((COUNT(AC$6:AC$115)/4),$ER$8:$ES$12,2,FALSE()),0),"") -> 8 | DD11: =IFERROR(AVERAGE(OFFSET('Data - For Rank'!G$2,AJ11,0,COUNTIF(AJ$6:AJ$115,AJ11)))+IFERROR(VLOOKUP((COUNT(AH$6:AH$115)/4),$ER$8:$ES$12,2,FALSE()),0),"") | DF11: =IFERROR(AVERAGE(OFFSET('Data - For Rank'!$H$2,AO11,0,COUNTIF(AO$6:AO$115,AO11)))+IFERROR(VLOOKUP((COUNT(AM$6:AM$115)/4),$ER$8:$ES$12,2,FALSE()),0),"") | DH11: =IFERROR(AVERAGE(OFFSET('Data - For Rank'!$I$2,AT11,0,COUNTIF(AT$6:AT$115,AT11)))+IFERROR(VLOOKUP((COUNT(AR$6:AR$115)/4),$ER$8:$ES$12,2,FALSE()),0),"") | DJ11: =IFERROR(AVERAGE(OFFSET('Data - For Rank'!$J$2,AY11,0,COUNTIF(AY$6:AY$115,AY11)))+IFERROR(VLOOKUP((COUNT(AW$6:AW$115)/4),$ER$8:$ES$12,2,FALSE()),0),"") | DL11: =IFERROR(AVERAGE(OFFSET('Data - For Rank'!$K$2,BD11,0,COUNTIF(BD$6:BD$115,BD11)))+IFERROR(VLOOKUP((COUNT(BB$6:BB$115)/4),$ER$8:$ES$12,2,FALSE()),0),"") | DN11: =IFERROR(AVERAGE(OFFSET('Data - For Rank'!$L$2,BI11,0,COUNTIF(BI$6:BI$115,BI11)))+IFERROR(VLOOKUP((COUNT(BG$6:BG$115)/4),$ER$8:$ES$12,2,FALSE()),0),"") | DP11: =IFERROR(AVERAGE(OFFSET('Data - For Rank'!$M$2,BN11,0,COUNTIF(BN$6:BN$115,BN11)))+IFERROR(VLOOKUP((COUNT(BL$6:BL$115)/4),$ER$8:$ES$12,2,FALSE()),0),"") | DR11: =IFERROR(AVERAGE(OFFSET('Data - For Rank'!$N$2,BS11,0,COUNTIF(BS$6:BS$115,BS11)))+IFERROR(VLOOKUP((COUNT(BQ$6:BQ$115)/4),$ER$8:$ES$12,2,FALSE()),0),"") | DT11: =IFERROR(AVERAGE(OFFSET('Data - For Rank'!$O$2,BX11,0,COUNTIF(BX$6:BX$115,BX11)))+IFERROR(VLOOKUP((COUNT(BV$6:BV$115)/4),$ER$8:$ES$12,2,FALSE()),0),"") | DV11: =IFERROR(AVERAGE(OFFSET('Data - For Rank'!$P$2,CC11,0,COUNTIF(CC$6:CC$115,CC11)))+IFERROR(VLOOKUP((COUNT(CA$6:CA$115)/4),$ER$8:$ES$12,2,FALSE()),0),"") | DX11: =IFERROR(AVERAGE(OFFSET('Data - For Rank'!$Q$2,CH11,0,COUNTIF(CH$6:CH$115,CH11)))+IFERROR(VLOOKUP((COUNT(CF$6:CF$115)/4),$ER$8:$ES$12,2,FALSE()),0),"") | DZ11: =IFERROR(AVERAGE(OFFSET('Data - For Rank'!$R$2,CM11,0,COUNTIF(CM$6:CM$115,CM11)))+IFERROR(VLOOKUP((COUNT(CK$6:CK$115)/4),$ER$8:$ES$12,2,FALSE()),0),"") | EB11: =IFERROR(AVERAGE(OFFSET('Data - For Rank'!$S$2,CR11,0,COUNTIF(CR$6:CR$115,CR11)))+IFERROR(VLOOKUP((COUNT(CP$6:CP$115)/4),$ER$8:$ES$12,2,FALSE()),0),"") | EC11: =CS11+CU11+CW11+CY11+DA11+DC11+DE11+DG11+DI11+DK11+DM11+DO11+DQ11+DS11+DU11+DW11+DY11+EA11 -> 23 | ED11: =AVERAGE(CT11,CV11,CX11,CZ11,DB11,DD11,DF11,DH11,DJ11,DL11,DN11,DP11,DR11,DT11,DV11,DX11,DZ11,EB11) -> 12.125 | EM11: 3 foursomes – first gets 16, last gets 5 | ER11: 2 | ES11: 6 | EU11: =32+30+28+26+24+22+20+18+16+14+12+10 -> 252
B12: =_xlfn.RANK.EQ(C12,$C$6:$C$63,) -> 2 | C12: =EC12 -> 93.5 | D12: JM | E12: Jeff Madden | F12: =COUNT(CT12,CV12,CX12,CZ12,DB12,DD12,DF12,DH12,DJ12,DL12,DN12,DP12,DR12,DT12,DV12,DX12,DZ12,EB12) -> 3 | G12: =IF(CT12=0,"",CT12) -> 36 | L12: =IF(CV12=0,"",CV12) | Q12: =IF(CX12=0,"",CX12) -> 26.5 | V12: =IF(CZ12=0,"",CZ12) | AA12: =IF(DB12=0,"",DB12) -> 31 | AF12: =IF(DD12=0,"",DD12) | AK12: =IF(DF12=0,"",DF12) | AP12: =IF(DH12=0,"",DH12) | AU12: =IF(DJ12=0,"",DJ12) | AZ12: =IF(DL12=0,"",DL12) | BE12: =IF(DN12=0,"",DN12) | BJ12: =IF(DP12=0,"",DP12) | BO12: =IF(DR12=0,"",DR12) | BT12: =IF(DT12=0,"",DT12) | BY12: =IF(DV12=0,"",DV12) | CD12: =IF(DX12=0,"",DX12) | CI12: =IF(DZ12=0,"",DZ12) | CN12: =IF(EB12=0,"",EB12) | CS12: 77 | CT12: =IFERROR(CT13+CT14,"") -> 36 | CV12: =IFERROR(CV13+CV14,"") | CW12: 83 | CX12: =IFERROR(CX13+CX14,"") -> 26.5 | CZ12: =IFERROR(CZ13+CZ14,"") | DA12: 85 | DB12: =IFERROR(DB13+DB14,"") -> 31 | DD12: =IFERROR(DD13+DD14,"") | DF12: =IFERROR(DF13+DF14,"") | DH12: =IFERROR(DH13+DH14,"") | DJ12: =IFERROR(DJ13+DJ14,"") | DL12: =IFERROR(DL13+DL14,"") | DN12: =IFERROR(DN13+DN14,"") | DP12: =IFERROR(DP13+DP14,"") | DR12: =IFERROR(DR13+DR14,"") | DT12: =IFERROR(DT13+DT14,"") | DV12: =IFERROR(DV13+DV14,"") | DX12: =IFERROR(DX13+DX14,"") | DZ12: =IFERROR(DZ13+DZ14,"") | EB12: =IFERROR(EB13+EB14,"") | EC12: =IFERROR(LARGE($G12:$CN12,1),0)+IFERROR(LARGE($G12:$CN12,2),0)+IFERROR(LARGE($G12:$CN12,3),0)+IFERROR(LARGE($G12:$CN12,4),0)+IFERROR(LARGE($G12:$CN12,5),0)+IFERROR(LARGE($G12:$CN12,6),0)+IFERROR(LARGE($G12:$CN12,7),0)+IFERROR(LARGE($G12:$CN12,8),0)+IFERROR(LARGE($G12:$CN12,9),0)+IFERROR(LARGE($G12:$CN12,10),0) -> 93.5 | ED12: =AVERAGE(CT12,CV12,CX12,CZ12,DB12,DD12,DF12,DH12,DJ12,DL12,DN12,DP12,DR12,DT12,DV12,DX12,DZ12,EB12) -> 31.166667 | EM12: 2 foursomes – first gets 14, last gets 7 | ER12: 1 | ES12: 8 | EU12: =28+26+24+22+20+18+16+14 -> 168
B13: =B12+0.13 -> 2.13 | D13: JM1 | E13: Harvey Points | H13: =IF(CS13=0,"",CS13) -> 40 | J13: =IFERROR(RANK(H13,H$6:H$115,0),"") -> 1 | M13: =IF(CU13=0,"",CU13) | O13: =IFERROR(RANK(M13,M$6:M$115,0),"") | R13: =IF(CW13=0,"",CW13) -> 37 | T13: =IFERROR(RANK(R13,R$6:R$115,0),"") -> 3 | W13: =IF(CY13=0,"",CY13) | Y13: =IFERROR(RANK(W13,W$6:W$115,0),"") | AB13: =IF(DA13=0,"",DA13) -> 33 | AD13: =IFERROR(RANK(AB13,AB$6:AB$115,0),"") -> 4 | AG13: =IF(DC13=0,"",DC13) | AI13: =IFERROR(RANK(AG13,AG$6:AG$115,0),"") | AL13: =IF(DE13=0,"",DE13) | AN13: =IFERROR(RANK(AL13,AL$6:AL$115,0),"") | AQ13: =IF(DG13=0,"",DG13) | AS13: =IFERROR(RANK(AQ13,AQ$6:AQ$115,0),"") | AV13: =IF(DI13=0,"",DI13) | AX13: =IFERROR(RANK(AV13,AV$6:AV$115,0),"") | BA13: =IF(DK13=0,"",DK13) | BC13: =IFERROR(RANK(BA13,BA$6:BA$115,0),"") | BF13: =IF(DM13=0,"",DM13) | BH13: =IFERROR(RANK(BF13,BF$6:BF$115,0),"") | BK13: =IF(DO13=0,"",DO13) | BM13: =IFERROR(RANK(BK13,BK$6:BK$115,0),"") | BP13: =IF(DQ13=0,"",DQ13) | BR13: =IFERROR(RANK(BP13,BP$6:BP$115,0),"") | BU13: =IF(DS13=0,"",DS13) | BW13: =IFERROR(RANK(BU13,BU$6:BU$115,0),"") | BZ13: =IF(DU13=0,"",DU13) | CB13: =IFERROR(RANK(BZ13,BZ$6:BZ$115,0),"") | CE13: =IF(DW13=0,"",DW13) | CG13: =IFERROR(RANK(CE13,CE$6:CE$115,0),"") | CJ13: =IF(DY13=0,"",DY13) | CL13: =IFERROR(RANK(CJ13,CJ$6:CJ$115,0),"") | CO13: =IF(EA13=0,"",EA13) | CQ13: =IFERROR(RANK(CO13,CO$6:CO$115,0),"") | CS13: 40 | CT13: =IFERROR(AVERAGE(OFFSET('Data - For Rank'!B$2,J13,0,COUNTIF($J$7:J$115,J13)))+IFERROR(VLOOKUP((COUNT($H$6:$H$115)/4),$ER$8:$ES$12,2,FALSE()),0),"") -> 18 | CV13: =IFERROR(AVERAGE(OFFSET('Data - For Rank'!$C$2,O13,0,COUNTIF(O$7:O$115,O13)))+IFERROR(VLOOKUP((COUNT(M$6:M$115)/4),$ER$8:$ES$12,2,FALSE()),0),"") | CW13: 37 | CX13: =IFERROR(AVERAGE(OFFSET('Data - For Rank'!D$2,T13,0,COUNTIF(T$7:T$115,T13)))+IFERROR(VLOOKUP((COUNT(R$6:R$115)/4),$ER$8:$ES$12,2,FALSE()),0),"") -> 14 | CZ13: =IFERROR(AVERAGE(OFFSET('Data - For Rank'!E$2,Y13,0,COUNTIF(Y$7:Y$115,Y13)))+IFERROR(VLOOKUP((COUNT(W$6:W$115)/4),$ER$8:$ES$12,2,FALSE()),0),"") | DA13: 33 | DB13: =IFERROR(AVERAGE(OFFSET('Data - For Rank'!F$2,AD13,0,COUNTIF(AD$7:AD$115,AD13)))+IFERROR(VLOOKUP((COUNT(AB$6:AB$115)/4),$ER$8:$ES$12,2,FALSE()),0),"") -> 14 | DD13: =IFERROR(AVERAGE(OFFSET('Data - For Rank'!G$2,AI13,0,COUNTIF(AI$7:AI$115,AI13)))+IFERROR(VLOOKUP((COUNT(AG$6:AG$115)/4),$ER$8:$ES$12,2,FALSE()),0),"") | DF13: =IFERROR(AVERAGE(OFFSET('Data - For Rank'!$H$2,AN13,0,COUNTIF(AN$7:AN$115,AN13)))+IFERROR(VLOOKUP((COUNT(AL$6:AL$115)/4),$ER$8:$ES$12,2,FALSE()),0),"") | DH13: =IFERROR(AVERAGE(OFFSET('Data - For Rank'!$I$2,AS13,0,COUNTIF(AS$7:AS$115,AS13)))+IFERROR(VLOOKUP((COUNT(AQ$6:AQ$115)/4),$ER$8:$ES$12,2,FALSE()),0),"") | DJ13: =IFERROR(AVERAGE(OFFSET('Data - For Rank'!$J$2,AX13,0,COUNTIF(AX$7:AX$115,AX13)))+IFERROR(VLOOKUP((COUNT(AV$6:AV$115)/4),$ER$8:$ES$12,2,FALSE()),0),"") | DL13: =IFERROR(AVERAGE(OFFSET('Data - For Rank'!$K$2,BC13,0,COUNTIF(BC$7:BC$115,BC13)))+IFERROR(VLOOKUP((COUNT(BA$6:BA$115)/4),$ER$8:$ES$12,2,FALSE()),0),"") | DN13: =IFERROR(AVERAGE(OFFSET('Data - For Rank'!$L$2,BH13,0,COUNTIF(BH$7:BH$115,BH13)))+IFERROR(VLOOKUP((COUNT(BF$6:BF$115)/4),$ER$8:$ES$12,2,FALSE()),0),"") | DP13: =IFERROR(AVERAGE(OFFSET('Data - For Rank'!$M$2,BM13,0,COUNTIF(BM$7:BM$115,BM13)))+IFERROR(VLOOKUP((COUNT(BK$6:BK$115)/4),$ER$8:$ES$12,2,FALSE()),0),"") | DR13: =IFERROR(AVERAGE(OFFSET('Data - For Rank'!$N$2,BR13,0,COUNTIF(BR$7:BR$115,BR13)))+IFERROR(VLOOKUP((COUNT(BP$6:BP$115)/4),$ER$8:$ES$12,2,FALSE()),0),"") | DT13: =IFERROR(AVERAGE(OFFSET('Data - For Rank'!$O$2,BW13,0,COUNTIF(BW$7:BW$115,BW13)))+IFERROR(VLOOKUP((COUNT(BU$6:BU$115)/4),$ER$8:$ES$12,2,FALSE()),0),"") | DV13: =IFERROR(AVERAGE(OFFSET('Data - For Rank'!$P$2,CB13,0,COUNTIF(CB$7:CB$115,CB13)))+IFERROR(VLOOKUP((COUNT(BZ$6:BZ$115)/4),$ER$8:$ES$12,2,FALSE()),0),"") | DX13: =IFERROR(AVERAGE(OFFSET('Data - For Rank'!$Q$2,CG13,0,COUNTIF(CG$7:CG$115,CG13)))+IFERROR(VLOOKUP((COUNT(CE$6:CE$115)/4),$ER$8:$ES$12,2,FALSE()),0),"") | DZ13: =IFERROR(AVERAGE(OFFSET('Data - For Rank'!$R$2,CL13,0,COUNTIF(CL$7:CL$115,CL13)))+IFERROR(VLOOKUP((COUNT(CJ$6:CJ$115)/4),$ER$8:$ES$12,2,FALSE()),0),"") | EB13: =IFERROR(AVERAGE(OFFSET('Data - For Rank'!$S$2,CQ13,0,COUNTIF(CQ$7:CQ$115,CQ13)))+IFERROR(VLOOKUP((COUNT(CO$6:CO$115)/4),$ER$8:$ES$12,2,FALSE()),0),"") | EC13: =AVERAGE(CS13,CU13,CW13,CY13,DA13,DC13,DE13,DG13,DI13,DK13,DM13,DO13,DQ13,DS13,DU13,DW13,DY13,EA13) -> 36.666667 | ED13: =AVERAGE(CX13,CT13,CV13,CZ13,DB13,DD13,DF13,DH13,DJ13,DL13,DN13,DP13,DR13,DT13,DV13,DX13,DZ13,EB13) -> 15.333333 | EM13: 1 foursome – first gets 12, last gets 9 | EU13: =24+22+20+18 -> 84
B14: =B12+0.023 -> 2.023 | D14: JM2 | E14: cash +/- | F14: =IF(COUNT(CT12:EB12)>10,SMALL(G12:CN12,COUNT(G12:CN12)-10),MIN(CT12:EB12)) -> 26.5 | I14: =IF(CS14=0,"",CS14) -> 35 | K14: =IFERROR(_xlfn.RANK.EQ(I14,I$6:I$115,0),"") -> 1 | N14: =IF(CU14=0,"",CU14) | P14: =IFERROR(_xlfn.RANK.EQ(N14,N$6:N$115,0),"") | S14: =IF(CW14=0,"",CW14) -> 4 | U14: =IFERROR(_xlfn.RANK.EQ(S14,S$6:S$115,0),"") -> 4 | X14: =IF(CY14=0,"",CY14) | Z14: =IFERROR(_xlfn.RANK.EQ(X14,X$6:X$115,0),"") | AC14: =IF(DA14=0,"",DA14) -> 38 | AE14: =IFERROR(_xlfn.RANK.EQ(AC14,AC$6:AC$115,0),"") -> 2 | AH14: =IF(DC14=0,"",DC14) | AJ14: =IFERROR(_xlfn.RANK.EQ(AH14,AH$6:AH$115,0),"") | AM14: =IF(DE14=0,"",DE14) | AO14: =IFERROR(_xlfn.RANK.EQ(AM14,AM$6:AM$115,0),"") | AR14: =IF(DG14=0,"",DG14) | AT14: =IFERROR(_xlfn.RANK.EQ(AR14,AR$6:AR$115,0),"") | AW14: =IF(DI14=0,"",DI14) | AY14: =IFERROR(_xlfn.RANK.EQ(AW14,AW$6:AW$115,0),"") | BB14: =IF(DK14=0,"",DK14) | BD14: =IFERROR(_xlfn.RANK.EQ(BB14,BB$6:BB$115,0),"") | BG14: =IF(DM14=0,"",DM14) | BI14: =IFERROR(_xlfn.RANK.EQ(BG14,BG$6:BG$115,0),"") | BL14: =IF(DO14=0,"",DO14) | BN14: =IFERROR(_xlfn.RANK.EQ(BL14,BL$6:BL$115,0),"") | BQ14: =IF(DQ14=0,"",DQ14) | BS14: =IFERROR(_xlfn.RANK.EQ(BQ14,BQ$6:BQ$115,0),"") | BV14: =IF(DS14=0,"",DS14) | BX14: =IFERROR(_xlfn.RANK.EQ(BV14,BV$6:BV$115,0),"") | CA14: =IF(DU14=0,"",DU14) | CC14: =IFERROR(_xlfn.RANK.EQ(CA14,CA$6:CA$115,0),"") | CF14: =IF(DW14=0,"",DW14) | CH14: =IFERROR(_xlfn.RANK.EQ(CF14,CF$6:CF$115,0),"") | CK14: =IF(DY14=0,"",DY14) | CM14: =IFERROR(_xlfn.RANK.EQ(CK14,CK$6:CK$115,0),"") | CP14: =IF(EA14=0,"",EA14) | CR14: =IFERROR(_xlfn.RANK.EQ(CP14,CP$6:CP$115,0),"") | CS14: 35 | CT14: =IFERROR(AVERAGE(OFFSET('Data - For Rank'!B$2,K14,0,COUNTIF(K$6:K$115,K14)))+IFERROR(VLOOKUP((COUNT($I$6:$I$115)/4),$ER$8:$ES$12,2,FALSE()),0),"") -> 18 | CV14: =IFERROR(AVERAGE(OFFSET('Data - For Rank'!$C$2,P14,0,COUNTIF(P$6:P$115,P14)))+IFERROR(VLOOKUP((COUNT(N$6:N$115)/4),$ER$8:$ES$12,2,FALSE()),0),"") | CW14: 4 | CX14: =IFERROR(AVERAGE(OFFSET('Data - For Rank'!D$2,U14,0,COUNTIF(U$6:$U121,U14)))+IFERROR(VLOOKUP((COUNT(S$6:S$115)/4),$ER$8:$ES$12,2,FALSE()),0),"") -> 12.5 | CZ14: =IFERROR(AVERAGE(OFFSET('Data - For Rank'!E$2,Z14,0,COUNTIF(Z$6:Z$115,Z14)))+IFERROR(VLOOKUP((COUNT(W$6:W$115)/4),$ER$8:$ES$12,2,FALSE()),0),"") | DA14: 38 | DB14: =IFERROR(AVERAGE(OFFSET('Data - For Rank'!F$2,AE14,0,COUNTIF(AE$6:AE$115,AE14)))+IFERROR(VLOOKUP((COUNT(AC$6:AC$115)/4),$ER$8:$ES$12,2,FALSE()),0),"") -> 17 | DD14: =IFERROR(AVERAGE(OFFSET('Data - For Rank'!G$2,AJ14,0,COUNTIF(AJ$6:AJ$115,AJ14)))+IFERROR(VLOOKUP((COUNT(AH$6:AH$115)/4),$ER$8:$ES$12,2,FALSE()),0),"") | DF14: =IFERROR(AVERAGE(OFFSET('Data - For Rank'!$H$2,AO14,0,COUNTIF(AO$6:AO$115,AO14)))+IFERROR(VLOOKUP((COUNT(AM$6:AM$115)/4),$ER$8:$ES$12,2,FALSE()),0),"") | DH14: =IFERROR(AVERAGE(OFFSET('Data - For Rank'!$I$2,AT14,0,COUNTIF(AT$6:AT$115,AT14)))+IFERROR(VLOOKUP((COUNT(AR$6:AR$115)/4),$ER$8:$ES$12,2,FALSE()),0),"") | DJ14: =IFERROR(AVERAGE(OFFSET('Data - For Rank'!$J$2,AY14,0,COUNTIF(AY$6:AY$115,AY14)))+IFERROR(VLOOKUP((COUNT(AW$6:AW$115)/4),$ER$8:$ES$12,2,FALSE()),0),"") | DL14: =IFERROR(AVERAGE(OFFSET('Data - For Rank'!$K$2,BD14,0,COUNTIF(BD$6:BD$115,BD14)))+IFERROR(VLOOKUP((COUNT(BB$6:BB$115)/4),$ER$8:$ES$12,2,FALSE()),0),"") | DN14: =IFERROR(AVERAGE(OFFSET('Data - For Rank'!$L$2,BI14,0,COUNTIF(BI$6:BI$115,BI14)))+IFERROR(VLOOKUP((COUNT(BG$6:BG$115)/4),$ER$8:$ES$12,2,FALSE()),0),"") | DP14: =IFERROR(AVERAGE(OFFSET('Data - For Rank'!$M$2,BN14,0,COUNTIF(BN$6:BN$115,BN14)))+IFERROR(VLOOKUP((COUNT(BL$6:BL$115)/4),$ER$8:$ES$12,2,FALSE()),0),"") | DR14: =IFERROR(AVERAGE(OFFSET('Data - For Rank'!$N$2,BS14,0,COUNTIF(BS$6:BS$115,BS14)))+IFERROR(VLOOKUP((COUNT(BQ$6:BQ$115)/4),$ER$8:$ES$12,2,FALSE()),0),"") | DT14: =IFERROR(AVERAGE(OFFSET('Data - For Rank'!$O$2,BX14,0,COUNTIF(BX$6:BX$115,BX14)))+IFERROR(VLOOKUP((COUNT(BV$6:BV$115)/4),$ER$8:$ES$12,2,FALSE()),0),"") | DV14: =IFERROR(AVERAGE(OFFSET('Data - For Rank'!$P$2,CC14,0,COUNTIF(CC$6:CC$115,CC14)))+IFERROR(VLOOKUP((COUNT(CA$6:CA$115)/4),$ER$8:$ES$12,2,FALSE()),0),"") | DX14: =IFERROR(AVERAGE(OFFSET('Data - For Rank'!$Q$2,CH14,0,COUNTIF(CH$6:CH$115,CH14)))+IFERROR(VLOOKUP((COUNT(CF$6:CF$115)/4),$ER$8:$ES$12,2,FALSE()),0),"") | DZ14: =IFERROR(AVERAGE(OFFSET('Data - For Rank'!$R$2,CM14,0,COUNTIF(CM$6:CM$115,CM14)))+IFERROR(VLOOKUP((COUNT(CK$6:CK$115)/4),$ER$8:$ES$12,2,FALSE()),0),"") | EB14: =IFERROR(AVERAGE(OFFSET('Data - For Rank'!$S$2,CR14,0,COUNTIF(CR$6:CR$115,CR14)))+IFERROR(VLOOKUP((COUNT(CP$6:CP$115)/4),$ER$8:$ES$12,2,FALSE()),0),"") | EC14: =CS14+CU14+CW14+CY14+DA14+DC14+DE14+DG14+DI14+DK14+DM14+DO14+DQ14+DS14+DU14+DW14+DY14+EA14 -> 77 | ED14: =AVERAGE(CT14,CV14,CX14,CZ14,DB14,DD14,DF14,DH14,DJ14,DL14,DN14,DP14,DR14,DT14,DV14,DX14,DZ14,EB14) -> 15.833333
B15: =_xlfn.RANK.EQ(C15,$C$6:$C$63,) -> 4 | C15: =EC15 -> 73.5 | D15: KC | E15: Kyle Cox | F15: =COUNT(CT15,CV15,CX15,CZ15,DB15,DD15,DF15,DH15,DJ15,DL15,DN15,DP15,DR15,DT15,DV15,DX15,DZ15,EB15) -> 3 | G15: =IF(CT15=0,"",CT15) -> 26.5 | L15: =IF(CV15=0,"",CV15) | Q15: =IF(CX15=0,"",CX15) | V15: =IF(CZ15=0,"",CZ15) -> 24 | AA15: =IF(DB15=0,"",DB15) -> 23 | AF15: =IF(DD15=0,"",DD15) | AK15: =IF(DF15=0,"",DF15) | AP15: =IF(DH15=0,"",DH15) | AU15: =IF(DJ15=0,"",DJ15) | AZ15: =IF(DL15=0,"",DL15) | BE15: =IF(DN15=0,"",DN15) | BJ15: =IF(DP15=0,"",DP15) | BO15: =IF(DR15=0,"",DR15) | BT15: =IF(DT15=0,"",DT15) | BY15: =IF(DV15=0,"",DV15) | CD15: =IF(DX15=0,"",DX15) | CI15: =IF(DZ15=0,"",DZ15) | CN15: =IF(EB15=0,"",EB15) | CS15: 83 | CT15: =IFERROR(CT16+CT17,"") -> 26.5 | CV15: =IFERROR(CV16+CV17,"") | CX15: =IFERROR(CX16+CX17,"") | CY15: 84 | CZ15: =IFERROR(CZ16+CZ17,"") -> 24 | DA15: 87 | DB15: =IFERROR(DB16+DB17,"") -> 23 | DD15: =IFERROR(DD16+DD17,"") | DF15: =IFERROR(DF16+DF17,"") | DH15: =IFERROR(DH16+DH17,"") | DJ15: =IFERROR(DJ16+DJ17,"") | DL15: =IFERROR(DL16+DL17,"") | DN15: =IFERROR(DN16+DN17,"") | DP15: =IFERROR(DP16+DP17,"") | DR15: =IFERROR(DR16+DR17,"") | DT15: =IFERROR(DT16+DT17,"") | DV15: =IFERROR(DV16+DV17,"") | DX15: =IFERROR(DX16+DX17,"") | DZ15: =IFERROR(DZ16+DZ17,"") | EB15: =IFERROR(EB16+EB17,"") | EC15: =IFERROR(LARGE($G15:$CN15,1),0)+IFERROR(LARGE($G15:$CN15,2),0)+IFERROR(LARGE($G15:$CN15,3),0)+IFERROR(LARGE($G15:$CN15,4),0)+IFERROR(LARGE($G15:$CN15,5),0)+IFERROR(LARGE($G15:$CN15,6),0)+IFERROR(LARGE($G15:$CN15,7),0)+IFERROR(LARGE($G15:$CN15,8),0)+IFERROR(LARGE($G15:$CN15,9),0)+IFERROR(LARGE($G15:$CN15,10),0) -> 73.5 | ED15: =AVERAGE(CT15,CV15,CX15,CZ15,DB15,DD15,DF15,DH15,DJ15,DL15,DN15,DP15,DR15,DT15,DV15,DX15,DZ15,EB15) -> 24.5
B16: =B15+0.14 -> 4.14 | D16: KC1 | E16: Harvey Points | H16: =IF(CS16=0,"",CS16) -> 33 | J16: =IFERROR(RANK(H16,H$6:H$115,0),"") -> 4 | M16: =IF(CU16=0,"",CU16) | O16: =IFERROR(RANK(M16,M$6:M$115,0),"") | R16: =IF(CW16=0,"",CW16) | T16: =IFERROR(RANK(R16,R$6:R$115,0),"") | W16: =IF(CY16=0,"",CY16) -> 30 | Y16: =IFERROR(RANK(W16,W$6:W$115,0),"") -> 4 | AB16: =IF(DA16=0,"",DA16) -> 31 | AD16: =IFERROR(RANK(AB16,AB$6:AB$115,0),"") -> 7 | AG16: =IF(DC16=0,"",DC16) | AI16: =IFERROR(RANK(AG16,AG$6:AG$115,0),"") | AL16: =IF(DE16=0,"",DE16) | AN16: =IFERROR(RANK(AL16,AL$6:AL$115,0),"") | AQ16: =IF(DG16=0,"",DG16) | AS16: =IFERROR(RANK(AQ16,AQ$6:AQ$115,0),"") | AV16: =IF(DI16=0,"",DI16) | AX16: =IFERROR(RANK(AV16,AV$6:AV$115,0),"") | BA16: =IF(DK16=0,"",DK16) | BC16: =IFERROR(RANK(BA16,BA$6:BA$115,0),"") | BF16: =IF(DM16=0,"",DM16) | BH16: =IFERROR(RANK(BF16,BF$6:BF$115,0),"") | BK16: =IF(DO16=0,"",DO16) | BM16: =IFERROR(RANK(BK16,BK$6:BK$115,0),"") | BP16: =IF(DQ16=0,"",DQ16) | BR16: =IFERROR(RANK(BP16,BP$6:BP$115,0),"") | BU16: =IF(DS16=0,"",DS16) | BW16: =IFERROR(RANK(BU16,BU$6:BU$115,0),"") | BZ16: =IF(DU16=0,"",DU16) | CB16: =IFERROR(RANK(BZ16,BZ$6:BZ$115,0),"") | CE16: =IF(DW16=0,"",DW16) | CG16: =IFERROR(RANK(CE16,CE$6:CE$115,0),"") | CJ16: =IF(DY16=0,"",DY16) | CL16: =IFERROR(RANK(CJ16,CJ$6:CJ$115,0),"") | CO16: =IF(EA16=0,"",EA16) | CQ16: =IFERROR(RANK(CO16,CO$6:CO$115,0),"") | CS16: 33 | CT16: =IFERROR(AVERAGE(OFFSET('Data - For Rank'!B$2,J16,0,COUNTIF($J$7:J$115,J16)))+IFERROR(VLOOKUP((COUNT($H$6:$H$115)/4),$ER$8:$ES$12,2,FALSE()),0),"") -> 14.5 | CV16: =IFERROR(AVERAGE(OFFSET('Data - For Rank'!$C$2,O16,0,COUNTIF(O$7:O$115,O16)))+IFERROR(VLOOKUP((COUNT(M$6:M$115)/4),$ER$8:$ES$12,2,FALSE()),0),"") | CX16: =IFERROR(AVERAGE(OFFSET('Data - For Rank'!D$2,T16,0,COUNTIF(T$7:T$115,T16)))+IFERROR(VLOOKUP((COUNT(R$6:R$115)/4),$ER$8:$ES$12,2,FALSE()),0),"") | CY16: 30 | CZ16: =IFERROR(AVERAGE(OFFSET('Data - For Rank'!E$2,Y16,0,COUNTIF(Y$7:Y$115,Y16)))+IFERROR(VLOOKUP((COUNT(W$6:W$115)/4),$ER$8:$ES$12,2,FALSE()),0),"") -> 11 | DA16: 31 | DB16: =IFERROR(AVERAGE(OFFSET('Data - For Rank'!F$2,AD16,0,COUNTIF(AD$7:AD$115,AD16)))+IFERROR(VLOOKUP((COUNT(AB$6:AB$115)/4),$ER$8:$ES$12,2,FALSE()),0),"") -> 11 | DD16: =IFERROR(AVERAGE(OFFSET('Data - For Rank'!G$2,AI16,0,COUNTIF(AI$7:AI$115,AI16)))+IFERROR(VLOOKUP((COUNT(AG$6:AG$115)/4),$ER$8:$ES$12,2,FALSE()),0),"") | DF16: =IFERROR(AVERAGE(OFFSET('Data - For Rank'!$H$2,AN16,0,COUNTIF(AN$7:AN$115,AN16)))+IFERROR(VLOOKUP((COUNT(AL$6:AL$115)/4),$ER$8:$ES$12,2,FALSE()),0),"") | DH16: =IFERROR(AVERAGE(OFFSET('Data - For Rank'!$I$2,AS16,0,COUNTIF(AS$7:AS$115,AS16)))+IFERROR(VLOOKUP((COUNT(AQ$6:AQ$115)/4),$ER$8:$ES$12,2,FALSE()),0),"") | DJ16: =IFERROR(AVERAGE(OFFSET('Data - For Rank'!$J$2,AX16,0,COUNTIF(AX$7:AX$115,AX16)))+IFERROR(VLOOKUP((COUNT(AV$6:AV$115)/4),$ER$8:$ES$12,2,FALSE()),0),"") | DL16: =IFERROR(AVERAGE(OFFSET('Data - For Rank'!$K$2,BC16,0,COUNTIF(BC$7:BC$115,BC16)))+IFERROR(VLOOKUP((COUNT(BA$6:BA$115)/4),$ER$8:$ES$12,2,FALSE()),0),"") | DN16: =IFERROR(AVERAGE(OFFSET('Data - For Rank'!$L$2,BH16,0,COUNTIF(BH$7:BH$115,BH16)))+IFERROR(VLOOKUP((COUNT(BF$6:BF$115)/4),$ER$8:$ES$12,2,FALSE()),0),"") | DP16: =IFERROR(AVERAGE(OFFSET('Data - For Rank'!$M$2,BM16,0,COUNTIF(BM$7:BM$115,BM16)))+IFERROR(VLOOKUP((COUNT(BK$6:BK$115)/4),$ER$8:$ES$12,2,FALSE()),0),"") | DR16: =IFERROR(AVERAGE(OFFSET('Data - For Rank'!$N$2,BR16,0,COUNTIF(BR$7:BR$115,BR16)))+IFERROR(VLOOKUP((COUNT(BP$6:BP$115)/4),$ER$8:$ES$12,2,FALSE()),0),"") | DT16: =IFERROR(AVERAGE(OFFSET('Data - For Rank'!$O$2,BW16,0,COUNTIF(BW$7:BW$115,BW16)))+IFERROR(VLOOKUP((COUNT(BU$6:BU$115)/4),$ER$8:$ES$12,2,FALSE()),0),"") | DV16: =IFERROR(AVERAGE(OFFSET('Data - For Rank'!$P$2,CB16,0,COUNTIF(CB$7:CB$115,CB16)))+IFERROR(VLOOKUP((COUNT(BZ$6:BZ$115)/4),$ER$8:$ES$12,2,FALSE()),0),"") | DX16: =IFERROR(AVERAGE(OFFSET('Data - For Rank'!$Q$2,CG16,0,COUNTIF(CG$7:CG$115,CG16)))+IFERROR(VLOOKUP((COUNT(CE$6:CE$115)/4),$ER$8:$ES$12,2,FALSE()),0),"") | DZ16: =IFERROR(AVERAGE(OFFSET('Data - For Rank'!$R$2,CL16,0,COUNTIF(CL$7:CL$115,CL16)))+IFERROR(VLOOKUP((COUNT(CJ$6:CJ$115)/4),$ER$8:$ES$12,2,FALSE()),0),"") | EB16: =IFERROR(AVERAGE(OFFSET('Data - For Rank'!$S$2,CQ16,0,COUNTIF(CQ$7:CQ$115,CQ16)))+IFERROR(VLOOKUP((COUNT(CO$6:CO$115)/4),$ER$8:$ES$12,2,FALSE()),0),"") | EC16: =AVERAGE(CS16,CU16,CW16,CY16,DA16,DC16,DE16,DG16,DI16,DK16,DM16,DO16,DQ16,DS16,DU16,DW16,DY16,EA16) -> 31.333333 | ED16: =AVERAGE(CT16,CV16,CX16,CZ16,DB16,DD16,DF16,DH16,DJ16,DL16,DN16,DP16,DR16,DT16,DV16,DX16,DZ16,EB16) -> 12.166667 | EM16: Basically, one point for every player and you take two from the top and the bottom
